[2025-02-27T09:50:12.804+0000] {taskinstance.py:1956} INFO - Dependencies all met for dep_context=non-requeueable deps ti=<TaskInstance: 3_4_2_homework_assignment.upload_to_clickhouse_task scheduled__2024-01-03T00:00:00+00:00 [queued]>
[2025-02-27T09:50:12.809+0000] {taskinstance.py:1956} INFO - Dependencies all met for dep_context=requeueable deps ti=<TaskInstance: 3_4_2_homework_assignment.upload_to_clickhouse_task scheduled__2024-01-03T00:00:00+00:00 [queued]>
[2025-02-27T09:50:12.809+0000] {taskinstance.py:2170} INFO - Starting attempt 1 of 1
[2025-02-27T09:50:12.819+0000] {taskinstance.py:2191} INFO - Executing <Task(PythonOperator): upload_to_clickhouse_task> on 2024-01-03 00:00:00+00:00
[2025-02-27T09:50:12.824+0000] {standard_task_runner.py:60} INFO - Started process 2209 to run task
[2025-02-27T09:50:12.826+0000] {standard_task_runner.py:87} INFO - Running: ['airflow', 'tasks', 'run', '3_4_2_homework_assignment', 'upload_to_clickhouse_task', 'scheduled__2024-01-03T00:00:00+00:00', '--job-id', '10', '--raw', '--subdir', 'DAGS_FOLDER/3_4_2_homework_assignment.py', '--cfg-path', '/tmp/tmppkx_d4e4']
[2025-02-27T09:50:12.827+0000] {standard_task_runner.py:88} INFO - Job 10: Subtask upload_to_clickhouse_task
[2025-02-27T09:50:12.853+0000] {task_command.py:423} INFO - Running <TaskInstance: 3_4_2_homework_assignment.upload_to_clickhouse_task scheduled__2024-01-03T00:00:00+00:00 [running]> on host ea5964584459
[2025-02-27T09:50:12.901+0000] {taskinstance.py:2480} INFO - Exporting env vars: AIRFLOW_CTX_DAG_OWNER='airflow' AIRFLOW_CTX_DAG_ID='3_4_2_homework_assignment' AIRFLOW_CTX_TASK_ID='upload_to_clickhouse_task' AIRFLOW_CTX_EXECUTION_DATE='2024-01-03T00:00:00+00:00' AIRFLOW_CTX_TRY_NUMBER='1' AIRFLOW_CTX_DAG_RUN_ID='scheduled__2024-01-03T00:00:00+00:00'
[2025-02-27T09:50:12.903+0000] {taskinstance.py:2698} ERROR - Task failed with exception
Traceback (most recent call last):
  File "/home/airflow/.local/lib/python3.9/site-packages/airflow/models/taskinstance.py", line 433, in _execute_task
    result = execute_callable(context=context, **execute_callable_kwargs)
  File "/home/airflow/.local/lib/python3.9/site-packages/airflow/operators/python.py", line 199, in execute
    return_value = self.execute_callable()
  File "/home/airflow/.local/lib/python3.9/site-packages/airflow/operators/python.py", line 216, in execute_callable
    return self.python_callable(*self.op_args, **self.op_kwargs)
  File "/opt/airflow/dags/3_4_2_homework_assignment.py", line 92, in upload_to_clickhouse
    data_frame = pd.read_csv(csv_file)
  File "/home/airflow/.local/lib/python3.9/site-packages/pandas/io/parsers/readers.py", line 948, in read_csv
    return _read(filepath_or_buffer, kwds)
  File "/home/airflow/.local/lib/python3.9/site-packages/pandas/io/parsers/readers.py", line 611, in _read
    parser = TextFileReader(filepath_or_buffer, **kwds)
  File "/home/airflow/.local/lib/python3.9/site-packages/pandas/io/parsers/readers.py", line 1448, in __init__
    self._engine = self._make_engine(f, self.engine)
  File "/home/airflow/.local/lib/python3.9/site-packages/pandas/io/parsers/readers.py", line 1705, in _make_engine
    self.handles = get_handle(
  File "/home/airflow/.local/lib/python3.9/site-packages/pandas/io/common.py", line 863, in get_handle
    handle = open(
FileNotFoundError: [Errno 2] No such file or directory: 'extracted_data_csv.csv'
[2025-02-27T09:50:12.908+0000] {taskinstance.py:1138} INFO - Marking task as FAILED. dag_id=3_4_2_homework_assignment, task_id=upload_to_clickhouse_task, execution_date=20240103T000000, start_date=20250227T095012, end_date=20250227T095012
[2025-02-27T09:50:12.916+0000] {standard_task_runner.py:107} ERROR - Failed to execute job 10 for task upload_to_clickhouse_task ([Errno 2] No such file or directory: 'extracted_data_csv.csv'; 2209)
[2025-02-27T09:50:12.960+0000] {local_task_job_runner.py:234} INFO - Task exited with return code 1
[2025-02-27T09:50:12.971+0000] {taskinstance.py:3280} INFO - 0 downstream tasks scheduled from follow-on schedule check
[2025-02-27T09:54:28.832+0000] {taskinstance.py:1956} INFO - Dependencies all met for dep_context=non-requeueable deps ti=<TaskInstance: 3_4_2_homework_assignment.upload_to_clickhouse_task scheduled__2024-01-03T00:00:00+00:00 [queued]>
[2025-02-27T09:54:28.837+0000] {taskinstance.py:1956} INFO - Dependencies all met for dep_context=requeueable deps ti=<TaskInstance: 3_4_2_homework_assignment.upload_to_clickhouse_task scheduled__2024-01-03T00:00:00+00:00 [queued]>
[2025-02-27T09:54:28.838+0000] {taskinstance.py:2170} INFO - Starting attempt 1 of 1
[2025-02-27T09:54:28.849+0000] {taskinstance.py:2191} INFO - Executing <Task(PythonOperator): upload_to_clickhouse_task> on 2024-01-03 00:00:00+00:00
[2025-02-27T09:54:28.855+0000] {standard_task_runner.py:60} INFO - Started process 2787 to run task
[2025-02-27T09:54:28.857+0000] {standard_task_runner.py:87} INFO - Running: ['airflow', 'tasks', 'run', '3_4_2_homework_assignment', 'upload_to_clickhouse_task', 'scheduled__2024-01-03T00:00:00+00:00', '--job-id', '10', '--raw', '--subdir', 'DAGS_FOLDER/3_4_2_homework_assignment.py', '--cfg-path', '/tmp/tmp7mpig9g3']
[2025-02-27T09:54:28.859+0000] {standard_task_runner.py:88} INFO - Job 10: Subtask upload_to_clickhouse_task
[2025-02-27T09:54:28.899+0000] {task_command.py:423} INFO - Running <TaskInstance: 3_4_2_homework_assignment.upload_to_clickhouse_task scheduled__2024-01-03T00:00:00+00:00 [running]> on host ea5964584459
[2025-02-27T09:54:28.996+0000] {taskinstance.py:2480} INFO - Exporting env vars: AIRFLOW_CTX_DAG_OWNER='airflow' AIRFLOW_CTX_DAG_ID='3_4_2_homework_assignment' AIRFLOW_CTX_TASK_ID='upload_to_clickhouse_task' AIRFLOW_CTX_EXECUTION_DATE='2024-01-03T00:00:00+00:00' AIRFLOW_CTX_TRY_NUMBER='1' AIRFLOW_CTX_DAG_RUN_ID='scheduled__2024-01-03T00:00:00+00:00'
[2025-02-27T09:54:29.003+0000] {taskinstance.py:2698} ERROR - Task failed with exception
Traceback (most recent call last):
  File "/home/airflow/.local/lib/python3.9/site-packages/airflow/models/taskinstance.py", line 433, in _execute_task
    result = execute_callable(context=context, **execute_callable_kwargs)
  File "/home/airflow/.local/lib/python3.9/site-packages/airflow/operators/python.py", line 199, in execute
    return_value = self.execute_callable()
  File "/home/airflow/.local/lib/python3.9/site-packages/airflow/operators/python.py", line 216, in execute_callable
    return self.python_callable(*self.op_args, **self.op_kwargs)
  File "/opt/airflow/dags/3_4_2_homework_assignment.py", line 93, in upload_to_clickhouse
    data_frame = pd.read_csv(csv_file)
  File "/home/airflow/.local/lib/python3.9/site-packages/pandas/io/parsers/readers.py", line 948, in read_csv
    return _read(filepath_or_buffer, kwds)
  File "/home/airflow/.local/lib/python3.9/site-packages/pandas/io/parsers/readers.py", line 611, in _read
    parser = TextFileReader(filepath_or_buffer, **kwds)
  File "/home/airflow/.local/lib/python3.9/site-packages/pandas/io/parsers/readers.py", line 1448, in __init__
    self._engine = self._make_engine(f, self.engine)
  File "/home/airflow/.local/lib/python3.9/site-packages/pandas/io/parsers/readers.py", line 1705, in _make_engine
    self.handles = get_handle(
  File "/home/airflow/.local/lib/python3.9/site-packages/pandas/io/common.py", line 863, in get_handle
    handle = open(
FileNotFoundError: [Errno 2] No such file or directory: 'extracted_data_csv.csv'
[2025-02-27T09:54:29.017+0000] {taskinstance.py:1138} INFO - Marking task as FAILED. dag_id=3_4_2_homework_assignment, task_id=upload_to_clickhouse_task, execution_date=20240103T000000, start_date=20250227T095428, end_date=20250227T095429
[2025-02-27T09:54:29.043+0000] {standard_task_runner.py:107} ERROR - Failed to execute job 10 for task upload_to_clickhouse_task ([Errno 2] No such file or directory: 'extracted_data_csv.csv'; 2787)
[2025-02-27T09:54:29.073+0000] {local_task_job_runner.py:234} INFO - Task exited with return code 1
[2025-02-27T09:54:29.095+0000] {taskinstance.py:3280} INFO - 0 downstream tasks scheduled from follow-on schedule check
[2025-02-27T10:06:22.571+0000] {taskinstance.py:1956} INFO - Dependencies all met for dep_context=non-requeueable deps ti=<TaskInstance: 3_4_2_homework_assignment.upload_to_clickhouse_task scheduled__2024-01-03T00:00:00+00:00 [queued]>
[2025-02-27T10:06:22.591+0000] {taskinstance.py:1956} INFO - Dependencies all met for dep_context=requeueable deps ti=<TaskInstance: 3_4_2_homework_assignment.upload_to_clickhouse_task scheduled__2024-01-03T00:00:00+00:00 [queued]>
[2025-02-27T10:06:22.592+0000] {taskinstance.py:2170} INFO - Starting attempt 1 of 1
[2025-02-27T10:06:22.627+0000] {taskinstance.py:2191} INFO - Executing <Task(PythonOperator): upload_to_clickhouse_task> on 2024-01-03 00:00:00+00:00
[2025-02-27T10:06:22.638+0000] {standard_task_runner.py:60} INFO - Started process 3431 to run task
[2025-02-27T10:06:22.643+0000] {standard_task_runner.py:87} INFO - Running: ['airflow', 'tasks', 'run', '3_4_2_homework_assignment', 'upload_to_clickhouse_task', 'scheduled__2024-01-03T00:00:00+00:00', '--job-id', '10', '--raw', '--subdir', 'DAGS_FOLDER/3_4_2_homework_assignment.py', '--cfg-path', '/tmp/tmpobyzvlxp']
[2025-02-27T10:06:22.646+0000] {standard_task_runner.py:88} INFO - Job 10: Subtask upload_to_clickhouse_task
[2025-02-27T10:06:22.712+0000] {task_command.py:423} INFO - Running <TaskInstance: 3_4_2_homework_assignment.upload_to_clickhouse_task scheduled__2024-01-03T00:00:00+00:00 [running]> on host ea5964584459
[2025-02-27T10:06:22.809+0000] {taskinstance.py:2480} INFO - Exporting env vars: AIRFLOW_CTX_DAG_OWNER='airflow' AIRFLOW_CTX_DAG_ID='3_4_2_homework_assignment' AIRFLOW_CTX_TASK_ID='upload_to_clickhouse_task' AIRFLOW_CTX_EXECUTION_DATE='2024-01-03T00:00:00+00:00' AIRFLOW_CTX_TRY_NUMBER='1' AIRFLOW_CTX_DAG_RUN_ID='scheduled__2024-01-03T00:00:00+00:00'
[2025-02-27T10:06:22.814+0000] {taskinstance.py:2698} ERROR - Task failed with exception
Traceback (most recent call last):
  File "/home/airflow/.local/lib/python3.9/site-packages/airflow/models/taskinstance.py", line 433, in _execute_task
    result = execute_callable(context=context, **execute_callable_kwargs)
  File "/home/airflow/.local/lib/python3.9/site-packages/airflow/operators/python.py", line 199, in execute
    return_value = self.execute_callable()
  File "/home/airflow/.local/lib/python3.9/site-packages/airflow/operators/python.py", line 216, in execute_callable
    return self.python_callable(*self.op_args, **self.op_kwargs)
  File "/opt/airflow/dags/3_4_2_homework_assignment.py", line 87, in upload_to_clickhouse
    data_frame = pd.read_csv(csv_file)
  File "/home/airflow/.local/lib/python3.9/site-packages/pandas/io/parsers/readers.py", line 948, in read_csv
    return _read(filepath_or_buffer, kwds)
  File "/home/airflow/.local/lib/python3.9/site-packages/pandas/io/parsers/readers.py", line 611, in _read
    parser = TextFileReader(filepath_or_buffer, **kwds)
  File "/home/airflow/.local/lib/python3.9/site-packages/pandas/io/parsers/readers.py", line 1448, in __init__
    self._engine = self._make_engine(f, self.engine)
  File "/home/airflow/.local/lib/python3.9/site-packages/pandas/io/parsers/readers.py", line 1705, in _make_engine
    self.handles = get_handle(
  File "/home/airflow/.local/lib/python3.9/site-packages/pandas/io/common.py", line 863, in get_handle
    handle = open(
FileNotFoundError: [Errno 2] No such file or directory: 'extracted_data_csv.csv'
[2025-02-27T10:06:22.823+0000] {taskinstance.py:1138} INFO - Marking task as FAILED. dag_id=3_4_2_homework_assignment, task_id=upload_to_clickhouse_task, execution_date=20240103T000000, start_date=20250227T100622, end_date=20250227T100622
[2025-02-27T10:06:22.842+0000] {standard_task_runner.py:107} ERROR - Failed to execute job 10 for task upload_to_clickhouse_task ([Errno 2] No such file or directory: 'extracted_data_csv.csv'; 3431)
[2025-02-27T10:06:22.898+0000] {local_task_job_runner.py:234} INFO - Task exited with return code 1
[2025-02-27T10:06:22.911+0000] {taskinstance.py:3280} INFO - 0 downstream tasks scheduled from follow-on schedule check
[2025-02-27T10:12:15.143+0000] {taskinstance.py:1956} INFO - Dependencies all met for dep_context=non-requeueable deps ti=<TaskInstance: 3_4_2_homework_assignment.upload_to_clickhouse_task scheduled__2024-01-03T00:00:00+00:00 [queued]>
[2025-02-27T10:12:15.148+0000] {taskinstance.py:1956} INFO - Dependencies all met for dep_context=requeueable deps ti=<TaskInstance: 3_4_2_homework_assignment.upload_to_clickhouse_task scheduled__2024-01-03T00:00:00+00:00 [queued]>
[2025-02-27T10:12:15.148+0000] {taskinstance.py:2170} INFO - Starting attempt 1 of 1
[2025-02-27T10:12:15.158+0000] {taskinstance.py:2191} INFO - Executing <Task(PythonOperator): upload_to_clickhouse_task> on 2024-01-03 00:00:00+00:00
[2025-02-27T10:12:15.163+0000] {standard_task_runner.py:60} INFO - Started process 4042 to run task
[2025-02-27T10:12:15.165+0000] {standard_task_runner.py:87} INFO - Running: ['airflow', 'tasks', 'run', '3_4_2_homework_assignment', 'upload_to_clickhouse_task', 'scheduled__2024-01-03T00:00:00+00:00', '--job-id', '8', '--raw', '--subdir', 'DAGS_FOLDER/3_4_2_homework_assignment.py', '--cfg-path', '/tmp/tmp3_zgvhcb']
[2025-02-27T10:12:15.166+0000] {standard_task_runner.py:88} INFO - Job 8: Subtask upload_to_clickhouse_task
[2025-02-27T10:12:15.193+0000] {task_command.py:423} INFO - Running <TaskInstance: 3_4_2_homework_assignment.upload_to_clickhouse_task scheduled__2024-01-03T00:00:00+00:00 [running]> on host ea5964584459
[2025-02-27T10:12:15.238+0000] {taskinstance.py:2480} INFO - Exporting env vars: AIRFLOW_CTX_DAG_OWNER='airflow' AIRFLOW_CTX_DAG_ID='3_4_2_homework_assignment' AIRFLOW_CTX_TASK_ID='upload_to_clickhouse_task' AIRFLOW_CTX_EXECUTION_DATE='2024-01-03T00:00:00+00:00' AIRFLOW_CTX_TRY_NUMBER='1' AIRFLOW_CTX_DAG_RUN_ID='scheduled__2024-01-03T00:00:00+00:00'
[2025-02-27T10:12:15.240+0000] {taskinstance.py:2698} ERROR - Task failed with exception
Traceback (most recent call last):
  File "/home/airflow/.local/lib/python3.9/site-packages/airflow/models/taskinstance.py", line 433, in _execute_task
    result = execute_callable(context=context, **execute_callable_kwargs)
  File "/home/airflow/.local/lib/python3.9/site-packages/airflow/operators/python.py", line 199, in execute
    return_value = self.execute_callable()
  File "/home/airflow/.local/lib/python3.9/site-packages/airflow/operators/python.py", line 216, in execute_callable
    return self.python_callable(*self.op_args, **self.op_kwargs)
  File "/opt/airflow/dags/3_4_2_homework_assignment.py", line 88, in upload_to_clickhouse
    data_frame = pd.read_csv(csv_file)
  File "/home/airflow/.local/lib/python3.9/site-packages/pandas/io/parsers/readers.py", line 948, in read_csv
    return _read(filepath_or_buffer, kwds)
  File "/home/airflow/.local/lib/python3.9/site-packages/pandas/io/parsers/readers.py", line 611, in _read
    parser = TextFileReader(filepath_or_buffer, **kwds)
  File "/home/airflow/.local/lib/python3.9/site-packages/pandas/io/parsers/readers.py", line 1448, in __init__
    self._engine = self._make_engine(f, self.engine)
  File "/home/airflow/.local/lib/python3.9/site-packages/pandas/io/parsers/readers.py", line 1705, in _make_engine
    self.handles = get_handle(
  File "/home/airflow/.local/lib/python3.9/site-packages/pandas/io/common.py", line 863, in get_handle
    handle = open(
FileNotFoundError: [Errno 2] No such file or directory: 'extracted_data_csv.csv'
[2025-02-27T10:12:15.253+0000] {taskinstance.py:1138} INFO - Marking task as FAILED. dag_id=3_4_2_homework_assignment, task_id=upload_to_clickhouse_task, execution_date=20240103T000000, start_date=20250227T101215, end_date=20250227T101215
[2025-02-27T10:12:15.261+0000] {standard_task_runner.py:107} ERROR - Failed to execute job 8 for task upload_to_clickhouse_task ([Errno 2] No such file or directory: 'extracted_data_csv.csv'; 4042)
[2025-02-27T10:12:15.298+0000] {local_task_job_runner.py:234} INFO - Task exited with return code 1
[2025-02-27T10:12:15.307+0000] {taskinstance.py:3280} INFO - 0 downstream tasks scheduled from follow-on schedule check
[2025-02-27T10:14:01.733+0000] {taskinstance.py:1956} INFO - Dependencies all met for dep_context=non-requeueable deps ti=<TaskInstance: 3_4_2_homework_assignment.upload_to_clickhouse_task scheduled__2024-01-03T00:00:00+00:00 [queued]>
[2025-02-27T10:14:01.738+0000] {taskinstance.py:1956} INFO - Dependencies all met for dep_context=requeueable deps ti=<TaskInstance: 3_4_2_homework_assignment.upload_to_clickhouse_task scheduled__2024-01-03T00:00:00+00:00 [queued]>
[2025-02-27T10:14:01.739+0000] {taskinstance.py:2170} INFO - Starting attempt 1 of 1
[2025-02-27T10:14:01.751+0000] {taskinstance.py:2191} INFO - Executing <Task(PythonOperator): upload_to_clickhouse_task> on 2024-01-03 00:00:00+00:00
[2025-02-27T10:14:01.756+0000] {standard_task_runner.py:60} INFO - Started process 4326 to run task
[2025-02-27T10:14:01.758+0000] {standard_task_runner.py:87} INFO - Running: ['airflow', 'tasks', 'run', '3_4_2_homework_assignment', 'upload_to_clickhouse_task', 'scheduled__2024-01-03T00:00:00+00:00', '--job-id', '10', '--raw', '--subdir', 'DAGS_FOLDER/3_4_2_homework_assignment.py', '--cfg-path', '/tmp/tmpqhsrx6x9']
[2025-02-27T10:14:01.760+0000] {standard_task_runner.py:88} INFO - Job 10: Subtask upload_to_clickhouse_task
[2025-02-27T10:14:01.785+0000] {task_command.py:423} INFO - Running <TaskInstance: 3_4_2_homework_assignment.upload_to_clickhouse_task scheduled__2024-01-03T00:00:00+00:00 [running]> on host ea5964584459
[2025-02-27T10:14:01.823+0000] {taskinstance.py:2480} INFO - Exporting env vars: AIRFLOW_CTX_DAG_OWNER='airflow' AIRFLOW_CTX_DAG_ID='3_4_2_homework_assignment' AIRFLOW_CTX_TASK_ID='upload_to_clickhouse_task' AIRFLOW_CTX_EXECUTION_DATE='2024-01-03T00:00:00+00:00' AIRFLOW_CTX_TRY_NUMBER='1' AIRFLOW_CTX_DAG_RUN_ID='scheduled__2024-01-03T00:00:00+00:00'
[2025-02-27T10:14:01.829+0000] {connection.py:411} WARNING - Failed to connect to None:9000
Traceback (most recent call last):
  File "/home/airflow/.local/lib/python3.9/site-packages/clickhouse_driver/connection.py", line 399, in connect
    return self._init_connection(host, port)
  File "/home/airflow/.local/lib/python3.9/site-packages/clickhouse_driver/connection.py", line 329, in _init_connection
    self.socket = self._create_socket(host, port)
  File "/home/airflow/.local/lib/python3.9/site-packages/clickhouse_driver/connection.py", line 301, in _create_socket
    raise err
  File "/home/airflow/.local/lib/python3.9/site-packages/clickhouse_driver/connection.py", line 292, in _create_socket
    sock.connect(sa)
ConnectionRefusedError: [Errno 111] Connection refused
[2025-02-27T10:14:01.829+0000] {taskinstance.py:2698} ERROR - Task failed with exception
Traceback (most recent call last):
  File "/home/airflow/.local/lib/python3.9/site-packages/airflow/models/taskinstance.py", line 433, in _execute_task
    result = execute_callable(context=context, **execute_callable_kwargs)
  File "/home/airflow/.local/lib/python3.9/site-packages/airflow/operators/python.py", line 199, in execute
    return_value = self.execute_callable()
  File "/home/airflow/.local/lib/python3.9/site-packages/airflow/operators/python.py", line 216, in execute_callable
    return self.python_callable(*self.op_args, **self.op_kwargs)
  File "/opt/airflow/dags/3_4_2_homework_assignment.py", line 90, in upload_to_clickhouse
    client.execute(f'CREATE TABLE IF NOT EXISTS {table_name} (source String, currency String, value Float, date String) ENGINE Log')
  File "/home/airflow/.local/lib/python3.9/site-packages/clickhouse_driver/client.py", line 370, in execute
    with self.disconnect_on_error(query, settings):
  File "/usr/local/lib/python3.9/contextlib.py", line 119, in __enter__
    return next(self.gen)
  File "/home/airflow/.local/lib/python3.9/site-packages/clickhouse_driver/client.py", line 313, in disconnect_on_error
    self.establish_connection(settings)
  File "/home/airflow/.local/lib/python3.9/site-packages/clickhouse_driver/client.py", line 300, in establish_connection
    self.connection.force_connect()
  File "/home/airflow/.local/lib/python3.9/site-packages/clickhouse_driver/connection.py", line 258, in force_connect
    self.connect()
  File "/home/airflow/.local/lib/python3.9/site-packages/clickhouse_driver/connection.py", line 420, in connect
    raise err
clickhouse_driver.errors.NetworkError: Code: 210. Connection refused (None:9000)
[2025-02-27T10:14:01.834+0000] {taskinstance.py:1138} INFO - Marking task as FAILED. dag_id=3_4_2_homework_assignment, task_id=upload_to_clickhouse_task, execution_date=20240103T000000, start_date=20250227T101401, end_date=20250227T101401
[2025-02-27T10:14:01.841+0000] {standard_task_runner.py:107} ERROR - Failed to execute job 10 for task upload_to_clickhouse_task (Code: 210. Connection refused (None:9000); 4326)
[2025-02-27T10:14:01.852+0000] {local_task_job_runner.py:234} INFO - Task exited with return code 1
[2025-02-27T10:14:01.860+0000] {taskinstance.py:3280} INFO - 0 downstream tasks scheduled from follow-on schedule check
[2025-02-27T10:19:15.703+0000] {taskinstance.py:1956} INFO - Dependencies all met for dep_context=non-requeueable deps ti=<TaskInstance: 3_4_2_homework_assignment.upload_to_clickhouse_task scheduled__2024-01-03T00:00:00+00:00 [queued]>
[2025-02-27T10:19:15.708+0000] {taskinstance.py:1956} INFO - Dependencies all met for dep_context=requeueable deps ti=<TaskInstance: 3_4_2_homework_assignment.upload_to_clickhouse_task scheduled__2024-01-03T00:00:00+00:00 [queued]>
[2025-02-27T10:19:15.708+0000] {taskinstance.py:2170} INFO - Starting attempt 1 of 1
[2025-02-27T10:19:15.719+0000] {taskinstance.py:2191} INFO - Executing <Task(PythonOperator): upload_to_clickhouse_task> on 2024-01-03 00:00:00+00:00
[2025-02-27T10:19:15.724+0000] {standard_task_runner.py:60} INFO - Started process 4919 to run task
[2025-02-27T10:19:15.726+0000] {standard_task_runner.py:87} INFO - Running: ['airflow', 'tasks', 'run', '3_4_2_homework_assignment', 'upload_to_clickhouse_task', 'scheduled__2024-01-03T00:00:00+00:00', '--job-id', '10', '--raw', '--subdir', 'DAGS_FOLDER/3_4_2_homework_assignment.py', '--cfg-path', '/tmp/tmpsg2440o1']
[2025-02-27T10:19:15.727+0000] {standard_task_runner.py:88} INFO - Job 10: Subtask upload_to_clickhouse_task
[2025-02-27T10:19:15.752+0000] {task_command.py:423} INFO - Running <TaskInstance: 3_4_2_homework_assignment.upload_to_clickhouse_task scheduled__2024-01-03T00:00:00+00:00 [running]> on host ea5964584459
[2025-02-27T10:19:15.790+0000] {taskinstance.py:2480} INFO - Exporting env vars: AIRFLOW_CTX_DAG_OWNER='airflow' AIRFLOW_CTX_DAG_ID='3_4_2_homework_assignment' AIRFLOW_CTX_TASK_ID='upload_to_clickhouse_task' AIRFLOW_CTX_EXECUTION_DATE='2024-01-03T00:00:00+00:00' AIRFLOW_CTX_TRY_NUMBER='1' AIRFLOW_CTX_DAG_RUN_ID='scheduled__2024-01-03T00:00:00+00:00'
[2025-02-27T10:19:15.796+0000] {connection.py:411} WARNING - Failed to connect to None:9000
Traceback (most recent call last):
  File "/home/airflow/.local/lib/python3.9/site-packages/clickhouse_driver/connection.py", line 399, in connect
    return self._init_connection(host, port)
  File "/home/airflow/.local/lib/python3.9/site-packages/clickhouse_driver/connection.py", line 329, in _init_connection
    self.socket = self._create_socket(host, port)
  File "/home/airflow/.local/lib/python3.9/site-packages/clickhouse_driver/connection.py", line 301, in _create_socket
    raise err
  File "/home/airflow/.local/lib/python3.9/site-packages/clickhouse_driver/connection.py", line 292, in _create_socket
    sock.connect(sa)
ConnectionRefusedError: [Errno 111] Connection refused
[2025-02-27T10:19:15.797+0000] {taskinstance.py:2698} ERROR - Task failed with exception
Traceback (most recent call last):
  File "/home/airflow/.local/lib/python3.9/site-packages/airflow/models/taskinstance.py", line 433, in _execute_task
    result = execute_callable(context=context, **execute_callable_kwargs)
  File "/home/airflow/.local/lib/python3.9/site-packages/airflow/operators/python.py", line 199, in execute
    return_value = self.execute_callable()
  File "/home/airflow/.local/lib/python3.9/site-packages/airflow/operators/python.py", line 216, in execute_callable
    return self.python_callable(*self.op_args, **self.op_kwargs)
  File "/opt/airflow/dags/3_4_2_homework_assignment.py", line 90, in upload_to_clickhouse
    client.execute(f'CREATE TABLE IF NOT EXISTS {table_name} (source String, currency String, value Float, date String) ENGINE Log')
  File "/home/airflow/.local/lib/python3.9/site-packages/clickhouse_driver/client.py", line 370, in execute
    with self.disconnect_on_error(query, settings):
  File "/usr/local/lib/python3.9/contextlib.py", line 119, in __enter__
    return next(self.gen)
  File "/home/airflow/.local/lib/python3.9/site-packages/clickhouse_driver/client.py", line 313, in disconnect_on_error
    self.establish_connection(settings)
  File "/home/airflow/.local/lib/python3.9/site-packages/clickhouse_driver/client.py", line 300, in establish_connection
    self.connection.force_connect()
  File "/home/airflow/.local/lib/python3.9/site-packages/clickhouse_driver/connection.py", line 258, in force_connect
    self.connect()
  File "/home/airflow/.local/lib/python3.9/site-packages/clickhouse_driver/connection.py", line 420, in connect
    raise err
clickhouse_driver.errors.NetworkError: Code: 210. Connection refused (None:9000)
[2025-02-27T10:19:15.801+0000] {taskinstance.py:1138} INFO - Marking task as FAILED. dag_id=3_4_2_homework_assignment, task_id=upload_to_clickhouse_task, execution_date=20240103T000000, start_date=20250227T101915, end_date=20250227T101915
[2025-02-27T10:19:15.810+0000] {standard_task_runner.py:107} ERROR - Failed to execute job 10 for task upload_to_clickhouse_task (Code: 210. Connection refused (None:9000); 4919)
[2025-02-27T10:19:15.820+0000] {local_task_job_runner.py:234} INFO - Task exited with return code 1
[2025-02-27T10:19:15.828+0000] {taskinstance.py:3280} INFO - 0 downstream tasks scheduled from follow-on schedule check
[2025-02-27T10:23:54.498+0000] {taskinstance.py:1956} INFO - Dependencies all met for dep_context=non-requeueable deps ti=<TaskInstance: 3_4_2_homework_assignment.upload_to_clickhouse_task scheduled__2024-01-03T00:00:00+00:00 [queued]>
[2025-02-27T10:23:54.506+0000] {taskinstance.py:1956} INFO - Dependencies all met for dep_context=requeueable deps ti=<TaskInstance: 3_4_2_homework_assignment.upload_to_clickhouse_task scheduled__2024-01-03T00:00:00+00:00 [queued]>
[2025-02-27T10:23:54.507+0000] {taskinstance.py:2170} INFO - Starting attempt 1 of 1
[2025-02-27T10:23:54.533+0000] {taskinstance.py:2191} INFO - Executing <Task(PythonOperator): upload_to_clickhouse_task> on 2024-01-03 00:00:00+00:00
[2025-02-27T10:23:54.544+0000] {standard_task_runner.py:60} INFO - Started process 5368 to run task
[2025-02-27T10:23:54.548+0000] {standard_task_runner.py:87} INFO - Running: ['airflow', 'tasks', 'run', '3_4_2_homework_assignment', 'upload_to_clickhouse_task', 'scheduled__2024-01-03T00:00:00+00:00', '--job-id', '10', '--raw', '--subdir', 'DAGS_FOLDER/3_4_2_homework_assignment.py', '--cfg-path', '/tmp/tmpd0qldv5d']
[2025-02-27T10:23:54.552+0000] {standard_task_runner.py:88} INFO - Job 10: Subtask upload_to_clickhouse_task
[2025-02-27T10:23:54.614+0000] {task_command.py:423} INFO - Running <TaskInstance: 3_4_2_homework_assignment.upload_to_clickhouse_task scheduled__2024-01-03T00:00:00+00:00 [running]> on host ea5964584459
[2025-02-27T10:23:54.679+0000] {taskinstance.py:2480} INFO - Exporting env vars: AIRFLOW_CTX_DAG_OWNER='airflow' AIRFLOW_CTX_DAG_ID='3_4_2_homework_assignment' AIRFLOW_CTX_TASK_ID='upload_to_clickhouse_task' AIRFLOW_CTX_EXECUTION_DATE='2024-01-03T00:00:00+00:00' AIRFLOW_CTX_TRY_NUMBER='1' AIRFLOW_CTX_DAG_RUN_ID='scheduled__2024-01-03T00:00:00+00:00'
[2025-02-27T10:23:54.696+0000] {connection.py:411} WARNING - Failed to connect to None:9000
Traceback (most recent call last):
  File "/home/airflow/.local/lib/python3.9/site-packages/clickhouse_driver/connection.py", line 399, in connect
    return self._init_connection(host, port)
  File "/home/airflow/.local/lib/python3.9/site-packages/clickhouse_driver/connection.py", line 329, in _init_connection
    self.socket = self._create_socket(host, port)
  File "/home/airflow/.local/lib/python3.9/site-packages/clickhouse_driver/connection.py", line 301, in _create_socket
    raise err
  File "/home/airflow/.local/lib/python3.9/site-packages/clickhouse_driver/connection.py", line 292, in _create_socket
    sock.connect(sa)
ConnectionRefusedError: [Errno 111] Connection refused
[2025-02-27T10:23:54.699+0000] {taskinstance.py:2698} ERROR - Task failed with exception
Traceback (most recent call last):
  File "/home/airflow/.local/lib/python3.9/site-packages/airflow/models/taskinstance.py", line 433, in _execute_task
    result = execute_callable(context=context, **execute_callable_kwargs)
  File "/home/airflow/.local/lib/python3.9/site-packages/airflow/operators/python.py", line 199, in execute
    return_value = self.execute_callable()
  File "/home/airflow/.local/lib/python3.9/site-packages/airflow/operators/python.py", line 216, in execute_callable
    return self.python_callable(*self.op_args, **self.op_kwargs)
  File "/opt/airflow/dags/3_4_2_homework_assignment.py", line 90, in upload_to_clickhouse
    client.execute(f'CREATE TABLE IF NOT EXISTS {table_name} (source String, currency String, value Float, date String) ENGINE Log')
  File "/home/airflow/.local/lib/python3.9/site-packages/clickhouse_driver/client.py", line 370, in execute
    with self.disconnect_on_error(query, settings):
  File "/usr/local/lib/python3.9/contextlib.py", line 119, in __enter__
    return next(self.gen)
  File "/home/airflow/.local/lib/python3.9/site-packages/clickhouse_driver/client.py", line 313, in disconnect_on_error
    self.establish_connection(settings)
  File "/home/airflow/.local/lib/python3.9/site-packages/clickhouse_driver/client.py", line 300, in establish_connection
    self.connection.force_connect()
  File "/home/airflow/.local/lib/python3.9/site-packages/clickhouse_driver/connection.py", line 258, in force_connect
    self.connect()
  File "/home/airflow/.local/lib/python3.9/site-packages/clickhouse_driver/connection.py", line 420, in connect
    raise err
clickhouse_driver.errors.NetworkError: Code: 210. Connection refused (None:9000)
[2025-02-27T10:23:54.711+0000] {taskinstance.py:1138} INFO - Marking task as FAILED. dag_id=3_4_2_homework_assignment, task_id=upload_to_clickhouse_task, execution_date=20240103T000000, start_date=20250227T102354, end_date=20250227T102354
[2025-02-27T10:23:54.733+0000] {standard_task_runner.py:107} ERROR - Failed to execute job 10 for task upload_to_clickhouse_task (Code: 210. Connection refused (None:9000); 5368)
[2025-02-27T10:23:54.765+0000] {local_task_job_runner.py:234} INFO - Task exited with return code 1
[2025-02-27T10:23:54.781+0000] {taskinstance.py:3280} INFO - 0 downstream tasks scheduled from follow-on schedule check
[2025-02-27T10:26:41.890+0000] {taskinstance.py:1956} INFO - Dependencies all met for dep_context=non-requeueable deps ti=<TaskInstance: 3_4_2_homework_assignment.upload_to_clickhouse_task scheduled__2024-01-03T00:00:00+00:00 [queued]>
[2025-02-27T10:26:41.894+0000] {taskinstance.py:1956} INFO - Dependencies all met for dep_context=requeueable deps ti=<TaskInstance: 3_4_2_homework_assignment.upload_to_clickhouse_task scheduled__2024-01-03T00:00:00+00:00 [queued]>
[2025-02-27T10:26:41.895+0000] {taskinstance.py:2170} INFO - Starting attempt 1 of 1
[2025-02-27T10:26:41.906+0000] {taskinstance.py:2191} INFO - Executing <Task(PythonOperator): upload_to_clickhouse_task> on 2024-01-03 00:00:00+00:00
[2025-02-27T10:26:41.911+0000] {standard_task_runner.py:60} INFO - Started process 5661 to run task
[2025-02-27T10:26:41.913+0000] {standard_task_runner.py:87} INFO - Running: ['airflow', 'tasks', 'run', '3_4_2_homework_assignment', 'upload_to_clickhouse_task', 'scheduled__2024-01-03T00:00:00+00:00', '--job-id', '10', '--raw', '--subdir', 'DAGS_FOLDER/3_4_2_homework_assignment.py', '--cfg-path', '/tmp/tmpesf1407o']
[2025-02-27T10:26:41.914+0000] {standard_task_runner.py:88} INFO - Job 10: Subtask upload_to_clickhouse_task
[2025-02-27T10:26:41.939+0000] {task_command.py:423} INFO - Running <TaskInstance: 3_4_2_homework_assignment.upload_to_clickhouse_task scheduled__2024-01-03T00:00:00+00:00 [running]> on host ea5964584459
[2025-02-27T10:26:41.976+0000] {taskinstance.py:2480} INFO - Exporting env vars: AIRFLOW_CTX_DAG_OWNER='airflow' AIRFLOW_CTX_DAG_ID='3_4_2_homework_assignment' AIRFLOW_CTX_TASK_ID='upload_to_clickhouse_task' AIRFLOW_CTX_EXECUTION_DATE='2024-01-03T00:00:00+00:00' AIRFLOW_CTX_TRY_NUMBER='1' AIRFLOW_CTX_DAG_RUN_ID='scheduled__2024-01-03T00:00:00+00:00'
[2025-02-27T10:26:41.988+0000] {taskinstance.py:2698} ERROR - Task failed with exception
Traceback (most recent call last):
  File "/home/airflow/.local/lib/python3.9/site-packages/airflow/models/taskinstance.py", line 433, in _execute_task
    result = execute_callable(context=context, **execute_callable_kwargs)
  File "/home/airflow/.local/lib/python3.9/site-packages/airflow/operators/python.py", line 199, in execute
    return_value = self.execute_callable()
  File "/home/airflow/.local/lib/python3.9/site-packages/airflow/operators/python.py", line 216, in execute_callable
    return self.python_callable(*self.op_args, **self.op_kwargs)
  File "/opt/airflow/dags/3_4_2_homework_assignment.py", line 92, in upload_to_clickhouse
    client.execute(f'INSERT INTO {table_name} VALUES', data_frame.to_dict('records'))
  File "/home/airflow/.local/lib/python3.9/site-packages/clickhouse_driver/client.py", line 376, in execute
    rv = self.process_insert_query(
  File "/home/airflow/.local/lib/python3.9/site-packages/clickhouse_driver/client.py", line 607, in process_insert_query
    rv = self.send_data(sample_block, data,
  File "/home/airflow/.local/lib/python3.9/site-packages/clickhouse_driver/client.py", line 658, in send_data
    block = block_cls(sample_block.columns_with_types, chunk,
  File "/home/airflow/.local/lib/python3.9/site-packages/clickhouse_driver/block.py", line 40, in __init__
    self.data = self.normalize(data or [])
  File "/home/airflow/.local/lib/python3.9/site-packages/clickhouse_driver/block.py", line 128, in normalize
    self._mutate_dicts_to_rows(data)
  File "/home/airflow/.local/lib/python3.9/site-packages/clickhouse_driver/block.py", line 159, in _mutate_dicts_to_rows
    return self._pure_mutate_dicts_to_rows(
  File "/home/airflow/.local/lib/python3.9/site-packages/clickhouse_driver/block.py", line 186, in _pure_mutate_dicts_to_rows
    new_data.append(row[name])
KeyError: 'source'
[2025-02-27T10:26:41.994+0000] {taskinstance.py:1138} INFO - Marking task as FAILED. dag_id=3_4_2_homework_assignment, task_id=upload_to_clickhouse_task, execution_date=20240103T000000, start_date=20250227T102641, end_date=20250227T102641
[2025-02-27T10:26:42.002+0000] {standard_task_runner.py:107} ERROR - Failed to execute job 10 for task upload_to_clickhouse_task ('source'; 5661)
[2025-02-27T10:26:42.048+0000] {local_task_job_runner.py:234} INFO - Task exited with return code 1
[2025-02-27T10:26:42.057+0000] {taskinstance.py:3280} INFO - 0 downstream tasks scheduled from follow-on schedule check
[2025-02-27T10:35:04.252+0000] {taskinstance.py:1956} INFO - Dependencies all met for dep_context=non-requeueable deps ti=<TaskInstance: 3_4_2_homework_assignment.upload_to_clickhouse_task scheduled__2024-01-03T00:00:00+00:00 [queued]>
[2025-02-27T10:35:04.258+0000] {taskinstance.py:1956} INFO - Dependencies all met for dep_context=requeueable deps ti=<TaskInstance: 3_4_2_homework_assignment.upload_to_clickhouse_task scheduled__2024-01-03T00:00:00+00:00 [queued]>
[2025-02-27T10:35:04.259+0000] {taskinstance.py:2170} INFO - Starting attempt 1 of 1
[2025-02-27T10:35:04.273+0000] {taskinstance.py:2191} INFO - Executing <Task(PythonOperator): upload_to_clickhouse_task> on 2024-01-03 00:00:00+00:00
[2025-02-27T10:35:04.279+0000] {standard_task_runner.py:60} INFO - Started process 6321 to run task
[2025-02-27T10:35:04.282+0000] {standard_task_runner.py:87} INFO - Running: ['airflow', 'tasks', 'run', '3_4_2_homework_assignment', 'upload_to_clickhouse_task', 'scheduled__2024-01-03T00:00:00+00:00', '--job-id', '10', '--raw', '--subdir', 'DAGS_FOLDER/3_4_2_homework_assignment.py', '--cfg-path', '/tmp/tmppkbh00zh']
[2025-02-27T10:35:04.283+0000] {standard_task_runner.py:88} INFO - Job 10: Subtask upload_to_clickhouse_task
[2025-02-27T10:35:04.311+0000] {task_command.py:423} INFO - Running <TaskInstance: 3_4_2_homework_assignment.upload_to_clickhouse_task scheduled__2024-01-03T00:00:00+00:00 [running]> on host ea5964584459
[2025-02-27T10:35:04.350+0000] {taskinstance.py:2480} INFO - Exporting env vars: AIRFLOW_CTX_DAG_OWNER='airflow' AIRFLOW_CTX_DAG_ID='3_4_2_homework_assignment' AIRFLOW_CTX_TASK_ID='upload_to_clickhouse_task' AIRFLOW_CTX_EXECUTION_DATE='2024-01-03T00:00:00+00:00' AIRFLOW_CTX_TRY_NUMBER='1' AIRFLOW_CTX_DAG_RUN_ID='scheduled__2024-01-03T00:00:00+00:00'
[2025-02-27T10:35:04.361+0000] {taskinstance.py:2698} ERROR - Task failed with exception
Traceback (most recent call last):
  File "/home/airflow/.local/lib/python3.9/site-packages/airflow/models/taskinstance.py", line 433, in _execute_task
    result = execute_callable(context=context, **execute_callable_kwargs)
  File "/home/airflow/.local/lib/python3.9/site-packages/airflow/operators/python.py", line 199, in execute
    return_value = self.execute_callable()
  File "/home/airflow/.local/lib/python3.9/site-packages/airflow/operators/python.py", line 216, in execute_callable
    return self.python_callable(*self.op_args, **self.op_kwargs)
  File "/opt/airflow/dags/3_4_2_homework_assignment.py", line 93, in upload_to_clickhouse
    client.execute(f'INSERT INTO {table_name} VALUES', data_frame.to_dict('records'))
  File "/home/airflow/.local/lib/python3.9/site-packages/clickhouse_driver/client.py", line 376, in execute
    rv = self.process_insert_query(
  File "/home/airflow/.local/lib/python3.9/site-packages/clickhouse_driver/client.py", line 607, in process_insert_query
    rv = self.send_data(sample_block, data,
  File "/home/airflow/.local/lib/python3.9/site-packages/clickhouse_driver/client.py", line 658, in send_data
    block = block_cls(sample_block.columns_with_types, chunk,
  File "/home/airflow/.local/lib/python3.9/site-packages/clickhouse_driver/block.py", line 40, in __init__
    self.data = self.normalize(data or [])
  File "/home/airflow/.local/lib/python3.9/site-packages/clickhouse_driver/block.py", line 128, in normalize
    self._mutate_dicts_to_rows(data)
  File "/home/airflow/.local/lib/python3.9/site-packages/clickhouse_driver/block.py", line 159, in _mutate_dicts_to_rows
    return self._pure_mutate_dicts_to_rows(
  File "/home/airflow/.local/lib/python3.9/site-packages/clickhouse_driver/block.py", line 186, in _pure_mutate_dicts_to_rows
    new_data.append(row[name])
KeyError: 'source'
[2025-02-27T10:35:04.368+0000] {taskinstance.py:1138} INFO - Marking task as FAILED. dag_id=3_4_2_homework_assignment, task_id=upload_to_clickhouse_task, execution_date=20240103T000000, start_date=20250227T103504, end_date=20250227T103504
[2025-02-27T10:35:04.376+0000] {standard_task_runner.py:107} ERROR - Failed to execute job 10 for task upload_to_clickhouse_task ('source'; 6321)
[2025-02-27T10:35:04.415+0000] {local_task_job_runner.py:234} INFO - Task exited with return code 1
[2025-02-27T10:35:04.423+0000] {taskinstance.py:3280} INFO - 0 downstream tasks scheduled from follow-on schedule check
[2025-02-27T10:44:56.699+0000] {taskinstance.py:1956} INFO - Dependencies all met for dep_context=non-requeueable deps ti=<TaskInstance: 3_4_2_homework_assignment.upload_to_clickhouse_task scheduled__2024-01-03T00:00:00+00:00 [queued]>
[2025-02-27T10:44:56.704+0000] {taskinstance.py:1956} INFO - Dependencies all met for dep_context=requeueable deps ti=<TaskInstance: 3_4_2_homework_assignment.upload_to_clickhouse_task scheduled__2024-01-03T00:00:00+00:00 [queued]>
[2025-02-27T10:44:56.705+0000] {taskinstance.py:2170} INFO - Starting attempt 1 of 1
[2025-02-27T10:44:56.716+0000] {taskinstance.py:2191} INFO - Executing <Task(PythonOperator): upload_to_clickhouse_task> on 2024-01-03 00:00:00+00:00
[2025-02-27T10:44:56.724+0000] {standard_task_runner.py:60} INFO - Started process 7006 to run task
[2025-02-27T10:44:56.726+0000] {standard_task_runner.py:87} INFO - Running: ['airflow', 'tasks', 'run', '3_4_2_homework_assignment', 'upload_to_clickhouse_task', 'scheduled__2024-01-03T00:00:00+00:00', '--job-id', '10', '--raw', '--subdir', 'DAGS_FOLDER/3_4_2_homework_assignment.py', '--cfg-path', '/tmp/tmp9cdrjcmw']
[2025-02-27T10:44:56.727+0000] {standard_task_runner.py:88} INFO - Job 10: Subtask upload_to_clickhouse_task
[2025-02-27T10:44:56.757+0000] {task_command.py:423} INFO - Running <TaskInstance: 3_4_2_homework_assignment.upload_to_clickhouse_task scheduled__2024-01-03T00:00:00+00:00 [running]> on host ea5964584459
[2025-02-27T10:44:56.807+0000] {taskinstance.py:2480} INFO - Exporting env vars: AIRFLOW_CTX_DAG_OWNER='airflow' AIRFLOW_CTX_DAG_ID='3_4_2_homework_assignment' AIRFLOW_CTX_TASK_ID='upload_to_clickhouse_task' AIRFLOW_CTX_EXECUTION_DATE='2024-01-03T00:00:00+00:00' AIRFLOW_CTX_TRY_NUMBER='1' AIRFLOW_CTX_DAG_RUN_ID='scheduled__2024-01-03T00:00:00+00:00'
[2025-02-27T10:44:56.820+0000] {unix.py:142} WARNING - /etc/timezone is deprecated on Debian, and no longer reliable. Ignoring.
[2025-02-27T10:44:56.823+0000] {python.py:201} INFO - Done. Returned value was: None
[2025-02-27T10:44:56.827+0000] {taskinstance.py:1138} INFO - Marking task as SUCCESS. dag_id=3_4_2_homework_assignment, task_id=upload_to_clickhouse_task, execution_date=20240103T000000, start_date=20250227T104456, end_date=20250227T104456
[2025-02-27T10:44:56.862+0000] {local_task_job_runner.py:234} INFO - Task exited with return code 0
[2025-02-27T10:44:56.871+0000] {taskinstance.py:3280} INFO - 0 downstream tasks scheduled from follow-on schedule check
