[2025-03-03T14:24:54.067+0000] {taskinstance.py:1956} INFO - Dependencies all met for dep_context=non-requeueable deps ti=<TaskInstance: 4_4_house_assignment.upload_to_clickhouse scheduled__2024-01-03T00:00:00+00:00 [queued]>
[2025-03-03T14:24:54.085+0000] {taskinstance.py:1956} INFO - Dependencies all met for dep_context=requeueable deps ti=<TaskInstance: 4_4_house_assignment.upload_to_clickhouse scheduled__2024-01-03T00:00:00+00:00 [queued]>
[2025-03-03T14:24:54.086+0000] {taskinstance.py:2170} INFO - Starting attempt 1 of 1
[2025-03-03T14:24:54.113+0000] {taskinstance.py:2191} INFO - Executing <Task(PythonOperator): upload_to_clickhouse> on 2024-01-03 00:00:00+00:00
[2025-03-03T14:24:54.125+0000] {standard_task_runner.py:60} INFO - Started process 2229 to run task
[2025-03-03T14:24:54.130+0000] {standard_task_runner.py:87} INFO - Running: ['airflow', 'tasks', 'run', '4_4_house_assignment', 'upload_to_clickhouse', 'scheduled__2024-01-03T00:00:00+00:00', '--job-id', '12', '--raw', '--subdir', 'DAGS_FOLDER/4_4_house_assignment.py', '--cfg-path', '/tmp/tmpycqg4v4c']
[2025-03-03T14:24:54.134+0000] {standard_task_runner.py:88} INFO - Job 12: Subtask upload_to_clickhouse
[2025-03-03T14:24:54.194+0000] {task_command.py:423} INFO - Running <TaskInstance: 4_4_house_assignment.upload_to_clickhouse scheduled__2024-01-03T00:00:00+00:00 [running]> on host 9a2e4036dec3
[2025-03-03T14:24:54.285+0000] {taskinstance.py:2480} INFO - Exporting env vars: AIRFLOW_CTX_DAG_OWNER='airflow' AIRFLOW_CTX_DAG_ID='4_4_house_assignment' AIRFLOW_CTX_TASK_ID='upload_to_clickhouse' AIRFLOW_CTX_EXECUTION_DATE='2024-01-03T00:00:00+00:00' AIRFLOW_CTX_TRY_NUMBER='1' AIRFLOW_CTX_DAG_RUN_ID='scheduled__2024-01-03T00:00:00+00:00'
[2025-03-03T14:24:54.296+0000] {connection.py:411} WARNING - Failed to connect to localhost:9000
Traceback (most recent call last):
  File "/home/airflow/.local/lib/python3.9/site-packages/clickhouse_driver/connection.py", line 399, in connect
    return self._init_connection(host, port)
  File "/home/airflow/.local/lib/python3.9/site-packages/clickhouse_driver/connection.py", line 329, in _init_connection
    self.socket = self._create_socket(host, port)
  File "/home/airflow/.local/lib/python3.9/site-packages/clickhouse_driver/connection.py", line 301, in _create_socket
    raise err
  File "/home/airflow/.local/lib/python3.9/site-packages/clickhouse_driver/connection.py", line 292, in _create_socket
    sock.connect(sa)
ConnectionRefusedError: [Errno 111] Connection refused
[2025-03-03T14:24:54.298+0000] {taskinstance.py:2698} ERROR - Task failed with exception
Traceback (most recent call last):
  File "/home/airflow/.local/lib/python3.9/site-packages/airflow/models/taskinstance.py", line 433, in _execute_task
    result = execute_callable(context=context, **execute_callable_kwargs)
  File "/home/airflow/.local/lib/python3.9/site-packages/airflow/operators/python.py", line 199, in execute
    return_value = self.execute_callable()
  File "/home/airflow/.local/lib/python3.9/site-packages/airflow/operators/python.py", line 216, in execute_callable
    return self.python_callable(*self.op_args, **self.op_kwargs)
  File "/opt/airflow/dags/4_4_house_assignment.py", line 74, in upload_to_clickhouse
    client.execute(f'CREATE TABLE IF NOT EXISTS {table_name} (num_code Int64, char_code String, nominal Int64, name String, value String, date String) ENGINE Log')
  File "/home/airflow/.local/lib/python3.9/site-packages/clickhouse_driver/client.py", line 370, in execute
    with self.disconnect_on_error(query, settings):
  File "/usr/local/lib/python3.9/contextlib.py", line 119, in __enter__
    return next(self.gen)
  File "/home/airflow/.local/lib/python3.9/site-packages/clickhouse_driver/client.py", line 313, in disconnect_on_error
    self.establish_connection(settings)
  File "/home/airflow/.local/lib/python3.9/site-packages/clickhouse_driver/client.py", line 300, in establish_connection
    self.connection.force_connect()
  File "/home/airflow/.local/lib/python3.9/site-packages/clickhouse_driver/connection.py", line 258, in force_connect
    self.connect()
  File "/home/airflow/.local/lib/python3.9/site-packages/clickhouse_driver/connection.py", line 420, in connect
    raise err
clickhouse_driver.errors.NetworkError: Code: 210. Connection refused (localhost:9000)
[2025-03-03T14:24:54.307+0000] {taskinstance.py:1138} INFO - Marking task as FAILED. dag_id=4_4_house_assignment, task_id=upload_to_clickhouse, execution_date=20240103T000000, start_date=20250303T142454, end_date=20250303T142454
[2025-03-03T14:24:54.324+0000] {standard_task_runner.py:107} ERROR - Failed to execute job 12 for task upload_to_clickhouse (Code: 210. Connection refused (localhost:9000); 2229)
[2025-03-03T14:24:54.343+0000] {local_task_job_runner.py:234} INFO - Task exited with return code 1
[2025-03-03T14:24:54.356+0000] {taskinstance.py:3280} INFO - 0 downstream tasks scheduled from follow-on schedule check
[2025-03-03T14:27:41.473+0000] {taskinstance.py:1956} INFO - Dependencies all met for dep_context=non-requeueable deps ti=<TaskInstance: 4_4_house_assignment.upload_to_clickhouse scheduled__2024-01-03T00:00:00+00:00 [queued]>
[2025-03-03T14:27:41.478+0000] {taskinstance.py:1956} INFO - Dependencies all met for dep_context=requeueable deps ti=<TaskInstance: 4_4_house_assignment.upload_to_clickhouse scheduled__2024-01-03T00:00:00+00:00 [queued]>
[2025-03-03T14:27:41.478+0000] {taskinstance.py:2170} INFO - Starting attempt 1 of 1
[2025-03-03T14:27:41.488+0000] {taskinstance.py:2191} INFO - Executing <Task(PythonOperator): upload_to_clickhouse> on 2024-01-03 00:00:00+00:00
[2025-03-03T14:27:41.493+0000] {standard_task_runner.py:60} INFO - Started process 2535 to run task
[2025-03-03T14:27:41.495+0000] {standard_task_runner.py:87} INFO - Running: ['airflow', 'tasks', 'run', '4_4_house_assignment', 'upload_to_clickhouse', 'scheduled__2024-01-03T00:00:00+00:00', '--job-id', '12', '--raw', '--subdir', 'DAGS_FOLDER/4_4_house_assignment.py', '--cfg-path', '/tmp/tmp2aqw620h']
[2025-03-03T14:27:41.497+0000] {standard_task_runner.py:88} INFO - Job 12: Subtask upload_to_clickhouse
[2025-03-03T14:27:41.521+0000] {task_command.py:423} INFO - Running <TaskInstance: 4_4_house_assignment.upload_to_clickhouse scheduled__2024-01-03T00:00:00+00:00 [running]> on host 9a2e4036dec3
[2025-03-03T14:27:41.563+0000] {taskinstance.py:2480} INFO - Exporting env vars: AIRFLOW_CTX_DAG_OWNER='airflow' AIRFLOW_CTX_DAG_ID='4_4_house_assignment' AIRFLOW_CTX_TASK_ID='upload_to_clickhouse' AIRFLOW_CTX_EXECUTION_DATE='2024-01-03T00:00:00+00:00' AIRFLOW_CTX_TRY_NUMBER='1' AIRFLOW_CTX_DAG_RUN_ID='scheduled__2024-01-03T00:00:00+00:00'
[2025-03-03T14:27:41.652+0000] {unix.py:142} WARNING - /etc/timezone is deprecated on Debian, and no longer reliable. Ignoring.
[2025-03-03T14:27:41.660+0000] {python.py:201} INFO - Done. Returned value was: None
[2025-03-03T14:27:41.663+0000] {taskinstance.py:1138} INFO - Marking task as SUCCESS. dag_id=4_4_house_assignment, task_id=upload_to_clickhouse, execution_date=20240103T000000, start_date=20250303T142741, end_date=20250303T142741
[2025-03-03T14:27:41.708+0000] {local_task_job_runner.py:234} INFO - Task exited with return code 0
[2025-03-03T14:27:41.717+0000] {taskinstance.py:3280} INFO - 0 downstream tasks scheduled from follow-on schedule check
[2025-03-10T09:48:44.834+0000] {taskinstance.py:1956} INFO - Dependencies all met for dep_context=non-requeueable deps ti=<TaskInstance: 4_4_house_assignment.upload_to_clickhouse scheduled__2024-01-03T00:00:00+00:00 [queued]>
[2025-03-10T09:48:44.840+0000] {taskinstance.py:1956} INFO - Dependencies all met for dep_context=requeueable deps ti=<TaskInstance: 4_4_house_assignment.upload_to_clickhouse scheduled__2024-01-03T00:00:00+00:00 [queued]>
[2025-03-10T09:48:44.840+0000] {taskinstance.py:2170} INFO - Starting attempt 1 of 1
[2025-03-10T09:48:44.851+0000] {taskinstance.py:2191} INFO - Executing <Task(PythonOperator): upload_to_clickhouse> on 2024-01-03 00:00:00+00:00
[2025-03-10T09:48:44.857+0000] {standard_task_runner.py:60} INFO - Started process 337 to run task
[2025-03-10T09:48:44.860+0000] {standard_task_runner.py:87} INFO - Running: ['airflow', 'tasks', 'run', '4_4_house_assignment', 'upload_to_clickhouse', 'scheduled__2024-01-03T00:00:00+00:00', '--job-id', '28', '--raw', '--subdir', 'DAGS_FOLDER/4_4_house_assignment.py', '--cfg-path', '/tmp/tmpvglkw_fm']
[2025-03-10T09:48:44.861+0000] {standard_task_runner.py:88} INFO - Job 28: Subtask upload_to_clickhouse
[2025-03-10T09:48:44.889+0000] {task_command.py:423} INFO - Running <TaskInstance: 4_4_house_assignment.upload_to_clickhouse scheduled__2024-01-03T00:00:00+00:00 [running]> on host 9a2e4036dec3
[2025-03-10T09:48:44.936+0000] {taskinstance.py:2480} INFO - Exporting env vars: AIRFLOW_CTX_DAG_OWNER='airflow' AIRFLOW_CTX_DAG_ID='4_4_house_assignment' AIRFLOW_CTX_TASK_ID='upload_to_clickhouse' AIRFLOW_CTX_EXECUTION_DATE='2024-01-03T00:00:00+00:00' AIRFLOW_CTX_TRY_NUMBER='1' AIRFLOW_CTX_DAG_RUN_ID='scheduled__2024-01-03T00:00:00+00:00'
[2025-03-10T09:48:44.952+0000] {unix.py:142} WARNING - /etc/timezone is deprecated on Debian, and no longer reliable. Ignoring.
[2025-03-10T09:48:44.956+0000] {python.py:201} INFO - Done. Returned value was: None
[2025-03-10T09:48:44.960+0000] {taskinstance.py:1138} INFO - Marking task as SUCCESS. dag_id=4_4_house_assignment, task_id=upload_to_clickhouse, execution_date=20240103T000000, start_date=20250310T094844, end_date=20250310T094844
[2025-03-10T09:48:44.993+0000] {local_task_job_runner.py:234} INFO - Task exited with return code 0
[2025-03-10T09:48:45.002+0000] {taskinstance.py:3280} INFO - 0 downstream tasks scheduled from follow-on schedule check
[2025-03-12T14:51:03.692+0000] {taskinstance.py:1956} INFO - Dependencies all met for dep_context=non-requeueable deps ti=<TaskInstance: 4_4_house_assignment.upload_to_clickhouse scheduled__2024-01-03T00:00:00+00:00 [queued]>
[2025-03-12T14:51:03.698+0000] {taskinstance.py:1956} INFO - Dependencies all met for dep_context=requeueable deps ti=<TaskInstance: 4_4_house_assignment.upload_to_clickhouse scheduled__2024-01-03T00:00:00+00:00 [queued]>
[2025-03-12T14:51:03.699+0000] {taskinstance.py:2170} INFO - Starting attempt 1 of 1
[2025-03-12T14:51:03.710+0000] {taskinstance.py:2191} INFO - Executing <Task(PythonOperator): upload_to_clickhouse> on 2024-01-03 00:00:00+00:00
[2025-03-12T14:51:03.715+0000] {standard_task_runner.py:60} INFO - Started process 2565 to run task
[2025-03-12T14:51:03.717+0000] {standard_task_runner.py:87} INFO - Running: ['airflow', 'tasks', 'run', '4_4_house_assignment', 'upload_to_clickhouse', 'scheduled__2024-01-03T00:00:00+00:00', '--job-id', '26', '--raw', '--subdir', 'DAGS_FOLDER/4_4_house_assignment.py', '--cfg-path', '/tmp/tmp22fz9n_a']
[2025-03-12T14:51:03.719+0000] {standard_task_runner.py:88} INFO - Job 26: Subtask upload_to_clickhouse
[2025-03-12T14:51:03.748+0000] {task_command.py:423} INFO - Running <TaskInstance: 4_4_house_assignment.upload_to_clickhouse scheduled__2024-01-03T00:00:00+00:00 [running]> on host 13d00b3af9e0
[2025-03-12T14:51:03.800+0000] {taskinstance.py:2480} INFO - Exporting env vars: AIRFLOW_CTX_DAG_OWNER='airflow' AIRFLOW_CTX_DAG_ID='4_4_house_assignment' AIRFLOW_CTX_TASK_ID='upload_to_clickhouse' AIRFLOW_CTX_EXECUTION_DATE='2024-01-03T00:00:00+00:00' AIRFLOW_CTX_TRY_NUMBER='1' AIRFLOW_CTX_DAG_RUN_ID='scheduled__2024-01-03T00:00:00+00:00'
[2025-03-12T14:51:03.812+0000] {connection.py:411} WARNING - Failed to connect to localhost:9000
Traceback (most recent call last):
  File "/home/airflow/.local/lib/python3.9/site-packages/clickhouse_driver/connection.py", line 399, in connect
    return self._init_connection(host, port)
  File "/home/airflow/.local/lib/python3.9/site-packages/clickhouse_driver/connection.py", line 329, in _init_connection
    self.socket = self._create_socket(host, port)
  File "/home/airflow/.local/lib/python3.9/site-packages/clickhouse_driver/connection.py", line 301, in _create_socket
    raise err
  File "/home/airflow/.local/lib/python3.9/site-packages/clickhouse_driver/connection.py", line 292, in _create_socket
    sock.connect(sa)
ConnectionRefusedError: [Errno 111] Connection refused
[2025-03-12T14:51:03.813+0000] {taskinstance.py:2698} ERROR - Task failed with exception
Traceback (most recent call last):
  File "/home/airflow/.local/lib/python3.9/site-packages/airflow/models/taskinstance.py", line 433, in _execute_task
    result = execute_callable(context=context, **execute_callable_kwargs)
  File "/home/airflow/.local/lib/python3.9/site-packages/airflow/operators/python.py", line 199, in execute
    return_value = self.execute_callable()
  File "/home/airflow/.local/lib/python3.9/site-packages/airflow/operators/python.py", line 216, in execute_callable
    return self.python_callable(*self.op_args, **self.op_kwargs)
  File "/opt/airflow/dags/4_4_house_assignment.py", line 74, in upload_to_clickhouse
    client.execute(f'CREATE TABLE IF NOT EXISTS {table_name} (num_code Int64, char_code String, nominal Int64, name String, value String, date String) ENGINE Log')
  File "/home/airflow/.local/lib/python3.9/site-packages/clickhouse_driver/client.py", line 370, in execute
    with self.disconnect_on_error(query, settings):
  File "/usr/local/lib/python3.9/contextlib.py", line 119, in __enter__
    return next(self.gen)
  File "/home/airflow/.local/lib/python3.9/site-packages/clickhouse_driver/client.py", line 313, in disconnect_on_error
    self.establish_connection(settings)
  File "/home/airflow/.local/lib/python3.9/site-packages/clickhouse_driver/client.py", line 300, in establish_connection
    self.connection.force_connect()
  File "/home/airflow/.local/lib/python3.9/site-packages/clickhouse_driver/connection.py", line 258, in force_connect
    self.connect()
  File "/home/airflow/.local/lib/python3.9/site-packages/clickhouse_driver/connection.py", line 420, in connect
    raise err
clickhouse_driver.errors.NetworkError: Code: 210. Connection refused (localhost:9000)
[2025-03-12T14:51:03.821+0000] {taskinstance.py:1138} INFO - Marking task as FAILED. dag_id=4_4_house_assignment, task_id=upload_to_clickhouse, execution_date=20240103T000000, start_date=20250312T145103, end_date=20250312T145103
[2025-03-12T14:51:03.830+0000] {standard_task_runner.py:107} ERROR - Failed to execute job 26 for task upload_to_clickhouse (Code: 210. Connection refused (localhost:9000); 2565)
[2025-03-12T14:51:03.851+0000] {local_task_job_runner.py:234} INFO - Task exited with return code 1
[2025-03-12T14:51:03.860+0000] {taskinstance.py:3280} INFO - 0 downstream tasks scheduled from follow-on schedule check
