[2025-02-27T09:49:47.999+0000] {taskinstance.py:1956} INFO - Dependencies all met for dep_context=non-requeueable deps ti=<TaskInstance: 3_4_2_homework_assignment.upload_to_clickhouse_task scheduled__2024-01-01T00:00:00+00:00 [queued]>
[2025-02-27T09:49:48.004+0000] {taskinstance.py:1956} INFO - Dependencies all met for dep_context=requeueable deps ti=<TaskInstance: 3_4_2_homework_assignment.upload_to_clickhouse_task scheduled__2024-01-01T00:00:00+00:00 [queued]>
[2025-02-27T09:49:48.005+0000] {taskinstance.py:2170} INFO - Starting attempt 1 of 1
[2025-02-27T09:49:48.016+0000] {taskinstance.py:2191} INFO - Executing <Task(PythonOperator): upload_to_clickhouse_task> on 2024-01-01 00:00:00+00:00
[2025-02-27T09:49:48.022+0000] {standard_task_runner.py:60} INFO - Started process 2097 to run task
[2025-02-27T09:49:48.024+0000] {standard_task_runner.py:87} INFO - Running: ['airflow', 'tasks', 'run', '3_4_2_homework_assignment', 'upload_to_clickhouse_task', 'scheduled__2024-01-01T00:00:00+00:00', '--job-id', '4', '--raw', '--subdir', 'DAGS_FOLDER/3_4_2_homework_assignment.py', '--cfg-path', '/tmp/tmp533761ot']
[2025-02-27T09:49:48.025+0000] {standard_task_runner.py:88} INFO - Job 4: Subtask upload_to_clickhouse_task
[2025-02-27T09:49:48.053+0000] {task_command.py:423} INFO - Running <TaskInstance: 3_4_2_homework_assignment.upload_to_clickhouse_task scheduled__2024-01-01T00:00:00+00:00 [running]> on host ea5964584459
[2025-02-27T09:49:48.100+0000] {taskinstance.py:2480} INFO - Exporting env vars: AIRFLOW_CTX_DAG_OWNER='airflow' AIRFLOW_CTX_DAG_ID='3_4_2_homework_assignment' AIRFLOW_CTX_TASK_ID='upload_to_clickhouse_task' AIRFLOW_CTX_EXECUTION_DATE='2024-01-01T00:00:00+00:00' AIRFLOW_CTX_TRY_NUMBER='1' AIRFLOW_CTX_DAG_RUN_ID='scheduled__2024-01-01T00:00:00+00:00'
[2025-02-27T09:49:48.102+0000] {taskinstance.py:2698} ERROR - Task failed with exception
Traceback (most recent call last):
  File "/home/airflow/.local/lib/python3.9/site-packages/airflow/models/taskinstance.py", line 433, in _execute_task
    result = execute_callable(context=context, **execute_callable_kwargs)
  File "/home/airflow/.local/lib/python3.9/site-packages/airflow/operators/python.py", line 199, in execute
    return_value = self.execute_callable()
  File "/home/airflow/.local/lib/python3.9/site-packages/airflow/operators/python.py", line 216, in execute_callable
    return self.python_callable(*self.op_args, **self.op_kwargs)
  File "/opt/airflow/dags/3_4_2_homework_assignment.py", line 92, in upload_to_clickhouse
    data_frame = pd.read_csv(csv_file)
  File "/home/airflow/.local/lib/python3.9/site-packages/pandas/io/parsers/readers.py", line 948, in read_csv
    return _read(filepath_or_buffer, kwds)
  File "/home/airflow/.local/lib/python3.9/site-packages/pandas/io/parsers/readers.py", line 611, in _read
    parser = TextFileReader(filepath_or_buffer, **kwds)
  File "/home/airflow/.local/lib/python3.9/site-packages/pandas/io/parsers/readers.py", line 1448, in __init__
    self._engine = self._make_engine(f, self.engine)
  File "/home/airflow/.local/lib/python3.9/site-packages/pandas/io/parsers/readers.py", line 1705, in _make_engine
    self.handles = get_handle(
  File "/home/airflow/.local/lib/python3.9/site-packages/pandas/io/common.py", line 863, in get_handle
    handle = open(
FileNotFoundError: [Errno 2] No such file or directory: 'extracted_data_csv.csv'
[2025-02-27T09:49:48.108+0000] {taskinstance.py:1138} INFO - Marking task as FAILED. dag_id=3_4_2_homework_assignment, task_id=upload_to_clickhouse_task, execution_date=20240101T000000, start_date=20250227T094947, end_date=20250227T094948
[2025-02-27T09:49:48.119+0000] {standard_task_runner.py:107} ERROR - Failed to execute job 4 for task upload_to_clickhouse_task ([Errno 2] No such file or directory: 'extracted_data_csv.csv'; 2097)
[2025-02-27T09:49:48.158+0000] {local_task_job_runner.py:234} INFO - Task exited with return code 1
[2025-02-27T09:49:48.167+0000] {taskinstance.py:3280} INFO - 0 downstream tasks scheduled from follow-on schedule check
[2025-02-27T09:53:49.945+0000] {taskinstance.py:1956} INFO - Dependencies all met for dep_context=non-requeueable deps ti=<TaskInstance: 3_4_2_homework_assignment.upload_to_clickhouse_task scheduled__2024-01-01T00:00:00+00:00 [queued]>
[2025-02-27T09:53:49.951+0000] {taskinstance.py:1956} INFO - Dependencies all met for dep_context=requeueable deps ti=<TaskInstance: 3_4_2_homework_assignment.upload_to_clickhouse_task scheduled__2024-01-01T00:00:00+00:00 [queued]>
[2025-02-27T09:53:49.951+0000] {taskinstance.py:2170} INFO - Starting attempt 1 of 1
[2025-02-27T09:53:49.961+0000] {taskinstance.py:2191} INFO - Executing <Task(PythonOperator): upload_to_clickhouse_task> on 2024-01-01 00:00:00+00:00
[2025-02-27T09:53:49.966+0000] {standard_task_runner.py:60} INFO - Started process 2675 to run task
[2025-02-27T09:53:49.968+0000] {standard_task_runner.py:87} INFO - Running: ['airflow', 'tasks', 'run', '3_4_2_homework_assignment', 'upload_to_clickhouse_task', 'scheduled__2024-01-01T00:00:00+00:00', '--job-id', '4', '--raw', '--subdir', 'DAGS_FOLDER/3_4_2_homework_assignment.py', '--cfg-path', '/tmp/tmpf3zsm440']
[2025-02-27T09:53:49.970+0000] {standard_task_runner.py:88} INFO - Job 4: Subtask upload_to_clickhouse_task
[2025-02-27T09:53:49.994+0000] {task_command.py:423} INFO - Running <TaskInstance: 3_4_2_homework_assignment.upload_to_clickhouse_task scheduled__2024-01-01T00:00:00+00:00 [running]> on host ea5964584459
[2025-02-27T09:53:50.034+0000] {taskinstance.py:2480} INFO - Exporting env vars: AIRFLOW_CTX_DAG_OWNER='airflow' AIRFLOW_CTX_DAG_ID='3_4_2_homework_assignment' AIRFLOW_CTX_TASK_ID='upload_to_clickhouse_task' AIRFLOW_CTX_EXECUTION_DATE='2024-01-01T00:00:00+00:00' AIRFLOW_CTX_TRY_NUMBER='1' AIRFLOW_CTX_DAG_RUN_ID='scheduled__2024-01-01T00:00:00+00:00'
[2025-02-27T09:53:50.036+0000] {taskinstance.py:2698} ERROR - Task failed with exception
Traceback (most recent call last):
  File "/home/airflow/.local/lib/python3.9/site-packages/airflow/models/taskinstance.py", line 433, in _execute_task
    result = execute_callable(context=context, **execute_callable_kwargs)
  File "/home/airflow/.local/lib/python3.9/site-packages/airflow/operators/python.py", line 199, in execute
    return_value = self.execute_callable()
  File "/home/airflow/.local/lib/python3.9/site-packages/airflow/operators/python.py", line 216, in execute_callable
    return self.python_callable(*self.op_args, **self.op_kwargs)
  File "/opt/airflow/dags/3_4_2_homework_assignment.py", line 93, in upload_to_clickhouse
    data_frame = pd.read_csv(csv_file)
  File "/home/airflow/.local/lib/python3.9/site-packages/pandas/io/parsers/readers.py", line 948, in read_csv
    return _read(filepath_or_buffer, kwds)
  File "/home/airflow/.local/lib/python3.9/site-packages/pandas/io/parsers/readers.py", line 611, in _read
    parser = TextFileReader(filepath_or_buffer, **kwds)
  File "/home/airflow/.local/lib/python3.9/site-packages/pandas/io/parsers/readers.py", line 1448, in __init__
    self._engine = self._make_engine(f, self.engine)
  File "/home/airflow/.local/lib/python3.9/site-packages/pandas/io/parsers/readers.py", line 1705, in _make_engine
    self.handles = get_handle(
  File "/home/airflow/.local/lib/python3.9/site-packages/pandas/io/common.py", line 863, in get_handle
    handle = open(
FileNotFoundError: [Errno 2] No such file or directory: 'extracted_data_csv.csv'
[2025-02-27T09:53:50.042+0000] {taskinstance.py:1138} INFO - Marking task as FAILED. dag_id=3_4_2_homework_assignment, task_id=upload_to_clickhouse_task, execution_date=20240101T000000, start_date=20250227T095349, end_date=20250227T095350
[2025-02-27T09:53:50.050+0000] {standard_task_runner.py:107} ERROR - Failed to execute job 4 for task upload_to_clickhouse_task ([Errno 2] No such file or directory: 'extracted_data_csv.csv'; 2675)
[2025-02-27T09:53:50.062+0000] {local_task_job_runner.py:234} INFO - Task exited with return code 1
[2025-02-27T09:53:50.071+0000] {taskinstance.py:3280} INFO - 0 downstream tasks scheduled from follow-on schedule check
[2025-02-27T10:05:43.440+0000] {taskinstance.py:1956} INFO - Dependencies all met for dep_context=non-requeueable deps ti=<TaskInstance: 3_4_2_homework_assignment.upload_to_clickhouse_task scheduled__2024-01-01T00:00:00+00:00 [queued]>
[2025-02-27T10:05:43.448+0000] {taskinstance.py:1956} INFO - Dependencies all met for dep_context=requeueable deps ti=<TaskInstance: 3_4_2_homework_assignment.upload_to_clickhouse_task scheduled__2024-01-01T00:00:00+00:00 [queued]>
[2025-02-27T10:05:43.449+0000] {taskinstance.py:2170} INFO - Starting attempt 1 of 1
[2025-02-27T10:05:43.481+0000] {taskinstance.py:2191} INFO - Executing <Task(PythonOperator): upload_to_clickhouse_task> on 2024-01-01 00:00:00+00:00
[2025-02-27T10:05:43.486+0000] {standard_task_runner.py:60} INFO - Started process 3319 to run task
[2025-02-27T10:05:43.488+0000] {standard_task_runner.py:87} INFO - Running: ['airflow', 'tasks', 'run', '3_4_2_homework_assignment', 'upload_to_clickhouse_task', 'scheduled__2024-01-01T00:00:00+00:00', '--job-id', '4', '--raw', '--subdir', 'DAGS_FOLDER/3_4_2_homework_assignment.py', '--cfg-path', '/tmp/tmprqj66vjy']
[2025-02-27T10:05:43.490+0000] {standard_task_runner.py:88} INFO - Job 4: Subtask upload_to_clickhouse_task
[2025-02-27T10:05:43.521+0000] {task_command.py:423} INFO - Running <TaskInstance: 3_4_2_homework_assignment.upload_to_clickhouse_task scheduled__2024-01-01T00:00:00+00:00 [running]> on host ea5964584459
[2025-02-27T10:05:43.569+0000] {taskinstance.py:2480} INFO - Exporting env vars: AIRFLOW_CTX_DAG_OWNER='airflow' AIRFLOW_CTX_DAG_ID='3_4_2_homework_assignment' AIRFLOW_CTX_TASK_ID='upload_to_clickhouse_task' AIRFLOW_CTX_EXECUTION_DATE='2024-01-01T00:00:00+00:00' AIRFLOW_CTX_TRY_NUMBER='1' AIRFLOW_CTX_DAG_RUN_ID='scheduled__2024-01-01T00:00:00+00:00'
[2025-02-27T10:05:43.572+0000] {taskinstance.py:2698} ERROR - Task failed with exception
Traceback (most recent call last):
  File "/home/airflow/.local/lib/python3.9/site-packages/airflow/models/taskinstance.py", line 433, in _execute_task
    result = execute_callable(context=context, **execute_callable_kwargs)
  File "/home/airflow/.local/lib/python3.9/site-packages/airflow/operators/python.py", line 199, in execute
    return_value = self.execute_callable()
  File "/home/airflow/.local/lib/python3.9/site-packages/airflow/operators/python.py", line 216, in execute_callable
    return self.python_callable(*self.op_args, **self.op_kwargs)
  File "/opt/airflow/dags/3_4_2_homework_assignment.py", line 87, in upload_to_clickhouse
    data_frame = pd.read_csv(csv_file)
  File "/home/airflow/.local/lib/python3.9/site-packages/pandas/io/parsers/readers.py", line 948, in read_csv
    return _read(filepath_or_buffer, kwds)
  File "/home/airflow/.local/lib/python3.9/site-packages/pandas/io/parsers/readers.py", line 611, in _read
    parser = TextFileReader(filepath_or_buffer, **kwds)
  File "/home/airflow/.local/lib/python3.9/site-packages/pandas/io/parsers/readers.py", line 1448, in __init__
    self._engine = self._make_engine(f, self.engine)
  File "/home/airflow/.local/lib/python3.9/site-packages/pandas/io/parsers/readers.py", line 1705, in _make_engine
    self.handles = get_handle(
  File "/home/airflow/.local/lib/python3.9/site-packages/pandas/io/common.py", line 863, in get_handle
    handle = open(
FileNotFoundError: [Errno 2] No such file or directory: 'extracted_data_csv.csv'
[2025-02-27T10:05:43.580+0000] {taskinstance.py:1138} INFO - Marking task as FAILED. dag_id=3_4_2_homework_assignment, task_id=upload_to_clickhouse_task, execution_date=20240101T000000, start_date=20250227T100543, end_date=20250227T100543
[2025-02-27T10:05:43.589+0000] {standard_task_runner.py:107} ERROR - Failed to execute job 4 for task upload_to_clickhouse_task ([Errno 2] No such file or directory: 'extracted_data_csv.csv'; 3319)
[2025-02-27T10:05:43.622+0000] {local_task_job_runner.py:234} INFO - Task exited with return code 1
[2025-02-27T10:05:43.632+0000] {taskinstance.py:3280} INFO - 0 downstream tasks scheduled from follow-on schedule check
[2025-02-27T10:11:28.373+0000] {taskinstance.py:1956} INFO - Dependencies all met for dep_context=non-requeueable deps ti=<TaskInstance: 3_4_2_homework_assignment.upload_to_clickhouse_task scheduled__2024-01-01T00:00:00+00:00 [queued]>
[2025-02-27T10:11:28.385+0000] {taskinstance.py:1956} INFO - Dependencies all met for dep_context=requeueable deps ti=<TaskInstance: 3_4_2_homework_assignment.upload_to_clickhouse_task scheduled__2024-01-01T00:00:00+00:00 [queued]>
[2025-02-27T10:11:28.386+0000] {taskinstance.py:2170} INFO - Starting attempt 1 of 1
[2025-02-27T10:11:28.398+0000] {taskinstance.py:2191} INFO - Executing <Task(PythonOperator): upload_to_clickhouse_task> on 2024-01-01 00:00:00+00:00
[2025-02-27T10:11:28.404+0000] {standard_task_runner.py:60} INFO - Started process 3926 to run task
[2025-02-27T10:11:28.406+0000] {standard_task_runner.py:87} INFO - Running: ['airflow', 'tasks', 'run', '3_4_2_homework_assignment', 'upload_to_clickhouse_task', 'scheduled__2024-01-01T00:00:00+00:00', '--job-id', '4', '--raw', '--subdir', 'DAGS_FOLDER/3_4_2_homework_assignment.py', '--cfg-path', '/tmp/tmp5tz7e6vo']
[2025-02-27T10:11:28.408+0000] {standard_task_runner.py:88} INFO - Job 4: Subtask upload_to_clickhouse_task
[2025-02-27T10:11:28.439+0000] {task_command.py:423} INFO - Running <TaskInstance: 3_4_2_homework_assignment.upload_to_clickhouse_task scheduled__2024-01-01T00:00:00+00:00 [running]> on host ea5964584459
[2025-02-27T10:11:28.489+0000] {taskinstance.py:2480} INFO - Exporting env vars: AIRFLOW_CTX_DAG_OWNER='airflow' AIRFLOW_CTX_DAG_ID='3_4_2_homework_assignment' AIRFLOW_CTX_TASK_ID='upload_to_clickhouse_task' AIRFLOW_CTX_EXECUTION_DATE='2024-01-01T00:00:00+00:00' AIRFLOW_CTX_TRY_NUMBER='1' AIRFLOW_CTX_DAG_RUN_ID='scheduled__2024-01-01T00:00:00+00:00'
[2025-02-27T10:11:28.492+0000] {taskinstance.py:2698} ERROR - Task failed with exception
Traceback (most recent call last):
  File "/home/airflow/.local/lib/python3.9/site-packages/airflow/models/taskinstance.py", line 433, in _execute_task
    result = execute_callable(context=context, **execute_callable_kwargs)
  File "/home/airflow/.local/lib/python3.9/site-packages/airflow/operators/python.py", line 199, in execute
    return_value = self.execute_callable()
  File "/home/airflow/.local/lib/python3.9/site-packages/airflow/operators/python.py", line 216, in execute_callable
    return self.python_callable(*self.op_args, **self.op_kwargs)
  File "/opt/airflow/dags/3_4_2_homework_assignment.py", line 88, in upload_to_clickhouse
    data_frame = pd.read_csv(csv_file)
  File "/home/airflow/.local/lib/python3.9/site-packages/pandas/io/parsers/readers.py", line 948, in read_csv
    return _read(filepath_or_buffer, kwds)
  File "/home/airflow/.local/lib/python3.9/site-packages/pandas/io/parsers/readers.py", line 611, in _read
    parser = TextFileReader(filepath_or_buffer, **kwds)
  File "/home/airflow/.local/lib/python3.9/site-packages/pandas/io/parsers/readers.py", line 1448, in __init__
    self._engine = self._make_engine(f, self.engine)
  File "/home/airflow/.local/lib/python3.9/site-packages/pandas/io/parsers/readers.py", line 1705, in _make_engine
    self.handles = get_handle(
  File "/home/airflow/.local/lib/python3.9/site-packages/pandas/io/common.py", line 863, in get_handle
    handle = open(
FileNotFoundError: [Errno 2] No such file or directory: 'extracted_data_csv.csv'
[2025-02-27T10:11:28.498+0000] {taskinstance.py:1138} INFO - Marking task as FAILED. dag_id=3_4_2_homework_assignment, task_id=upload_to_clickhouse_task, execution_date=20240101T000000, start_date=20250227T101128, end_date=20250227T101128
[2025-02-27T10:11:28.507+0000] {standard_task_runner.py:107} ERROR - Failed to execute job 4 for task upload_to_clickhouse_task ([Errno 2] No such file or directory: 'extracted_data_csv.csv'; 3926)
[2025-02-27T10:11:28.541+0000] {local_task_job_runner.py:234} INFO - Task exited with return code 1
[2025-02-27T10:11:28.550+0000] {taskinstance.py:3280} INFO - 0 downstream tasks scheduled from follow-on schedule check
[2025-02-27T10:13:30.243+0000] {taskinstance.py:1956} INFO - Dependencies all met for dep_context=non-requeueable deps ti=<TaskInstance: 3_4_2_homework_assignment.upload_to_clickhouse_task scheduled__2024-01-01T00:00:00+00:00 [queued]>
[2025-02-27T10:13:30.249+0000] {taskinstance.py:1956} INFO - Dependencies all met for dep_context=requeueable deps ti=<TaskInstance: 3_4_2_homework_assignment.upload_to_clickhouse_task scheduled__2024-01-01T00:00:00+00:00 [queued]>
[2025-02-27T10:13:30.249+0000] {taskinstance.py:2170} INFO - Starting attempt 1 of 1
[2025-02-27T10:13:30.260+0000] {taskinstance.py:2191} INFO - Executing <Task(PythonOperator): upload_to_clickhouse_task> on 2024-01-01 00:00:00+00:00
[2025-02-27T10:13:30.265+0000] {standard_task_runner.py:60} INFO - Started process 4214 to run task
[2025-02-27T10:13:30.267+0000] {standard_task_runner.py:87} INFO - Running: ['airflow', 'tasks', 'run', '3_4_2_homework_assignment', 'upload_to_clickhouse_task', 'scheduled__2024-01-01T00:00:00+00:00', '--job-id', '4', '--raw', '--subdir', 'DAGS_FOLDER/3_4_2_homework_assignment.py', '--cfg-path', '/tmp/tmp7h3t3gc8']
[2025-02-27T10:13:30.268+0000] {standard_task_runner.py:88} INFO - Job 4: Subtask upload_to_clickhouse_task
[2025-02-27T10:13:30.297+0000] {task_command.py:423} INFO - Running <TaskInstance: 3_4_2_homework_assignment.upload_to_clickhouse_task scheduled__2024-01-01T00:00:00+00:00 [running]> on host ea5964584459
[2025-02-27T10:13:30.340+0000] {taskinstance.py:2480} INFO - Exporting env vars: AIRFLOW_CTX_DAG_OWNER='airflow' AIRFLOW_CTX_DAG_ID='3_4_2_homework_assignment' AIRFLOW_CTX_TASK_ID='upload_to_clickhouse_task' AIRFLOW_CTX_EXECUTION_DATE='2024-01-01T00:00:00+00:00' AIRFLOW_CTX_TRY_NUMBER='1' AIRFLOW_CTX_DAG_RUN_ID='scheduled__2024-01-01T00:00:00+00:00'
[2025-02-27T10:13:30.349+0000] {connection.py:411} WARNING - Failed to connect to None:9000
Traceback (most recent call last):
  File "/home/airflow/.local/lib/python3.9/site-packages/clickhouse_driver/connection.py", line 399, in connect
    return self._init_connection(host, port)
  File "/home/airflow/.local/lib/python3.9/site-packages/clickhouse_driver/connection.py", line 329, in _init_connection
    self.socket = self._create_socket(host, port)
  File "/home/airflow/.local/lib/python3.9/site-packages/clickhouse_driver/connection.py", line 301, in _create_socket
    raise err
  File "/home/airflow/.local/lib/python3.9/site-packages/clickhouse_driver/connection.py", line 292, in _create_socket
    sock.connect(sa)
ConnectionRefusedError: [Errno 111] Connection refused
[2025-02-27T10:13:30.350+0000] {taskinstance.py:2698} ERROR - Task failed with exception
Traceback (most recent call last):
  File "/home/airflow/.local/lib/python3.9/site-packages/airflow/models/taskinstance.py", line 433, in _execute_task
    result = execute_callable(context=context, **execute_callable_kwargs)
  File "/home/airflow/.local/lib/python3.9/site-packages/airflow/operators/python.py", line 199, in execute
    return_value = self.execute_callable()
  File "/home/airflow/.local/lib/python3.9/site-packages/airflow/operators/python.py", line 216, in execute_callable
    return self.python_callable(*self.op_args, **self.op_kwargs)
  File "/opt/airflow/dags/3_4_2_homework_assignment.py", line 90, in upload_to_clickhouse
    client.execute(f'CREATE TABLE IF NOT EXISTS {table_name} (source String, currency String, value Float, date String) ENGINE Log')
  File "/home/airflow/.local/lib/python3.9/site-packages/clickhouse_driver/client.py", line 370, in execute
    with self.disconnect_on_error(query, settings):
  File "/usr/local/lib/python3.9/contextlib.py", line 119, in __enter__
    return next(self.gen)
  File "/home/airflow/.local/lib/python3.9/site-packages/clickhouse_driver/client.py", line 313, in disconnect_on_error
    self.establish_connection(settings)
  File "/home/airflow/.local/lib/python3.9/site-packages/clickhouse_driver/client.py", line 300, in establish_connection
    self.connection.force_connect()
  File "/home/airflow/.local/lib/python3.9/site-packages/clickhouse_driver/connection.py", line 258, in force_connect
    self.connect()
  File "/home/airflow/.local/lib/python3.9/site-packages/clickhouse_driver/connection.py", line 420, in connect
    raise err
clickhouse_driver.errors.NetworkError: Code: 210. Connection refused (None:9000)
[2025-02-27T10:13:30.356+0000] {taskinstance.py:1138} INFO - Marking task as FAILED. dag_id=3_4_2_homework_assignment, task_id=upload_to_clickhouse_task, execution_date=20240101T000000, start_date=20250227T101330, end_date=20250227T101330
[2025-02-27T10:13:30.365+0000] {standard_task_runner.py:107} ERROR - Failed to execute job 4 for task upload_to_clickhouse_task (Code: 210. Connection refused (None:9000); 4214)
[2025-02-27T10:13:30.402+0000] {local_task_job_runner.py:234} INFO - Task exited with return code 1
[2025-02-27T10:13:30.412+0000] {taskinstance.py:3280} INFO - 0 downstream tasks scheduled from follow-on schedule check
[2025-02-27T10:18:43.735+0000] {taskinstance.py:1956} INFO - Dependencies all met for dep_context=non-requeueable deps ti=<TaskInstance: 3_4_2_homework_assignment.upload_to_clickhouse_task scheduled__2024-01-01T00:00:00+00:00 [queued]>
[2025-02-27T10:18:43.740+0000] {taskinstance.py:1956} INFO - Dependencies all met for dep_context=requeueable deps ti=<TaskInstance: 3_4_2_homework_assignment.upload_to_clickhouse_task scheduled__2024-01-01T00:00:00+00:00 [queued]>
[2025-02-27T10:18:43.741+0000] {taskinstance.py:2170} INFO - Starting attempt 1 of 1
[2025-02-27T10:18:43.752+0000] {taskinstance.py:2191} INFO - Executing <Task(PythonOperator): upload_to_clickhouse_task> on 2024-01-01 00:00:00+00:00
[2025-02-27T10:18:43.757+0000] {standard_task_runner.py:60} INFO - Started process 4807 to run task
[2025-02-27T10:18:43.759+0000] {standard_task_runner.py:87} INFO - Running: ['airflow', 'tasks', 'run', '3_4_2_homework_assignment', 'upload_to_clickhouse_task', 'scheduled__2024-01-01T00:00:00+00:00', '--job-id', '4', '--raw', '--subdir', 'DAGS_FOLDER/3_4_2_homework_assignment.py', '--cfg-path', '/tmp/tmp_jb981h3']
[2025-02-27T10:18:43.761+0000] {standard_task_runner.py:88} INFO - Job 4: Subtask upload_to_clickhouse_task
[2025-02-27T10:18:43.789+0000] {task_command.py:423} INFO - Running <TaskInstance: 3_4_2_homework_assignment.upload_to_clickhouse_task scheduled__2024-01-01T00:00:00+00:00 [running]> on host ea5964584459
[2025-02-27T10:18:43.832+0000] {taskinstance.py:2480} INFO - Exporting env vars: AIRFLOW_CTX_DAG_OWNER='airflow' AIRFLOW_CTX_DAG_ID='3_4_2_homework_assignment' AIRFLOW_CTX_TASK_ID='upload_to_clickhouse_task' AIRFLOW_CTX_EXECUTION_DATE='2024-01-01T00:00:00+00:00' AIRFLOW_CTX_TRY_NUMBER='1' AIRFLOW_CTX_DAG_RUN_ID='scheduled__2024-01-01T00:00:00+00:00'
[2025-02-27T10:18:43.841+0000] {connection.py:411} WARNING - Failed to connect to None:9000
Traceback (most recent call last):
  File "/home/airflow/.local/lib/python3.9/site-packages/clickhouse_driver/connection.py", line 399, in connect
    return self._init_connection(host, port)
  File "/home/airflow/.local/lib/python3.9/site-packages/clickhouse_driver/connection.py", line 329, in _init_connection
    self.socket = self._create_socket(host, port)
  File "/home/airflow/.local/lib/python3.9/site-packages/clickhouse_driver/connection.py", line 301, in _create_socket
    raise err
  File "/home/airflow/.local/lib/python3.9/site-packages/clickhouse_driver/connection.py", line 292, in _create_socket
    sock.connect(sa)
ConnectionRefusedError: [Errno 111] Connection refused
[2025-02-27T10:18:43.842+0000] {taskinstance.py:2698} ERROR - Task failed with exception
Traceback (most recent call last):
  File "/home/airflow/.local/lib/python3.9/site-packages/airflow/models/taskinstance.py", line 433, in _execute_task
    result = execute_callable(context=context, **execute_callable_kwargs)
  File "/home/airflow/.local/lib/python3.9/site-packages/airflow/operators/python.py", line 199, in execute
    return_value = self.execute_callable()
  File "/home/airflow/.local/lib/python3.9/site-packages/airflow/operators/python.py", line 216, in execute_callable
    return self.python_callable(*self.op_args, **self.op_kwargs)
  File "/opt/airflow/dags/3_4_2_homework_assignment.py", line 90, in upload_to_clickhouse
    client.execute(f'CREATE TABLE IF NOT EXISTS {table_name} (source String, currency String, value Float, date String) ENGINE Log')
  File "/home/airflow/.local/lib/python3.9/site-packages/clickhouse_driver/client.py", line 370, in execute
    with self.disconnect_on_error(query, settings):
  File "/usr/local/lib/python3.9/contextlib.py", line 119, in __enter__
    return next(self.gen)
  File "/home/airflow/.local/lib/python3.9/site-packages/clickhouse_driver/client.py", line 313, in disconnect_on_error
    self.establish_connection(settings)
  File "/home/airflow/.local/lib/python3.9/site-packages/clickhouse_driver/client.py", line 300, in establish_connection
    self.connection.force_connect()
  File "/home/airflow/.local/lib/python3.9/site-packages/clickhouse_driver/connection.py", line 258, in force_connect
    self.connect()
  File "/home/airflow/.local/lib/python3.9/site-packages/clickhouse_driver/connection.py", line 420, in connect
    raise err
clickhouse_driver.errors.NetworkError: Code: 210. Connection refused (None:9000)
[2025-02-27T10:18:43.848+0000] {taskinstance.py:1138} INFO - Marking task as FAILED. dag_id=3_4_2_homework_assignment, task_id=upload_to_clickhouse_task, execution_date=20240101T000000, start_date=20250227T101843, end_date=20250227T101843
[2025-02-27T10:18:43.857+0000] {standard_task_runner.py:107} ERROR - Failed to execute job 4 for task upload_to_clickhouse_task (Code: 210. Connection refused (None:9000); 4807)
[2025-02-27T10:18:43.893+0000] {local_task_job_runner.py:234} INFO - Task exited with return code 1
[2025-02-27T10:18:43.902+0000] {taskinstance.py:3280} INFO - 0 downstream tasks scheduled from follow-on schedule check
[2025-02-27T10:23:21.953+0000] {taskinstance.py:1956} INFO - Dependencies all met for dep_context=non-requeueable deps ti=<TaskInstance: 3_4_2_homework_assignment.upload_to_clickhouse_task scheduled__2024-01-01T00:00:00+00:00 [queued]>
[2025-02-27T10:23:21.960+0000] {taskinstance.py:1956} INFO - Dependencies all met for dep_context=requeueable deps ti=<TaskInstance: 3_4_2_homework_assignment.upload_to_clickhouse_task scheduled__2024-01-01T00:00:00+00:00 [queued]>
[2025-02-27T10:23:21.960+0000] {taskinstance.py:2170} INFO - Starting attempt 1 of 1
[2025-02-27T10:23:21.980+0000] {taskinstance.py:2191} INFO - Executing <Task(PythonOperator): upload_to_clickhouse_task> on 2024-01-01 00:00:00+00:00
[2025-02-27T10:23:21.987+0000] {standard_task_runner.py:60} INFO - Started process 5256 to run task
[2025-02-27T10:23:21.989+0000] {standard_task_runner.py:87} INFO - Running: ['airflow', 'tasks', 'run', '3_4_2_homework_assignment', 'upload_to_clickhouse_task', 'scheduled__2024-01-01T00:00:00+00:00', '--job-id', '4', '--raw', '--subdir', 'DAGS_FOLDER/3_4_2_homework_assignment.py', '--cfg-path', '/tmp/tmp711hwm1_']
[2025-02-27T10:23:21.991+0000] {standard_task_runner.py:88} INFO - Job 4: Subtask upload_to_clickhouse_task
[2025-02-27T10:23:22.033+0000] {task_command.py:423} INFO - Running <TaskInstance: 3_4_2_homework_assignment.upload_to_clickhouse_task scheduled__2024-01-01T00:00:00+00:00 [running]> on host ea5964584459
[2025-02-27T10:23:22.092+0000] {taskinstance.py:2480} INFO - Exporting env vars: AIRFLOW_CTX_DAG_OWNER='airflow' AIRFLOW_CTX_DAG_ID='3_4_2_homework_assignment' AIRFLOW_CTX_TASK_ID='upload_to_clickhouse_task' AIRFLOW_CTX_EXECUTION_DATE='2024-01-01T00:00:00+00:00' AIRFLOW_CTX_TRY_NUMBER='1' AIRFLOW_CTX_DAG_RUN_ID='scheduled__2024-01-01T00:00:00+00:00'
[2025-02-27T10:23:22.102+0000] {connection.py:411} WARNING - Failed to connect to None:9000
Traceback (most recent call last):
  File "/home/airflow/.local/lib/python3.9/site-packages/clickhouse_driver/connection.py", line 399, in connect
    return self._init_connection(host, port)
  File "/home/airflow/.local/lib/python3.9/site-packages/clickhouse_driver/connection.py", line 329, in _init_connection
    self.socket = self._create_socket(host, port)
  File "/home/airflow/.local/lib/python3.9/site-packages/clickhouse_driver/connection.py", line 301, in _create_socket
    raise err
  File "/home/airflow/.local/lib/python3.9/site-packages/clickhouse_driver/connection.py", line 292, in _create_socket
    sock.connect(sa)
ConnectionRefusedError: [Errno 111] Connection refused
[2025-02-27T10:23:22.104+0000] {taskinstance.py:2698} ERROR - Task failed with exception
Traceback (most recent call last):
  File "/home/airflow/.local/lib/python3.9/site-packages/airflow/models/taskinstance.py", line 433, in _execute_task
    result = execute_callable(context=context, **execute_callable_kwargs)
  File "/home/airflow/.local/lib/python3.9/site-packages/airflow/operators/python.py", line 199, in execute
    return_value = self.execute_callable()
  File "/home/airflow/.local/lib/python3.9/site-packages/airflow/operators/python.py", line 216, in execute_callable
    return self.python_callable(*self.op_args, **self.op_kwargs)
  File "/opt/airflow/dags/3_4_2_homework_assignment.py", line 90, in upload_to_clickhouse
    client.execute(f'CREATE TABLE IF NOT EXISTS {table_name} (source String, currency String, value Float, date String) ENGINE Log')
  File "/home/airflow/.local/lib/python3.9/site-packages/clickhouse_driver/client.py", line 370, in execute
    with self.disconnect_on_error(query, settings):
  File "/usr/local/lib/python3.9/contextlib.py", line 119, in __enter__
    return next(self.gen)
  File "/home/airflow/.local/lib/python3.9/site-packages/clickhouse_driver/client.py", line 313, in disconnect_on_error
    self.establish_connection(settings)
  File "/home/airflow/.local/lib/python3.9/site-packages/clickhouse_driver/client.py", line 300, in establish_connection
    self.connection.force_connect()
  File "/home/airflow/.local/lib/python3.9/site-packages/clickhouse_driver/connection.py", line 258, in force_connect
    self.connect()
  File "/home/airflow/.local/lib/python3.9/site-packages/clickhouse_driver/connection.py", line 420, in connect
    raise err
clickhouse_driver.errors.NetworkError: Code: 210. Connection refused (None:9000)
[2025-02-27T10:23:22.111+0000] {taskinstance.py:1138} INFO - Marking task as FAILED. dag_id=3_4_2_homework_assignment, task_id=upload_to_clickhouse_task, execution_date=20240101T000000, start_date=20250227T102321, end_date=20250227T102322
[2025-02-27T10:23:22.124+0000] {standard_task_runner.py:107} ERROR - Failed to execute job 4 for task upload_to_clickhouse_task (Code: 210. Connection refused (None:9000); 5256)
[2025-02-27T10:23:22.165+0000] {local_task_job_runner.py:234} INFO - Task exited with return code 1
[2025-02-27T10:23:22.175+0000] {taskinstance.py:3280} INFO - 0 downstream tasks scheduled from follow-on schedule check
[2025-02-27T10:25:56.333+0000] {taskinstance.py:1956} INFO - Dependencies all met for dep_context=non-requeueable deps ti=<TaskInstance: 3_4_2_homework_assignment.upload_to_clickhouse_task scheduled__2024-01-01T00:00:00+00:00 [queued]>
[2025-02-27T10:25:56.340+0000] {taskinstance.py:1956} INFO - Dependencies all met for dep_context=requeueable deps ti=<TaskInstance: 3_4_2_homework_assignment.upload_to_clickhouse_task scheduled__2024-01-01T00:00:00+00:00 [queued]>
[2025-02-27T10:25:56.340+0000] {taskinstance.py:2170} INFO - Starting attempt 1 of 1
[2025-02-27T10:25:56.360+0000] {taskinstance.py:2191} INFO - Executing <Task(PythonOperator): upload_to_clickhouse_task> on 2024-01-01 00:00:00+00:00
[2025-02-27T10:25:56.367+0000] {standard_task_runner.py:60} INFO - Started process 5547 to run task
[2025-02-27T10:25:56.369+0000] {standard_task_runner.py:87} INFO - Running: ['airflow', 'tasks', 'run', '3_4_2_homework_assignment', 'upload_to_clickhouse_task', 'scheduled__2024-01-01T00:00:00+00:00', '--job-id', '4', '--raw', '--subdir', 'DAGS_FOLDER/3_4_2_homework_assignment.py', '--cfg-path', '/tmp/tmp9o66vqp7']
[2025-02-27T10:25:56.370+0000] {standard_task_runner.py:88} INFO - Job 4: Subtask upload_to_clickhouse_task
[2025-02-27T10:25:56.405+0000] {task_command.py:423} INFO - Running <TaskInstance: 3_4_2_homework_assignment.upload_to_clickhouse_task scheduled__2024-01-01T00:00:00+00:00 [running]> on host ea5964584459
[2025-02-27T10:25:56.451+0000] {taskinstance.py:2480} INFO - Exporting env vars: AIRFLOW_CTX_DAG_OWNER='airflow' AIRFLOW_CTX_DAG_ID='3_4_2_homework_assignment' AIRFLOW_CTX_TASK_ID='upload_to_clickhouse_task' AIRFLOW_CTX_EXECUTION_DATE='2024-01-01T00:00:00+00:00' AIRFLOW_CTX_TRY_NUMBER='1' AIRFLOW_CTX_DAG_RUN_ID='scheduled__2024-01-01T00:00:00+00:00'
[2025-02-27T10:25:56.573+0000] {taskinstance.py:2698} ERROR - Task failed with exception
Traceback (most recent call last):
  File "/home/airflow/.local/lib/python3.9/site-packages/airflow/models/taskinstance.py", line 433, in _execute_task
    result = execute_callable(context=context, **execute_callable_kwargs)
  File "/home/airflow/.local/lib/python3.9/site-packages/airflow/operators/python.py", line 199, in execute
    return_value = self.execute_callable()
  File "/home/airflow/.local/lib/python3.9/site-packages/airflow/operators/python.py", line 216, in execute_callable
    return self.python_callable(*self.op_args, **self.op_kwargs)
  File "/opt/airflow/dags/3_4_2_homework_assignment.py", line 92, in upload_to_clickhouse
    client.execute(f'INSERT INTO {table_name} VALUES', data_frame.to_dict('records'))
  File "/home/airflow/.local/lib/python3.9/site-packages/clickhouse_driver/client.py", line 376, in execute
    rv = self.process_insert_query(
  File "/home/airflow/.local/lib/python3.9/site-packages/clickhouse_driver/client.py", line 607, in process_insert_query
    rv = self.send_data(sample_block, data,
  File "/home/airflow/.local/lib/python3.9/site-packages/clickhouse_driver/client.py", line 658, in send_data
    block = block_cls(sample_block.columns_with_types, chunk,
  File "/home/airflow/.local/lib/python3.9/site-packages/clickhouse_driver/block.py", line 40, in __init__
    self.data = self.normalize(data or [])
  File "/home/airflow/.local/lib/python3.9/site-packages/clickhouse_driver/block.py", line 128, in normalize
    self._mutate_dicts_to_rows(data)
  File "/home/airflow/.local/lib/python3.9/site-packages/clickhouse_driver/block.py", line 159, in _mutate_dicts_to_rows
    return self._pure_mutate_dicts_to_rows(
  File "/home/airflow/.local/lib/python3.9/site-packages/clickhouse_driver/block.py", line 186, in _pure_mutate_dicts_to_rows
    new_data.append(row[name])
KeyError: 'source'
[2025-02-27T10:25:56.586+0000] {taskinstance.py:1138} INFO - Marking task as FAILED. dag_id=3_4_2_homework_assignment, task_id=upload_to_clickhouse_task, execution_date=20240101T000000, start_date=20250227T102556, end_date=20250227T102556
[2025-02-27T10:25:56.600+0000] {standard_task_runner.py:107} ERROR - Failed to execute job 4 for task upload_to_clickhouse_task ('source'; 5547)
[2025-02-27T10:25:56.624+0000] {local_task_job_runner.py:234} INFO - Task exited with return code 1
[2025-02-27T10:25:56.635+0000] {taskinstance.py:3280} INFO - 0 downstream tasks scheduled from follow-on schedule check
[2025-02-27T10:34:11.627+0000] {taskinstance.py:1956} INFO - Dependencies all met for dep_context=non-requeueable deps ti=<TaskInstance: 3_4_2_homework_assignment.upload_to_clickhouse_task scheduled__2024-01-01T00:00:00+00:00 [queued]>
[2025-02-27T10:34:11.633+0000] {taskinstance.py:1956} INFO - Dependencies all met for dep_context=requeueable deps ti=<TaskInstance: 3_4_2_homework_assignment.upload_to_clickhouse_task scheduled__2024-01-01T00:00:00+00:00 [queued]>
[2025-02-27T10:34:11.634+0000] {taskinstance.py:2170} INFO - Starting attempt 1 of 1
[2025-02-27T10:34:11.648+0000] {taskinstance.py:2191} INFO - Executing <Task(PythonOperator): upload_to_clickhouse_task> on 2024-01-01 00:00:00+00:00
[2025-02-27T10:34:11.653+0000] {standard_task_runner.py:60} INFO - Started process 6205 to run task
[2025-02-27T10:34:11.655+0000] {standard_task_runner.py:87} INFO - Running: ['airflow', 'tasks', 'run', '3_4_2_homework_assignment', 'upload_to_clickhouse_task', 'scheduled__2024-01-01T00:00:00+00:00', '--job-id', '4', '--raw', '--subdir', 'DAGS_FOLDER/3_4_2_homework_assignment.py', '--cfg-path', '/tmp/tmp1hs_jz5v']
[2025-02-27T10:34:11.656+0000] {standard_task_runner.py:88} INFO - Job 4: Subtask upload_to_clickhouse_task
[2025-02-27T10:34:11.686+0000] {task_command.py:423} INFO - Running <TaskInstance: 3_4_2_homework_assignment.upload_to_clickhouse_task scheduled__2024-01-01T00:00:00+00:00 [running]> on host ea5964584459
[2025-02-27T10:34:11.734+0000] {taskinstance.py:2480} INFO - Exporting env vars: AIRFLOW_CTX_DAG_OWNER='airflow' AIRFLOW_CTX_DAG_ID='3_4_2_homework_assignment' AIRFLOW_CTX_TASK_ID='upload_to_clickhouse_task' AIRFLOW_CTX_EXECUTION_DATE='2024-01-01T00:00:00+00:00' AIRFLOW_CTX_TRY_NUMBER='1' AIRFLOW_CTX_DAG_RUN_ID='scheduled__2024-01-01T00:00:00+00:00'
[2025-02-27T10:34:11.828+0000] {taskinstance.py:2698} ERROR - Task failed with exception
Traceback (most recent call last):
  File "/home/airflow/.local/lib/python3.9/site-packages/airflow/models/taskinstance.py", line 433, in _execute_task
    result = execute_callable(context=context, **execute_callable_kwargs)
  File "/home/airflow/.local/lib/python3.9/site-packages/airflow/operators/python.py", line 199, in execute
    return_value = self.execute_callable()
  File "/home/airflow/.local/lib/python3.9/site-packages/airflow/operators/python.py", line 216, in execute_callable
    return self.python_callable(*self.op_args, **self.op_kwargs)
  File "/opt/airflow/dags/3_4_2_homework_assignment.py", line 93, in upload_to_clickhouse
    client.execute(f'INSERT INTO {table_name} VALUES', data_frame.to_dict('records'))
  File "/home/airflow/.local/lib/python3.9/site-packages/clickhouse_driver/client.py", line 376, in execute
    rv = self.process_insert_query(
  File "/home/airflow/.local/lib/python3.9/site-packages/clickhouse_driver/client.py", line 607, in process_insert_query
    rv = self.send_data(sample_block, data,
  File "/home/airflow/.local/lib/python3.9/site-packages/clickhouse_driver/client.py", line 658, in send_data
    block = block_cls(sample_block.columns_with_types, chunk,
  File "/home/airflow/.local/lib/python3.9/site-packages/clickhouse_driver/block.py", line 40, in __init__
    self.data = self.normalize(data or [])
  File "/home/airflow/.local/lib/python3.9/site-packages/clickhouse_driver/block.py", line 128, in normalize
    self._mutate_dicts_to_rows(data)
  File "/home/airflow/.local/lib/python3.9/site-packages/clickhouse_driver/block.py", line 159, in _mutate_dicts_to_rows
    return self._pure_mutate_dicts_to_rows(
  File "/home/airflow/.local/lib/python3.9/site-packages/clickhouse_driver/block.py", line 186, in _pure_mutate_dicts_to_rows
    new_data.append(row[name])
KeyError: 'source'
[2025-02-27T10:34:11.838+0000] {taskinstance.py:1138} INFO - Marking task as FAILED. dag_id=3_4_2_homework_assignment, task_id=upload_to_clickhouse_task, execution_date=20240101T000000, start_date=20250227T103411, end_date=20250227T103411
[2025-02-27T10:34:11.849+0000] {standard_task_runner.py:107} ERROR - Failed to execute job 4 for task upload_to_clickhouse_task ('source'; 6205)
[2025-02-27T10:34:11.871+0000] {local_task_job_runner.py:234} INFO - Task exited with return code 1
[2025-02-27T10:34:11.881+0000] {taskinstance.py:3280} INFO - 0 downstream tasks scheduled from follow-on schedule check
[2025-02-27T10:44:28.145+0000] {taskinstance.py:1956} INFO - Dependencies all met for dep_context=non-requeueable deps ti=<TaskInstance: 3_4_2_homework_assignment.upload_to_clickhouse_task scheduled__2024-01-01T00:00:00+00:00 [queued]>
[2025-02-27T10:44:28.151+0000] {taskinstance.py:1956} INFO - Dependencies all met for dep_context=requeueable deps ti=<TaskInstance: 3_4_2_homework_assignment.upload_to_clickhouse_task scheduled__2024-01-01T00:00:00+00:00 [queued]>
[2025-02-27T10:44:28.151+0000] {taskinstance.py:2170} INFO - Starting attempt 1 of 1
[2025-02-27T10:44:28.168+0000] {taskinstance.py:2191} INFO - Executing <Task(PythonOperator): upload_to_clickhouse_task> on 2024-01-01 00:00:00+00:00
[2025-02-27T10:44:28.174+0000] {standard_task_runner.py:60} INFO - Started process 6894 to run task
[2025-02-27T10:44:28.177+0000] {standard_task_runner.py:87} INFO - Running: ['airflow', 'tasks', 'run', '3_4_2_homework_assignment', 'upload_to_clickhouse_task', 'scheduled__2024-01-01T00:00:00+00:00', '--job-id', '4', '--raw', '--subdir', 'DAGS_FOLDER/3_4_2_homework_assignment.py', '--cfg-path', '/tmp/tmp8l2e0qf_']
[2025-02-27T10:44:28.178+0000] {standard_task_runner.py:88} INFO - Job 4: Subtask upload_to_clickhouse_task
[2025-02-27T10:44:28.211+0000] {task_command.py:423} INFO - Running <TaskInstance: 3_4_2_homework_assignment.upload_to_clickhouse_task scheduled__2024-01-01T00:00:00+00:00 [running]> on host ea5964584459
[2025-02-27T10:44:28.265+0000] {taskinstance.py:2480} INFO - Exporting env vars: AIRFLOW_CTX_DAG_OWNER='airflow' AIRFLOW_CTX_DAG_ID='3_4_2_homework_assignment' AIRFLOW_CTX_TASK_ID='upload_to_clickhouse_task' AIRFLOW_CTX_EXECUTION_DATE='2024-01-01T00:00:00+00:00' AIRFLOW_CTX_TRY_NUMBER='1' AIRFLOW_CTX_DAG_RUN_ID='scheduled__2024-01-01T00:00:00+00:00'
[2025-02-27T10:44:28.358+0000] {unix.py:142} WARNING - /etc/timezone is deprecated on Debian, and no longer reliable. Ignoring.
[2025-02-27T10:44:28.367+0000] {python.py:201} INFO - Done. Returned value was: None
[2025-02-27T10:44:28.372+0000] {taskinstance.py:1138} INFO - Marking task as SUCCESS. dag_id=3_4_2_homework_assignment, task_id=upload_to_clickhouse_task, execution_date=20240101T000000, start_date=20250227T104428, end_date=20250227T104428
[2025-02-27T10:44:28.430+0000] {local_task_job_runner.py:234} INFO - Task exited with return code 0
[2025-02-27T10:44:28.440+0000] {taskinstance.py:3280} INFO - 0 downstream tasks scheduled from follow-on schedule check
