[2025-03-11T13:58:09.272+0000] {taskinstance.py:1956} INFO - Dependencies all met for dep_context=non-requeueable deps ti=<TaskInstance: 5_2_sencor.start_report_task manual__2025-03-11T13:58:05.040944+00:00 [queued]>
[2025-03-11T13:58:09.277+0000] {taskinstance.py:1956} INFO - Dependencies all met for dep_context=requeueable deps ti=<TaskInstance: 5_2_sencor.start_report_task manual__2025-03-11T13:58:05.040944+00:00 [queued]>
[2025-03-11T13:58:09.278+0000] {taskinstance.py:2170} INFO - Starting attempt 1 of 1
[2025-03-11T13:58:09.288+0000] {taskinstance.py:2191} INFO - Executing <Task(SimpleHttpOperator): start_report_task> on 2025-03-11 13:58:05.040944+00:00
[2025-03-11T13:58:09.292+0000] {standard_task_runner.py:60} INFO - Started process 7387 to run task
[2025-03-11T13:58:09.295+0000] {standard_task_runner.py:87} INFO - Running: ['airflow', 'tasks', 'run', '5_2_sencor', 'start_report_task', 'manual__2025-03-11T13:58:05.040944+00:00', '--job-id', '58', '--raw', '--subdir', 'DAGS_FOLDER/5_2_sencor.py', '--cfg-path', '/tmp/tmpc43nw5at']
[2025-03-11T13:58:09.296+0000] {standard_task_runner.py:88} INFO - Job 58: Subtask start_report_task
[2025-03-11T13:58:09.323+0000] {task_command.py:423} INFO - Running <TaskInstance: 5_2_sencor.start_report_task manual__2025-03-11T13:58:05.040944+00:00 [running]> on host 9a2e4036dec3
[2025-03-11T13:58:09.477+0000] {taskinstance.py:2480} INFO - Exporting env vars: AIRFLOW_CTX_DAG_OWNER='airflow' AIRFLOW_CTX_DAG_ID='5_2_sencor' AIRFLOW_CTX_TASK_ID='start_report_task' AIRFLOW_CTX_EXECUTION_DATE='2025-03-11T13:58:05.040944+00:00' AIRFLOW_CTX_TRY_NUMBER='1' AIRFLOW_CTX_DAG_RUN_ID='manual__2025-03-11T13:58:05.040944+00:00'
[2025-03-11T13:58:09.477+0000] {http.py:169} INFO - Calling HTTP method
[2025-03-11T13:58:09.480+0000] {base.py:83} INFO - Using connection ID 'report_api' for task execution.
[2025-03-11T13:58:09.595+0000] {base.py:83} INFO - Using connection ID 'report_api' for task execution.
[2025-03-11T13:58:13.024+0000] {http.py:221} WARNING - HTTPConnectionPool(host='start_report', port=80): Max retries exceeded with url: / (Caused by NewConnectionError('<urllib3.connection.HTTPConnection object at 0x7ff609808a60>: Failed to establish a new connection: [Errno -2] Name or service not known')) Tenacity will retry to execute the operation
[2025-03-11T13:58:13.024+0000] {taskinstance.py:2698} ERROR - Task failed with exception
Traceback (most recent call last):
  File "/home/airflow/.local/lib/python3.9/site-packages/urllib3/connection.py", line 174, in _new_conn
    conn = connection.create_connection(
  File "/home/airflow/.local/lib/python3.9/site-packages/urllib3/util/connection.py", line 72, in create_connection
    for res in socket.getaddrinfo(host, port, family, socket.SOCK_STREAM):
  File "/usr/local/lib/python3.9/socket.py", line 954, in getaddrinfo
    for res in _socket.getaddrinfo(host, port, family, type, proto, flags):
socket.gaierror: [Errno -2] Name or service not known

During handling of the above exception, another exception occurred:

Traceback (most recent call last):
  File "/home/airflow/.local/lib/python3.9/site-packages/urllib3/connectionpool.py", line 715, in urlopen
    httplib_response = self._make_request(
  File "/home/airflow/.local/lib/python3.9/site-packages/urllib3/connectionpool.py", line 416, in _make_request
    conn.request(method, url, **httplib_request_kw)
  File "/home/airflow/.local/lib/python3.9/site-packages/urllib3/connection.py", line 244, in request
    super(HTTPConnection, self).request(method, url, body=body, headers=headers)
  File "/usr/local/lib/python3.9/http/client.py", line 1285, in request
    self._send_request(method, url, body, headers, encode_chunked)
  File "/usr/local/lib/python3.9/http/client.py", line 1331, in _send_request
    self.endheaders(body, encode_chunked=encode_chunked)
  File "/usr/local/lib/python3.9/http/client.py", line 1280, in endheaders
    self._send_output(message_body, encode_chunked=encode_chunked)
  File "/usr/local/lib/python3.9/http/client.py", line 1040, in _send_output
    self.send(msg)
  File "/usr/local/lib/python3.9/http/client.py", line 980, in send
    self.connect()
  File "/home/airflow/.local/lib/python3.9/site-packages/urllib3/connection.py", line 205, in connect
    conn = self._new_conn()
  File "/home/airflow/.local/lib/python3.9/site-packages/urllib3/connection.py", line 186, in _new_conn
    raise NewConnectionError(
urllib3.exceptions.NewConnectionError: <urllib3.connection.HTTPConnection object at 0x7ff609808a60>: Failed to establish a new connection: [Errno -2] Name or service not known

During handling of the above exception, another exception occurred:

Traceback (most recent call last):
  File "/home/airflow/.local/lib/python3.9/site-packages/requests/adapters.py", line 486, in send
    resp = conn.urlopen(
  File "/home/airflow/.local/lib/python3.9/site-packages/urllib3/connectionpool.py", line 799, in urlopen
    retries = retries.increment(
  File "/home/airflow/.local/lib/python3.9/site-packages/urllib3/util/retry.py", line 592, in increment
    raise MaxRetryError(_pool, url, error or ResponseError(cause))
urllib3.exceptions.MaxRetryError: HTTPConnectionPool(host='start_report', port=80): Max retries exceeded with url: / (Caused by NewConnectionError('<urllib3.connection.HTTPConnection object at 0x7ff609808a60>: Failed to establish a new connection: [Errno -2] Name or service not known'))

During handling of the above exception, another exception occurred:

Traceback (most recent call last):
  File "/home/airflow/.local/lib/python3.9/site-packages/airflow/models/taskinstance.py", line 433, in _execute_task
    result = execute_callable(context=context, **execute_callable_kwargs)
  File "/home/airflow/.local/lib/python3.9/site-packages/airflow/providers/http/operators/http.py", line 166, in execute
    return self.execute_sync(context=context)
  File "/home/airflow/.local/lib/python3.9/site-packages/airflow/providers/http/operators/http.py", line 170, in execute_sync
    response = self.hook.run(self.endpoint, self.data, self.headers, self.extra_options)
  File "/home/airflow/.local/lib/python3.9/site-packages/airflow/providers/http/hooks/http.py", line 166, in run
    return self.run_and_check(session, prepped_request, extra_options)
  File "/home/airflow/.local/lib/python3.9/site-packages/airflow/providers/http/hooks/http.py", line 222, in run_and_check
    raise ex
  File "/home/airflow/.local/lib/python3.9/site-packages/airflow/providers/http/hooks/http.py", line 214, in run_and_check
    response = session.send(prepped_request, **send_kwargs)
  File "/home/airflow/.local/lib/python3.9/site-packages/requests/sessions.py", line 703, in send
    r = adapter.send(request, **kwargs)
  File "/home/airflow/.local/lib/python3.9/site-packages/requests/adapters.py", line 519, in send
    raise ConnectionError(e, request=request)
requests.exceptions.ConnectionError: HTTPConnectionPool(host='start_report', port=80): Max retries exceeded with url: / (Caused by NewConnectionError('<urllib3.connection.HTTPConnection object at 0x7ff609808a60>: Failed to establish a new connection: [Errno -2] Name or service not known'))
[2025-03-11T13:58:13.032+0000] {taskinstance.py:1138} INFO - Marking task as FAILED. dag_id=5_2_sencor, task_id=start_report_task, execution_date=20250311T135805, start_date=20250311T135809, end_date=20250311T135813
[2025-03-11T13:58:13.043+0000] {standard_task_runner.py:107} ERROR - Failed to execute job 58 for task start_report_task (HTTPConnectionPool(host='start_report', port=80): Max retries exceeded with url: / (Caused by NewConnectionError('<urllib3.connection.HTTPConnection object at 0x7ff609808a60>: Failed to establish a new connection: [Errno -2] Name or service not known')); 7387)
[2025-03-11T13:58:13.078+0000] {local_task_job_runner.py:234} INFO - Task exited with return code 1
[2025-03-11T13:58:13.090+0000] {taskinstance.py:3280} INFO - 0 downstream tasks scheduled from follow-on schedule check
