[2025-02-27T09:51:17.246+0000] {taskinstance.py:1956} INFO - Dependencies all met for dep_context=non-requeueable deps ti=<TaskInstance: 3_4_2_homework_assignment.upload_to_clickhouse_task scheduled__2024-01-09T00:00:00+00:00 [queued]>
[2025-02-27T09:51:17.254+0000] {taskinstance.py:1956} INFO - Dependencies all met for dep_context=requeueable deps ti=<TaskInstance: 3_4_2_homework_assignment.upload_to_clickhouse_task scheduled__2024-01-09T00:00:00+00:00 [queued]>
[2025-02-27T09:51:17.254+0000] {taskinstance.py:2170} INFO - Starting attempt 1 of 1
[2025-02-27T09:51:17.267+0000] {taskinstance.py:2191} INFO - Executing <Task(PythonOperator): upload_to_clickhouse_task> on 2024-01-09 00:00:00+00:00
[2025-02-27T09:51:17.273+0000] {standard_task_runner.py:60} INFO - Started process 2541 to run task
[2025-02-27T09:51:17.275+0000] {standard_task_runner.py:87} INFO - Running: ['airflow', 'tasks', 'run', '3_4_2_homework_assignment', 'upload_to_clickhouse_task', 'scheduled__2024-01-09T00:00:00+00:00', '--job-id', '28', '--raw', '--subdir', 'DAGS_FOLDER/3_4_2_homework_assignment.py', '--cfg-path', '/tmp/tmpesxg21q3']
[2025-02-27T09:51:17.277+0000] {standard_task_runner.py:88} INFO - Job 28: Subtask upload_to_clickhouse_task
[2025-02-27T09:51:17.307+0000] {task_command.py:423} INFO - Running <TaskInstance: 3_4_2_homework_assignment.upload_to_clickhouse_task scheduled__2024-01-09T00:00:00+00:00 [running]> on host ea5964584459
[2025-02-27T09:51:17.353+0000] {taskinstance.py:2480} INFO - Exporting env vars: AIRFLOW_CTX_DAG_OWNER='airflow' AIRFLOW_CTX_DAG_ID='3_4_2_homework_assignment' AIRFLOW_CTX_TASK_ID='upload_to_clickhouse_task' AIRFLOW_CTX_EXECUTION_DATE='2024-01-09T00:00:00+00:00' AIRFLOW_CTX_TRY_NUMBER='1' AIRFLOW_CTX_DAG_RUN_ID='scheduled__2024-01-09T00:00:00+00:00'
[2025-02-27T09:51:17.356+0000] {taskinstance.py:2698} ERROR - Task failed with exception
Traceback (most recent call last):
  File "/home/airflow/.local/lib/python3.9/site-packages/airflow/models/taskinstance.py", line 433, in _execute_task
    result = execute_callable(context=context, **execute_callable_kwargs)
  File "/home/airflow/.local/lib/python3.9/site-packages/airflow/operators/python.py", line 199, in execute
    return_value = self.execute_callable()
  File "/home/airflow/.local/lib/python3.9/site-packages/airflow/operators/python.py", line 216, in execute_callable
    return self.python_callable(*self.op_args, **self.op_kwargs)
  File "/opt/airflow/dags/3_4_2_homework_assignment.py", line 92, in upload_to_clickhouse
    data_frame = pd.read_csv(csv_file)
  File "/home/airflow/.local/lib/python3.9/site-packages/pandas/io/parsers/readers.py", line 948, in read_csv
    return _read(filepath_or_buffer, kwds)
  File "/home/airflow/.local/lib/python3.9/site-packages/pandas/io/parsers/readers.py", line 611, in _read
    parser = TextFileReader(filepath_or_buffer, **kwds)
  File "/home/airflow/.local/lib/python3.9/site-packages/pandas/io/parsers/readers.py", line 1448, in __init__
    self._engine = self._make_engine(f, self.engine)
  File "/home/airflow/.local/lib/python3.9/site-packages/pandas/io/parsers/readers.py", line 1705, in _make_engine
    self.handles = get_handle(
  File "/home/airflow/.local/lib/python3.9/site-packages/pandas/io/common.py", line 863, in get_handle
    handle = open(
FileNotFoundError: [Errno 2] No such file or directory: 'extracted_data_csv.csv'
[2025-02-27T09:51:17.361+0000] {taskinstance.py:1138} INFO - Marking task as FAILED. dag_id=3_4_2_homework_assignment, task_id=upload_to_clickhouse_task, execution_date=20240109T000000, start_date=20250227T095117, end_date=20250227T095117
[2025-02-27T09:51:17.370+0000] {standard_task_runner.py:107} ERROR - Failed to execute job 28 for task upload_to_clickhouse_task ([Errno 2] No such file or directory: 'extracted_data_csv.csv'; 2541)
[2025-02-27T09:51:17.409+0000] {local_task_job_runner.py:234} INFO - Task exited with return code 1
[2025-02-27T09:51:17.419+0000] {taskinstance.py:3280} INFO - 0 downstream tasks scheduled from follow-on schedule check
[2025-02-27T09:55:36.355+0000] {taskinstance.py:1956} INFO - Dependencies all met for dep_context=non-requeueable deps ti=<TaskInstance: 3_4_2_homework_assignment.upload_to_clickhouse_task scheduled__2024-01-09T00:00:00+00:00 [queued]>
[2025-02-27T09:55:36.360+0000] {taskinstance.py:1956} INFO - Dependencies all met for dep_context=requeueable deps ti=<TaskInstance: 3_4_2_homework_assignment.upload_to_clickhouse_task scheduled__2024-01-09T00:00:00+00:00 [queued]>
[2025-02-27T09:55:36.360+0000] {taskinstance.py:2170} INFO - Starting attempt 1 of 1
[2025-02-27T09:55:36.370+0000] {taskinstance.py:2191} INFO - Executing <Task(PythonOperator): upload_to_clickhouse_task> on 2024-01-09 00:00:00+00:00
[2025-02-27T09:55:36.375+0000] {standard_task_runner.py:60} INFO - Started process 3119 to run task
[2025-02-27T09:55:36.377+0000] {standard_task_runner.py:87} INFO - Running: ['airflow', 'tasks', 'run', '3_4_2_homework_assignment', 'upload_to_clickhouse_task', 'scheduled__2024-01-09T00:00:00+00:00', '--job-id', '28', '--raw', '--subdir', 'DAGS_FOLDER/3_4_2_homework_assignment.py', '--cfg-path', '/tmp/tmprqppra6d']
[2025-02-27T09:55:36.378+0000] {standard_task_runner.py:88} INFO - Job 28: Subtask upload_to_clickhouse_task
[2025-02-27T09:55:36.405+0000] {task_command.py:423} INFO - Running <TaskInstance: 3_4_2_homework_assignment.upload_to_clickhouse_task scheduled__2024-01-09T00:00:00+00:00 [running]> on host ea5964584459
[2025-02-27T09:55:36.443+0000] {taskinstance.py:2480} INFO - Exporting env vars: AIRFLOW_CTX_DAG_OWNER='airflow' AIRFLOW_CTX_DAG_ID='3_4_2_homework_assignment' AIRFLOW_CTX_TASK_ID='upload_to_clickhouse_task' AIRFLOW_CTX_EXECUTION_DATE='2024-01-09T00:00:00+00:00' AIRFLOW_CTX_TRY_NUMBER='1' AIRFLOW_CTX_DAG_RUN_ID='scheduled__2024-01-09T00:00:00+00:00'
[2025-02-27T09:55:36.445+0000] {taskinstance.py:2698} ERROR - Task failed with exception
Traceback (most recent call last):
  File "/home/airflow/.local/lib/python3.9/site-packages/airflow/models/taskinstance.py", line 433, in _execute_task
    result = execute_callable(context=context, **execute_callable_kwargs)
  File "/home/airflow/.local/lib/python3.9/site-packages/airflow/operators/python.py", line 199, in execute
    return_value = self.execute_callable()
  File "/home/airflow/.local/lib/python3.9/site-packages/airflow/operators/python.py", line 216, in execute_callable
    return self.python_callable(*self.op_args, **self.op_kwargs)
  File "/opt/airflow/dags/3_4_2_homework_assignment.py", line 93, in upload_to_clickhouse
    data_frame = pd.read_csv(csv_file)
  File "/home/airflow/.local/lib/python3.9/site-packages/pandas/io/parsers/readers.py", line 948, in read_csv
    return _read(filepath_or_buffer, kwds)
  File "/home/airflow/.local/lib/python3.9/site-packages/pandas/io/parsers/readers.py", line 611, in _read
    parser = TextFileReader(filepath_or_buffer, **kwds)
  File "/home/airflow/.local/lib/python3.9/site-packages/pandas/io/parsers/readers.py", line 1448, in __init__
    self._engine = self._make_engine(f, self.engine)
  File "/home/airflow/.local/lib/python3.9/site-packages/pandas/io/parsers/readers.py", line 1705, in _make_engine
    self.handles = get_handle(
  File "/home/airflow/.local/lib/python3.9/site-packages/pandas/io/common.py", line 863, in get_handle
    handle = open(
FileNotFoundError: [Errno 2] No such file or directory: 'extracted_data_csv.csv'
[2025-02-27T09:55:36.450+0000] {taskinstance.py:1138} INFO - Marking task as FAILED. dag_id=3_4_2_homework_assignment, task_id=upload_to_clickhouse_task, execution_date=20240109T000000, start_date=20250227T095536, end_date=20250227T095536
[2025-02-27T09:55:36.457+0000] {standard_task_runner.py:107} ERROR - Failed to execute job 28 for task upload_to_clickhouse_task ([Errno 2] No such file or directory: 'extracted_data_csv.csv'; 3119)
[2025-02-27T09:55:36.471+0000] {local_task_job_runner.py:234} INFO - Task exited with return code 1
[2025-02-27T09:55:36.480+0000] {taskinstance.py:3280} INFO - 0 downstream tasks scheduled from follow-on schedule check
[2025-02-27T10:07:29.806+0000] {taskinstance.py:1956} INFO - Dependencies all met for dep_context=non-requeueable deps ti=<TaskInstance: 3_4_2_homework_assignment.upload_to_clickhouse_task scheduled__2024-01-09T00:00:00+00:00 [queued]>
[2025-02-27T10:07:29.811+0000] {taskinstance.py:1956} INFO - Dependencies all met for dep_context=requeueable deps ti=<TaskInstance: 3_4_2_homework_assignment.upload_to_clickhouse_task scheduled__2024-01-09T00:00:00+00:00 [queued]>
[2025-02-27T10:07:29.812+0000] {taskinstance.py:2170} INFO - Starting attempt 1 of 1
[2025-02-27T10:07:29.823+0000] {taskinstance.py:2191} INFO - Executing <Task(PythonOperator): upload_to_clickhouse_task> on 2024-01-09 00:00:00+00:00
[2025-02-27T10:07:29.829+0000] {standard_task_runner.py:60} INFO - Started process 3763 to run task
[2025-02-27T10:07:29.831+0000] {standard_task_runner.py:87} INFO - Running: ['airflow', 'tasks', 'run', '3_4_2_homework_assignment', 'upload_to_clickhouse_task', 'scheduled__2024-01-09T00:00:00+00:00', '--job-id', '28', '--raw', '--subdir', 'DAGS_FOLDER/3_4_2_homework_assignment.py', '--cfg-path', '/tmp/tmp6ihwqy_s']
[2025-02-27T10:07:29.833+0000] {standard_task_runner.py:88} INFO - Job 28: Subtask upload_to_clickhouse_task
[2025-02-27T10:07:29.860+0000] {task_command.py:423} INFO - Running <TaskInstance: 3_4_2_homework_assignment.upload_to_clickhouse_task scheduled__2024-01-09T00:00:00+00:00 [running]> on host ea5964584459
[2025-02-27T10:07:29.903+0000] {taskinstance.py:2480} INFO - Exporting env vars: AIRFLOW_CTX_DAG_OWNER='airflow' AIRFLOW_CTX_DAG_ID='3_4_2_homework_assignment' AIRFLOW_CTX_TASK_ID='upload_to_clickhouse_task' AIRFLOW_CTX_EXECUTION_DATE='2024-01-09T00:00:00+00:00' AIRFLOW_CTX_TRY_NUMBER='1' AIRFLOW_CTX_DAG_RUN_ID='scheduled__2024-01-09T00:00:00+00:00'
[2025-02-27T10:07:29.906+0000] {taskinstance.py:2698} ERROR - Task failed with exception
Traceback (most recent call last):
  File "/home/airflow/.local/lib/python3.9/site-packages/airflow/models/taskinstance.py", line 433, in _execute_task
    result = execute_callable(context=context, **execute_callable_kwargs)
  File "/home/airflow/.local/lib/python3.9/site-packages/airflow/operators/python.py", line 199, in execute
    return_value = self.execute_callable()
  File "/home/airflow/.local/lib/python3.9/site-packages/airflow/operators/python.py", line 216, in execute_callable
    return self.python_callable(*self.op_args, **self.op_kwargs)
  File "/opt/airflow/dags/3_4_2_homework_assignment.py", line 87, in upload_to_clickhouse
    data_frame = pd.read_csv(csv_file)
  File "/home/airflow/.local/lib/python3.9/site-packages/pandas/io/parsers/readers.py", line 948, in read_csv
    return _read(filepath_or_buffer, kwds)
  File "/home/airflow/.local/lib/python3.9/site-packages/pandas/io/parsers/readers.py", line 611, in _read
    parser = TextFileReader(filepath_or_buffer, **kwds)
  File "/home/airflow/.local/lib/python3.9/site-packages/pandas/io/parsers/readers.py", line 1448, in __init__
    self._engine = self._make_engine(f, self.engine)
  File "/home/airflow/.local/lib/python3.9/site-packages/pandas/io/parsers/readers.py", line 1705, in _make_engine
    self.handles = get_handle(
  File "/home/airflow/.local/lib/python3.9/site-packages/pandas/io/common.py", line 863, in get_handle
    handle = open(
FileNotFoundError: [Errno 2] No such file or directory: 'extracted_data_csv.csv'
[2025-02-27T10:07:29.911+0000] {taskinstance.py:1138} INFO - Marking task as FAILED. dag_id=3_4_2_homework_assignment, task_id=upload_to_clickhouse_task, execution_date=20240109T000000, start_date=20250227T100729, end_date=20250227T100729
[2025-02-27T10:07:29.919+0000] {standard_task_runner.py:107} ERROR - Failed to execute job 28 for task upload_to_clickhouse_task ([Errno 2] No such file or directory: 'extracted_data_csv.csv'; 3763)
[2025-02-27T10:07:29.967+0000] {local_task_job_runner.py:234} INFO - Task exited with return code 1
[2025-02-27T10:07:29.976+0000] {taskinstance.py:3280} INFO - 0 downstream tasks scheduled from follow-on schedule check
[2025-02-27T10:15:05.931+0000] {taskinstance.py:1956} INFO - Dependencies all met for dep_context=non-requeueable deps ti=<TaskInstance: 3_4_2_homework_assignment.upload_to_clickhouse_task scheduled__2024-01-09T00:00:00+00:00 [queued]>
[2025-02-27T10:15:05.936+0000] {taskinstance.py:1956} INFO - Dependencies all met for dep_context=requeueable deps ti=<TaskInstance: 3_4_2_homework_assignment.upload_to_clickhouse_task scheduled__2024-01-09T00:00:00+00:00 [queued]>
[2025-02-27T10:15:05.936+0000] {taskinstance.py:2170} INFO - Starting attempt 1 of 1
[2025-02-27T10:15:05.947+0000] {taskinstance.py:2191} INFO - Executing <Task(PythonOperator): upload_to_clickhouse_task> on 2024-01-09 00:00:00+00:00
[2025-02-27T10:15:05.951+0000] {standard_task_runner.py:60} INFO - Started process 4658 to run task
[2025-02-27T10:15:05.953+0000] {standard_task_runner.py:87} INFO - Running: ['airflow', 'tasks', 'run', '3_4_2_homework_assignment', 'upload_to_clickhouse_task', 'scheduled__2024-01-09T00:00:00+00:00', '--job-id', '28', '--raw', '--subdir', 'DAGS_FOLDER/3_4_2_homework_assignment.py', '--cfg-path', '/tmp/tmpsuxpftuq']
[2025-02-27T10:15:05.954+0000] {standard_task_runner.py:88} INFO - Job 28: Subtask upload_to_clickhouse_task
[2025-02-27T10:15:05.979+0000] {task_command.py:423} INFO - Running <TaskInstance: 3_4_2_homework_assignment.upload_to_clickhouse_task scheduled__2024-01-09T00:00:00+00:00 [running]> on host ea5964584459
[2025-02-27T10:15:06.020+0000] {taskinstance.py:2480} INFO - Exporting env vars: AIRFLOW_CTX_DAG_OWNER='airflow' AIRFLOW_CTX_DAG_ID='3_4_2_homework_assignment' AIRFLOW_CTX_TASK_ID='upload_to_clickhouse_task' AIRFLOW_CTX_EXECUTION_DATE='2024-01-09T00:00:00+00:00' AIRFLOW_CTX_TRY_NUMBER='1' AIRFLOW_CTX_DAG_RUN_ID='scheduled__2024-01-09T00:00:00+00:00'
[2025-02-27T10:15:06.025+0000] {connection.py:411} WARNING - Failed to connect to None:9000
Traceback (most recent call last):
  File "/home/airflow/.local/lib/python3.9/site-packages/clickhouse_driver/connection.py", line 399, in connect
    return self._init_connection(host, port)
  File "/home/airflow/.local/lib/python3.9/site-packages/clickhouse_driver/connection.py", line 329, in _init_connection
    self.socket = self._create_socket(host, port)
  File "/home/airflow/.local/lib/python3.9/site-packages/clickhouse_driver/connection.py", line 301, in _create_socket
    raise err
  File "/home/airflow/.local/lib/python3.9/site-packages/clickhouse_driver/connection.py", line 292, in _create_socket
    sock.connect(sa)
ConnectionRefusedError: [Errno 111] Connection refused
[2025-02-27T10:15:06.026+0000] {taskinstance.py:2698} ERROR - Task failed with exception
Traceback (most recent call last):
  File "/home/airflow/.local/lib/python3.9/site-packages/airflow/models/taskinstance.py", line 433, in _execute_task
    result = execute_callable(context=context, **execute_callable_kwargs)
  File "/home/airflow/.local/lib/python3.9/site-packages/airflow/operators/python.py", line 199, in execute
    return_value = self.execute_callable()
  File "/home/airflow/.local/lib/python3.9/site-packages/airflow/operators/python.py", line 216, in execute_callable
    return self.python_callable(*self.op_args, **self.op_kwargs)
  File "/opt/airflow/dags/3_4_2_homework_assignment.py", line 90, in upload_to_clickhouse
    client.execute(f'CREATE TABLE IF NOT EXISTS {table_name} (source String, currency String, value Float, date String) ENGINE Log')
  File "/home/airflow/.local/lib/python3.9/site-packages/clickhouse_driver/client.py", line 370, in execute
    with self.disconnect_on_error(query, settings):
  File "/usr/local/lib/python3.9/contextlib.py", line 119, in __enter__
    return next(self.gen)
  File "/home/airflow/.local/lib/python3.9/site-packages/clickhouse_driver/client.py", line 313, in disconnect_on_error
    self.establish_connection(settings)
  File "/home/airflow/.local/lib/python3.9/site-packages/clickhouse_driver/client.py", line 300, in establish_connection
    self.connection.force_connect()
  File "/home/airflow/.local/lib/python3.9/site-packages/clickhouse_driver/connection.py", line 258, in force_connect
    self.connect()
  File "/home/airflow/.local/lib/python3.9/site-packages/clickhouse_driver/connection.py", line 420, in connect
    raise err
clickhouse_driver.errors.NetworkError: Code: 210. Connection refused (None:9000)
[2025-02-27T10:15:06.031+0000] {taskinstance.py:1138} INFO - Marking task as FAILED. dag_id=3_4_2_homework_assignment, task_id=upload_to_clickhouse_task, execution_date=20240109T000000, start_date=20250227T101505, end_date=20250227T101506
[2025-02-27T10:15:06.038+0000] {standard_task_runner.py:107} ERROR - Failed to execute job 28 for task upload_to_clickhouse_task (Code: 210. Connection refused (None:9000); 4658)
[2025-02-27T10:15:06.046+0000] {local_task_job_runner.py:234} INFO - Task exited with return code 1
[2025-02-27T10:15:06.056+0000] {taskinstance.py:3280} INFO - 0 downstream tasks scheduled from follow-on schedule check
[2025-02-27T10:27:46.385+0000] {taskinstance.py:1956} INFO - Dependencies all met for dep_context=non-requeueable deps ti=<TaskInstance: 3_4_2_homework_assignment.upload_to_clickhouse_task scheduled__2024-01-09T00:00:00+00:00 [queued]>
[2025-02-27T10:27:46.390+0000] {taskinstance.py:1956} INFO - Dependencies all met for dep_context=requeueable deps ti=<TaskInstance: 3_4_2_homework_assignment.upload_to_clickhouse_task scheduled__2024-01-09T00:00:00+00:00 [queued]>
[2025-02-27T10:27:46.390+0000] {taskinstance.py:2170} INFO - Starting attempt 1 of 1
[2025-02-27T10:27:46.402+0000] {taskinstance.py:2191} INFO - Executing <Task(PythonOperator): upload_to_clickhouse_task> on 2024-01-09 00:00:00+00:00
[2025-02-27T10:27:46.407+0000] {standard_task_runner.py:60} INFO - Started process 5993 to run task
[2025-02-27T10:27:46.409+0000] {standard_task_runner.py:87} INFO - Running: ['airflow', 'tasks', 'run', '3_4_2_homework_assignment', 'upload_to_clickhouse_task', 'scheduled__2024-01-09T00:00:00+00:00', '--job-id', '28', '--raw', '--subdir', 'DAGS_FOLDER/3_4_2_homework_assignment.py', '--cfg-path', '/tmp/tmpoz84uhwf']
[2025-02-27T10:27:46.410+0000] {standard_task_runner.py:88} INFO - Job 28: Subtask upload_to_clickhouse_task
[2025-02-27T10:27:46.434+0000] {task_command.py:423} INFO - Running <TaskInstance: 3_4_2_homework_assignment.upload_to_clickhouse_task scheduled__2024-01-09T00:00:00+00:00 [running]> on host ea5964584459
[2025-02-27T10:27:46.470+0000] {taskinstance.py:2480} INFO - Exporting env vars: AIRFLOW_CTX_DAG_OWNER='airflow' AIRFLOW_CTX_DAG_ID='3_4_2_homework_assignment' AIRFLOW_CTX_TASK_ID='upload_to_clickhouse_task' AIRFLOW_CTX_EXECUTION_DATE='2024-01-09T00:00:00+00:00' AIRFLOW_CTX_TRY_NUMBER='1' AIRFLOW_CTX_DAG_RUN_ID='scheduled__2024-01-09T00:00:00+00:00'
[2025-02-27T10:27:46.481+0000] {taskinstance.py:2698} ERROR - Task failed with exception
Traceback (most recent call last):
  File "/home/airflow/.local/lib/python3.9/site-packages/airflow/models/taskinstance.py", line 433, in _execute_task
    result = execute_callable(context=context, **execute_callable_kwargs)
  File "/home/airflow/.local/lib/python3.9/site-packages/airflow/operators/python.py", line 199, in execute
    return_value = self.execute_callable()
  File "/home/airflow/.local/lib/python3.9/site-packages/airflow/operators/python.py", line 216, in execute_callable
    return self.python_callable(*self.op_args, **self.op_kwargs)
  File "/opt/airflow/dags/3_4_2_homework_assignment.py", line 92, in upload_to_clickhouse
    client.execute(f'INSERT INTO {table_name} VALUES', data_frame.to_dict('records'))
  File "/home/airflow/.local/lib/python3.9/site-packages/clickhouse_driver/client.py", line 376, in execute
    rv = self.process_insert_query(
  File "/home/airflow/.local/lib/python3.9/site-packages/clickhouse_driver/client.py", line 607, in process_insert_query
    rv = self.send_data(sample_block, data,
  File "/home/airflow/.local/lib/python3.9/site-packages/clickhouse_driver/client.py", line 658, in send_data
    block = block_cls(sample_block.columns_with_types, chunk,
  File "/home/airflow/.local/lib/python3.9/site-packages/clickhouse_driver/block.py", line 40, in __init__
    self.data = self.normalize(data or [])
  File "/home/airflow/.local/lib/python3.9/site-packages/clickhouse_driver/block.py", line 128, in normalize
    self._mutate_dicts_to_rows(data)
  File "/home/airflow/.local/lib/python3.9/site-packages/clickhouse_driver/block.py", line 159, in _mutate_dicts_to_rows
    return self._pure_mutate_dicts_to_rows(
  File "/home/airflow/.local/lib/python3.9/site-packages/clickhouse_driver/block.py", line 186, in _pure_mutate_dicts_to_rows
    new_data.append(row[name])
KeyError: 'source'
[2025-02-27T10:27:46.487+0000] {taskinstance.py:1138} INFO - Marking task as FAILED. dag_id=3_4_2_homework_assignment, task_id=upload_to_clickhouse_task, execution_date=20240109T000000, start_date=20250227T102746, end_date=20250227T102746
[2025-02-27T10:27:46.495+0000] {standard_task_runner.py:107} ERROR - Failed to execute job 28 for task upload_to_clickhouse_task ('source'; 5993)
[2025-02-27T10:27:46.543+0000] {local_task_job_runner.py:234} INFO - Task exited with return code 1
[2025-02-27T10:27:46.552+0000] {taskinstance.py:3280} INFO - 0 downstream tasks scheduled from follow-on schedule check
[2025-02-27T10:36:08.341+0000] {taskinstance.py:1956} INFO - Dependencies all met for dep_context=non-requeueable deps ti=<TaskInstance: 3_4_2_homework_assignment.upload_to_clickhouse_task scheduled__2024-01-09T00:00:00+00:00 [queued]>
[2025-02-27T10:36:08.346+0000] {taskinstance.py:1956} INFO - Dependencies all met for dep_context=requeueable deps ti=<TaskInstance: 3_4_2_homework_assignment.upload_to_clickhouse_task scheduled__2024-01-09T00:00:00+00:00 [queued]>
[2025-02-27T10:36:08.346+0000] {taskinstance.py:2170} INFO - Starting attempt 1 of 1
[2025-02-27T10:36:08.358+0000] {taskinstance.py:2191} INFO - Executing <Task(PythonOperator): upload_to_clickhouse_task> on 2024-01-09 00:00:00+00:00
[2025-02-27T10:36:08.363+0000] {standard_task_runner.py:60} INFO - Started process 6653 to run task
[2025-02-27T10:36:08.365+0000] {standard_task_runner.py:87} INFO - Running: ['airflow', 'tasks', 'run', '3_4_2_homework_assignment', 'upload_to_clickhouse_task', 'scheduled__2024-01-09T00:00:00+00:00', '--job-id', '28', '--raw', '--subdir', 'DAGS_FOLDER/3_4_2_homework_assignment.py', '--cfg-path', '/tmp/tmpw9neaq9y']
[2025-02-27T10:36:08.366+0000] {standard_task_runner.py:88} INFO - Job 28: Subtask upload_to_clickhouse_task
[2025-02-27T10:36:08.392+0000] {task_command.py:423} INFO - Running <TaskInstance: 3_4_2_homework_assignment.upload_to_clickhouse_task scheduled__2024-01-09T00:00:00+00:00 [running]> on host ea5964584459
[2025-02-27T10:36:08.429+0000] {taskinstance.py:2480} INFO - Exporting env vars: AIRFLOW_CTX_DAG_OWNER='airflow' AIRFLOW_CTX_DAG_ID='3_4_2_homework_assignment' AIRFLOW_CTX_TASK_ID='upload_to_clickhouse_task' AIRFLOW_CTX_EXECUTION_DATE='2024-01-09T00:00:00+00:00' AIRFLOW_CTX_TRY_NUMBER='1' AIRFLOW_CTX_DAG_RUN_ID='scheduled__2024-01-09T00:00:00+00:00'
[2025-02-27T10:36:08.441+0000] {taskinstance.py:2698} ERROR - Task failed with exception
Traceback (most recent call last):
  File "/home/airflow/.local/lib/python3.9/site-packages/airflow/models/taskinstance.py", line 433, in _execute_task
    result = execute_callable(context=context, **execute_callable_kwargs)
  File "/home/airflow/.local/lib/python3.9/site-packages/airflow/operators/python.py", line 199, in execute
    return_value = self.execute_callable()
  File "/home/airflow/.local/lib/python3.9/site-packages/airflow/operators/python.py", line 216, in execute_callable
    return self.python_callable(*self.op_args, **self.op_kwargs)
  File "/opt/airflow/dags/3_4_2_homework_assignment.py", line 93, in upload_to_clickhouse
    client.execute(f'INSERT INTO {table_name} VALUES', data_frame.to_dict('records'))
  File "/home/airflow/.local/lib/python3.9/site-packages/clickhouse_driver/client.py", line 376, in execute
    rv = self.process_insert_query(
  File "/home/airflow/.local/lib/python3.9/site-packages/clickhouse_driver/client.py", line 607, in process_insert_query
    rv = self.send_data(sample_block, data,
  File "/home/airflow/.local/lib/python3.9/site-packages/clickhouse_driver/client.py", line 658, in send_data
    block = block_cls(sample_block.columns_with_types, chunk,
  File "/home/airflow/.local/lib/python3.9/site-packages/clickhouse_driver/block.py", line 40, in __init__
    self.data = self.normalize(data or [])
  File "/home/airflow/.local/lib/python3.9/site-packages/clickhouse_driver/block.py", line 128, in normalize
    self._mutate_dicts_to_rows(data)
  File "/home/airflow/.local/lib/python3.9/site-packages/clickhouse_driver/block.py", line 159, in _mutate_dicts_to_rows
    return self._pure_mutate_dicts_to_rows(
  File "/home/airflow/.local/lib/python3.9/site-packages/clickhouse_driver/block.py", line 186, in _pure_mutate_dicts_to_rows
    new_data.append(row[name])
KeyError: 'source'
[2025-02-27T10:36:08.447+0000] {taskinstance.py:1138} INFO - Marking task as FAILED. dag_id=3_4_2_homework_assignment, task_id=upload_to_clickhouse_task, execution_date=20240109T000000, start_date=20250227T103608, end_date=20250227T103608
[2025-02-27T10:36:08.455+0000] {standard_task_runner.py:107} ERROR - Failed to execute job 28 for task upload_to_clickhouse_task ('source'; 6653)
[2025-02-27T10:36:08.500+0000] {local_task_job_runner.py:234} INFO - Task exited with return code 1
[2025-02-27T10:36:08.508+0000] {taskinstance.py:3280} INFO - 0 downstream tasks scheduled from follow-on schedule check
[2025-02-27T10:46:00.418+0000] {taskinstance.py:1956} INFO - Dependencies all met for dep_context=non-requeueable deps ti=<TaskInstance: 3_4_2_homework_assignment.upload_to_clickhouse_task scheduled__2024-01-09T00:00:00+00:00 [queued]>
[2025-02-27T10:46:00.423+0000] {taskinstance.py:1956} INFO - Dependencies all met for dep_context=requeueable deps ti=<TaskInstance: 3_4_2_homework_assignment.upload_to_clickhouse_task scheduled__2024-01-09T00:00:00+00:00 [queued]>
[2025-02-27T10:46:00.424+0000] {taskinstance.py:2170} INFO - Starting attempt 1 of 1
[2025-02-27T10:46:00.434+0000] {taskinstance.py:2191} INFO - Executing <Task(PythonOperator): upload_to_clickhouse_task> on 2024-01-09 00:00:00+00:00
[2025-02-27T10:46:00.439+0000] {standard_task_runner.py:60} INFO - Started process 7338 to run task
[2025-02-27T10:46:00.441+0000] {standard_task_runner.py:87} INFO - Running: ['airflow', 'tasks', 'run', '3_4_2_homework_assignment', 'upload_to_clickhouse_task', 'scheduled__2024-01-09T00:00:00+00:00', '--job-id', '28', '--raw', '--subdir', 'DAGS_FOLDER/3_4_2_homework_assignment.py', '--cfg-path', '/tmp/tmp79evlga3']
[2025-02-27T10:46:00.443+0000] {standard_task_runner.py:88} INFO - Job 28: Subtask upload_to_clickhouse_task
[2025-02-27T10:46:00.466+0000] {task_command.py:423} INFO - Running <TaskInstance: 3_4_2_homework_assignment.upload_to_clickhouse_task scheduled__2024-01-09T00:00:00+00:00 [running]> on host ea5964584459
[2025-02-27T10:46:00.505+0000] {taskinstance.py:2480} INFO - Exporting env vars: AIRFLOW_CTX_DAG_OWNER='airflow' AIRFLOW_CTX_DAG_ID='3_4_2_homework_assignment' AIRFLOW_CTX_TASK_ID='upload_to_clickhouse_task' AIRFLOW_CTX_EXECUTION_DATE='2024-01-09T00:00:00+00:00' AIRFLOW_CTX_TRY_NUMBER='1' AIRFLOW_CTX_DAG_RUN_ID='scheduled__2024-01-09T00:00:00+00:00'
[2025-02-27T10:46:00.518+0000] {unix.py:142} WARNING - /etc/timezone is deprecated on Debian, and no longer reliable. Ignoring.
[2025-02-27T10:46:00.521+0000] {python.py:201} INFO - Done. Returned value was: None
[2025-02-27T10:46:00.524+0000] {taskinstance.py:1138} INFO - Marking task as SUCCESS. dag_id=3_4_2_homework_assignment, task_id=upload_to_clickhouse_task, execution_date=20240109T000000, start_date=20250227T104600, end_date=20250227T104600
[2025-02-27T10:46:00.575+0000] {local_task_job_runner.py:234} INFO - Task exited with return code 0
[2025-02-27T10:46:00.584+0000] {taskinstance.py:3280} INFO - 0 downstream tasks scheduled from follow-on schedule check
