[2025-03-03T14:24:41.766+0000] {taskinstance.py:1956} INFO - Dependencies all met for dep_context=non-requeueable deps ti=<TaskInstance: 4_4_house_assignment.upload_to_clickhouse scheduled__2024-01-02T00:00:00+00:00 [queued]>
[2025-03-03T14:24:41.778+0000] {taskinstance.py:1956} INFO - Dependencies all met for dep_context=requeueable deps ti=<TaskInstance: 4_4_house_assignment.upload_to_clickhouse scheduled__2024-01-02T00:00:00+00:00 [queued]>
[2025-03-03T14:24:41.779+0000] {taskinstance.py:2170} INFO - Starting attempt 1 of 1
[2025-03-03T14:24:41.796+0000] {taskinstance.py:2191} INFO - Executing <Task(PythonOperator): upload_to_clickhouse> on 2024-01-02 00:00:00+00:00
[2025-03-03T14:24:41.805+0000] {standard_task_runner.py:60} INFO - Started process 2175 to run task
[2025-03-03T14:24:41.809+0000] {standard_task_runner.py:87} INFO - Running: ['airflow', 'tasks', 'run', '4_4_house_assignment', 'upload_to_clickhouse', 'scheduled__2024-01-02T00:00:00+00:00', '--job-id', '9', '--raw', '--subdir', 'DAGS_FOLDER/4_4_house_assignment.py', '--cfg-path', '/tmp/tmpoghaj2yi']
[2025-03-03T14:24:41.811+0000] {standard_task_runner.py:88} INFO - Job 9: Subtask upload_to_clickhouse
[2025-03-03T14:24:41.840+0000] {task_command.py:423} INFO - Running <TaskInstance: 4_4_house_assignment.upload_to_clickhouse scheduled__2024-01-02T00:00:00+00:00 [running]> on host 9a2e4036dec3
[2025-03-03T14:24:41.886+0000] {taskinstance.py:2480} INFO - Exporting env vars: AIRFLOW_CTX_DAG_OWNER='airflow' AIRFLOW_CTX_DAG_ID='4_4_house_assignment' AIRFLOW_CTX_TASK_ID='upload_to_clickhouse' AIRFLOW_CTX_EXECUTION_DATE='2024-01-02T00:00:00+00:00' AIRFLOW_CTX_TRY_NUMBER='1' AIRFLOW_CTX_DAG_RUN_ID='scheduled__2024-01-02T00:00:00+00:00'
[2025-03-03T14:24:41.893+0000] {connection.py:411} WARNING - Failed to connect to localhost:9000
Traceback (most recent call last):
  File "/home/airflow/.local/lib/python3.9/site-packages/clickhouse_driver/connection.py", line 399, in connect
    return self._init_connection(host, port)
  File "/home/airflow/.local/lib/python3.9/site-packages/clickhouse_driver/connection.py", line 329, in _init_connection
    self.socket = self._create_socket(host, port)
  File "/home/airflow/.local/lib/python3.9/site-packages/clickhouse_driver/connection.py", line 301, in _create_socket
    raise err
  File "/home/airflow/.local/lib/python3.9/site-packages/clickhouse_driver/connection.py", line 292, in _create_socket
    sock.connect(sa)
ConnectionRefusedError: [Errno 111] Connection refused
[2025-03-03T14:24:41.895+0000] {taskinstance.py:2698} ERROR - Task failed with exception
Traceback (most recent call last):
  File "/home/airflow/.local/lib/python3.9/site-packages/airflow/models/taskinstance.py", line 433, in _execute_task
    result = execute_callable(context=context, **execute_callable_kwargs)
  File "/home/airflow/.local/lib/python3.9/site-packages/airflow/operators/python.py", line 199, in execute
    return_value = self.execute_callable()
  File "/home/airflow/.local/lib/python3.9/site-packages/airflow/operators/python.py", line 216, in execute_callable
    return self.python_callable(*self.op_args, **self.op_kwargs)
  File "/opt/airflow/dags/4_4_house_assignment.py", line 74, in upload_to_clickhouse
    client.execute(f'CREATE TABLE IF NOT EXISTS {table_name} (num_code Int64, char_code String, nominal Int64, name String, value String, date String) ENGINE Log')
  File "/home/airflow/.local/lib/python3.9/site-packages/clickhouse_driver/client.py", line 370, in execute
    with self.disconnect_on_error(query, settings):
  File "/usr/local/lib/python3.9/contextlib.py", line 119, in __enter__
    return next(self.gen)
  File "/home/airflow/.local/lib/python3.9/site-packages/clickhouse_driver/client.py", line 313, in disconnect_on_error
    self.establish_connection(settings)
  File "/home/airflow/.local/lib/python3.9/site-packages/clickhouse_driver/client.py", line 300, in establish_connection
    self.connection.force_connect()
  File "/home/airflow/.local/lib/python3.9/site-packages/clickhouse_driver/connection.py", line 258, in force_connect
    self.connect()
  File "/home/airflow/.local/lib/python3.9/site-packages/clickhouse_driver/connection.py", line 420, in connect
    raise err
clickhouse_driver.errors.NetworkError: Code: 210. Connection refused (localhost:9000)
[2025-03-03T14:24:41.901+0000] {taskinstance.py:1138} INFO - Marking task as FAILED. dag_id=4_4_house_assignment, task_id=upload_to_clickhouse, execution_date=20240102T000000, start_date=20250303T142441, end_date=20250303T142441
[2025-03-03T14:24:41.910+0000] {standard_task_runner.py:107} ERROR - Failed to execute job 9 for task upload_to_clickhouse (Code: 210. Connection refused (localhost:9000); 2175)
[2025-03-03T14:24:41.942+0000] {local_task_job_runner.py:234} INFO - Task exited with return code 1
[2025-03-03T14:24:41.952+0000] {taskinstance.py:3280} INFO - 0 downstream tasks scheduled from follow-on schedule check
[2025-03-03T14:27:27.054+0000] {taskinstance.py:1956} INFO - Dependencies all met for dep_context=non-requeueable deps ti=<TaskInstance: 4_4_house_assignment.upload_to_clickhouse scheduled__2024-01-02T00:00:00+00:00 [queued]>
[2025-03-03T14:27:27.060+0000] {taskinstance.py:1956} INFO - Dependencies all met for dep_context=requeueable deps ti=<TaskInstance: 4_4_house_assignment.upload_to_clickhouse scheduled__2024-01-02T00:00:00+00:00 [queued]>
[2025-03-03T14:27:27.060+0000] {taskinstance.py:2170} INFO - Starting attempt 1 of 1
[2025-03-03T14:27:27.074+0000] {taskinstance.py:2191} INFO - Executing <Task(PythonOperator): upload_to_clickhouse> on 2024-01-02 00:00:00+00:00
[2025-03-03T14:27:27.079+0000] {standard_task_runner.py:60} INFO - Started process 2480 to run task
[2025-03-03T14:27:27.081+0000] {standard_task_runner.py:87} INFO - Running: ['airflow', 'tasks', 'run', '4_4_house_assignment', 'upload_to_clickhouse', 'scheduled__2024-01-02T00:00:00+00:00', '--job-id', '9', '--raw', '--subdir', 'DAGS_FOLDER/4_4_house_assignment.py', '--cfg-path', '/tmp/tmpmqjw2d00']
[2025-03-03T14:27:27.082+0000] {standard_task_runner.py:88} INFO - Job 9: Subtask upload_to_clickhouse
[2025-03-03T14:27:27.109+0000] {task_command.py:423} INFO - Running <TaskInstance: 4_4_house_assignment.upload_to_clickhouse scheduled__2024-01-02T00:00:00+00:00 [running]> on host 9a2e4036dec3
[2025-03-03T14:27:27.161+0000] {taskinstance.py:2480} INFO - Exporting env vars: AIRFLOW_CTX_DAG_OWNER='airflow' AIRFLOW_CTX_DAG_ID='4_4_house_assignment' AIRFLOW_CTX_TASK_ID='upload_to_clickhouse' AIRFLOW_CTX_EXECUTION_DATE='2024-01-02T00:00:00+00:00' AIRFLOW_CTX_TRY_NUMBER='1' AIRFLOW_CTX_DAG_RUN_ID='scheduled__2024-01-02T00:00:00+00:00'
[2025-03-03T14:27:28.743+0000] {unix.py:142} WARNING - /etc/timezone is deprecated on Debian, and no longer reliable. Ignoring.
[2025-03-03T14:27:28.752+0000] {python.py:201} INFO - Done. Returned value was: None
[2025-03-03T14:27:28.756+0000] {taskinstance.py:1138} INFO - Marking task as SUCCESS. dag_id=4_4_house_assignment, task_id=upload_to_clickhouse, execution_date=20240102T000000, start_date=20250303T142727, end_date=20250303T142728
[2025-03-03T14:27:28.787+0000] {local_task_job_runner.py:234} INFO - Task exited with return code 0
[2025-03-03T14:27:28.795+0000] {taskinstance.py:3280} INFO - 0 downstream tasks scheduled from follow-on schedule check
[2025-03-10T09:48:31.975+0000] {taskinstance.py:1956} INFO - Dependencies all met for dep_context=non-requeueable deps ti=<TaskInstance: 4_4_house_assignment.upload_to_clickhouse scheduled__2024-01-02T00:00:00+00:00 [queued]>
[2025-03-10T09:48:31.983+0000] {taskinstance.py:1956} INFO - Dependencies all met for dep_context=requeueable deps ti=<TaskInstance: 4_4_house_assignment.upload_to_clickhouse scheduled__2024-01-02T00:00:00+00:00 [queued]>
[2025-03-10T09:48:31.983+0000] {taskinstance.py:2170} INFO - Starting attempt 1 of 1
[2025-03-10T09:48:31.999+0000] {taskinstance.py:2191} INFO - Executing <Task(PythonOperator): upload_to_clickhouse> on 2024-01-02 00:00:00+00:00
[2025-03-10T09:48:32.005+0000] {standard_task_runner.py:60} INFO - Started process 281 to run task
[2025-03-10T09:48:32.008+0000] {standard_task_runner.py:87} INFO - Running: ['airflow', 'tasks', 'run', '4_4_house_assignment', 'upload_to_clickhouse', 'scheduled__2024-01-02T00:00:00+00:00', '--job-id', '25', '--raw', '--subdir', 'DAGS_FOLDER/4_4_house_assignment.py', '--cfg-path', '/tmp/tmpkkccpkj4']
[2025-03-10T09:48:32.010+0000] {standard_task_runner.py:88} INFO - Job 25: Subtask upload_to_clickhouse
[2025-03-10T09:48:32.042+0000] {task_command.py:423} INFO - Running <TaskInstance: 4_4_house_assignment.upload_to_clickhouse scheduled__2024-01-02T00:00:00+00:00 [running]> on host 9a2e4036dec3
[2025-03-10T09:48:32.103+0000] {taskinstance.py:2480} INFO - Exporting env vars: AIRFLOW_CTX_DAG_OWNER='airflow' AIRFLOW_CTX_DAG_ID='4_4_house_assignment' AIRFLOW_CTX_TASK_ID='upload_to_clickhouse' AIRFLOW_CTX_EXECUTION_DATE='2024-01-02T00:00:00+00:00' AIRFLOW_CTX_TRY_NUMBER='1' AIRFLOW_CTX_DAG_RUN_ID='scheduled__2024-01-02T00:00:00+00:00'
[2025-03-10T09:48:32.120+0000] {unix.py:142} WARNING - /etc/timezone is deprecated on Debian, and no longer reliable. Ignoring.
[2025-03-10T09:48:32.123+0000] {python.py:201} INFO - Done. Returned value was: None
[2025-03-10T09:48:32.128+0000] {taskinstance.py:1138} INFO - Marking task as SUCCESS. dag_id=4_4_house_assignment, task_id=upload_to_clickhouse, execution_date=20240102T000000, start_date=20250310T094831, end_date=20250310T094832
[2025-03-10T09:48:32.182+0000] {local_task_job_runner.py:234} INFO - Task exited with return code 0
[2025-03-10T09:48:32.192+0000] {taskinstance.py:3280} INFO - 0 downstream tasks scheduled from follow-on schedule check
[2025-03-12T14:50:39.639+0000] {taskinstance.py:1956} INFO - Dependencies all met for dep_context=non-requeueable deps ti=<TaskInstance: 4_4_house_assignment.upload_to_clickhouse scheduled__2024-01-02T00:00:00+00:00 [queued]>
[2025-03-12T14:50:39.648+0000] {taskinstance.py:1956} INFO - Dependencies all met for dep_context=requeueable deps ti=<TaskInstance: 4_4_house_assignment.upload_to_clickhouse scheduled__2024-01-02T00:00:00+00:00 [queued]>
[2025-03-12T14:50:39.648+0000] {taskinstance.py:2170} INFO - Starting attempt 1 of 1
[2025-03-12T14:50:39.666+0000] {taskinstance.py:2191} INFO - Executing <Task(PythonOperator): upload_to_clickhouse> on 2024-01-02 00:00:00+00:00
[2025-03-12T14:50:39.671+0000] {standard_task_runner.py:60} INFO - Started process 2484 to run task
[2025-03-12T14:50:39.675+0000] {standard_task_runner.py:87} INFO - Running: ['airflow', 'tasks', 'run', '4_4_house_assignment', 'upload_to_clickhouse', 'scheduled__2024-01-02T00:00:00+00:00', '--job-id', '22', '--raw', '--subdir', 'DAGS_FOLDER/4_4_house_assignment.py', '--cfg-path', '/tmp/tmp9w55wf3i']
[2025-03-12T14:50:39.677+0000] {standard_task_runner.py:88} INFO - Job 22: Subtask upload_to_clickhouse
[2025-03-12T14:50:39.723+0000] {task_command.py:423} INFO - Running <TaskInstance: 4_4_house_assignment.upload_to_clickhouse scheduled__2024-01-02T00:00:00+00:00 [running]> on host 13d00b3af9e0
[2025-03-12T14:50:39.772+0000] {taskinstance.py:2480} INFO - Exporting env vars: AIRFLOW_CTX_DAG_OWNER='airflow' AIRFLOW_CTX_DAG_ID='4_4_house_assignment' AIRFLOW_CTX_TASK_ID='upload_to_clickhouse' AIRFLOW_CTX_EXECUTION_DATE='2024-01-02T00:00:00+00:00' AIRFLOW_CTX_TRY_NUMBER='1' AIRFLOW_CTX_DAG_RUN_ID='scheduled__2024-01-02T00:00:00+00:00'
[2025-03-12T14:50:39.783+0000] {connection.py:411} WARNING - Failed to connect to localhost:9000
Traceback (most recent call last):
  File "/home/airflow/.local/lib/python3.9/site-packages/clickhouse_driver/connection.py", line 399, in connect
    return self._init_connection(host, port)
  File "/home/airflow/.local/lib/python3.9/site-packages/clickhouse_driver/connection.py", line 329, in _init_connection
    self.socket = self._create_socket(host, port)
  File "/home/airflow/.local/lib/python3.9/site-packages/clickhouse_driver/connection.py", line 301, in _create_socket
    raise err
  File "/home/airflow/.local/lib/python3.9/site-packages/clickhouse_driver/connection.py", line 292, in _create_socket
    sock.connect(sa)
ConnectionRefusedError: [Errno 111] Connection refused
[2025-03-12T14:50:39.784+0000] {taskinstance.py:2698} ERROR - Task failed with exception
Traceback (most recent call last):
  File "/home/airflow/.local/lib/python3.9/site-packages/airflow/models/taskinstance.py", line 433, in _execute_task
    result = execute_callable(context=context, **execute_callable_kwargs)
  File "/home/airflow/.local/lib/python3.9/site-packages/airflow/operators/python.py", line 199, in execute
    return_value = self.execute_callable()
  File "/home/airflow/.local/lib/python3.9/site-packages/airflow/operators/python.py", line 216, in execute_callable
    return self.python_callable(*self.op_args, **self.op_kwargs)
  File "/opt/airflow/dags/4_4_house_assignment.py", line 74, in upload_to_clickhouse
    client.execute(f'CREATE TABLE IF NOT EXISTS {table_name} (num_code Int64, char_code String, nominal Int64, name String, value String, date String) ENGINE Log')
  File "/home/airflow/.local/lib/python3.9/site-packages/clickhouse_driver/client.py", line 370, in execute
    with self.disconnect_on_error(query, settings):
  File "/usr/local/lib/python3.9/contextlib.py", line 119, in __enter__
    return next(self.gen)
  File "/home/airflow/.local/lib/python3.9/site-packages/clickhouse_driver/client.py", line 313, in disconnect_on_error
    self.establish_connection(settings)
  File "/home/airflow/.local/lib/python3.9/site-packages/clickhouse_driver/client.py", line 300, in establish_connection
    self.connection.force_connect()
  File "/home/airflow/.local/lib/python3.9/site-packages/clickhouse_driver/connection.py", line 258, in force_connect
    self.connect()
  File "/home/airflow/.local/lib/python3.9/site-packages/clickhouse_driver/connection.py", line 420, in connect
    raise err
clickhouse_driver.errors.NetworkError: Code: 210. Connection refused (localhost:9000)
[2025-03-12T14:50:39.793+0000] {taskinstance.py:1138} INFO - Marking task as FAILED. dag_id=4_4_house_assignment, task_id=upload_to_clickhouse, execution_date=20240102T000000, start_date=20250312T145039, end_date=20250312T145039
[2025-03-12T14:50:39.802+0000] {standard_task_runner.py:107} ERROR - Failed to execute job 22 for task upload_to_clickhouse (Code: 210. Connection refused (localhost:9000); 2484)
[2025-03-12T14:50:39.847+0000] {local_task_job_runner.py:234} INFO - Task exited with return code 1
[2025-03-12T14:50:39.856+0000] {taskinstance.py:3280} INFO - 0 downstream tasks scheduled from follow-on schedule check
