[2025-03-12T14:27:35.460+0000] {taskinstance.py:1956} INFO - Dependencies all met for dep_context=non-requeueable deps ti=<TaskInstance: Telegram.always_fail_task manual__2025-03-12T14:27:31.176973+00:00 [queued]>
[2025-03-12T14:27:35.468+0000] {taskinstance.py:1956} INFO - Dependencies all met for dep_context=requeueable deps ti=<TaskInstance: Telegram.always_fail_task manual__2025-03-12T14:27:31.176973+00:00 [queued]>
[2025-03-12T14:27:35.468+0000] {taskinstance.py:2170} INFO - Starting attempt 1 of 1
[2025-03-12T14:27:35.489+0000] {taskinstance.py:2191} INFO - Executing <Task(PythonOperator): always_fail_task> on 2025-03-12 14:27:31.176973+00:00
[2025-03-12T14:27:35.496+0000] {standard_task_runner.py:60} INFO - Started process 1217 to run task
[2025-03-12T14:27:35.499+0000] {standard_task_runner.py:87} INFO - Running: ['airflow', 'tasks', 'run', 'Telegram', 'always_fail_task', 'manual__2025-03-12T14:27:31.176973+00:00', '--job-id', '4', '--raw', '--subdir', 'DAGS_FOLDER/5_1_house_assignment.py', '--cfg-path', '/tmp/tmp8h8sydms']
[2025-03-12T14:27:35.500+0000] {standard_task_runner.py:88} INFO - Job 4: Subtask always_fail_task
[2025-03-12T14:27:35.541+0000] {task_command.py:423} INFO - Running <TaskInstance: Telegram.always_fail_task manual__2025-03-12T14:27:31.176973+00:00 [running]> on host 13d00b3af9e0
[2025-03-12T14:27:35.599+0000] {taskinstance.py:2480} INFO - Exporting env vars: AIRFLOW_CTX_DAG_OWNER='airflow' AIRFLOW_CTX_DAG_ID='Telegram' AIRFLOW_CTX_TASK_ID='always_fail_task' AIRFLOW_CTX_EXECUTION_DATE='2025-03-12T14:27:31.176973+00:00' AIRFLOW_CTX_TRY_NUMBER='1' AIRFLOW_CTX_DAG_RUN_ID='manual__2025-03-12T14:27:31.176973+00:00'
[2025-03-12T14:27:35.604+0000] {taskinstance.py:2698} ERROR - Task failed with exception
Traceback (most recent call last):
  File "/home/airflow/.local/lib/python3.9/site-packages/airflow/models/taskinstance.py", line 433, in _execute_task
    result = execute_callable(context=context, **execute_callable_kwargs)
  File "/home/airflow/.local/lib/python3.9/site-packages/airflow/operators/python.py", line 199, in execute
    return_value = self.execute_callable()
  File "/home/airflow/.local/lib/python3.9/site-packages/airflow/operators/python.py", line 216, in execute_callable
    return self.python_callable(*self.op_args, **self.op_kwargs)
  File "/opt/airflow/dags/5_1_house_assignment.py", line 9, in raise_exc
    raise AirflowException("This task is designed to fail.")
airflow.exceptions.AirflowException: This task is designed to fail.
[2025-03-12T14:27:35.610+0000] {taskinstance.py:1138} INFO - Marking task as FAILED. dag_id=Telegram, task_id=always_fail_task, execution_date=20250312T142731, start_date=20250312T142735, end_date=20250312T142735
[2025-03-12T14:27:35.615+0000] {base.py:83} INFO - Using connection ID 'telegram_id' for task execution.
[2025-03-12T14:27:35.617+0000] {base.py:83} INFO - Using connection ID 'telegram_id' for task execution.
[2025-03-12T14:27:49.663+0000] {_client.py:1740} INFO - HTTP Request: POST https://api.telegram.org/bot7637994734:AAGvM2WRHeVQYm8VJwtx1lyk6bN6LERhzT0/sendMessage "HTTP/1.1 200 OK"
[2025-03-12T14:27:49.675+0000] {standard_task_runner.py:107} ERROR - Failed to execute job 4 for task always_fail_task (This task is designed to fail.; 1217)
[2025-03-12T14:27:49.693+0000] {local_task_job_runner.py:234} INFO - Task exited with return code 1
[2025-03-12T14:27:49.701+0000] {taskinstance.py:3280} INFO - 0 downstream tasks scheduled from follow-on schedule check
