[2025-02-27T09:51:06.221+0000] {taskinstance.py:1956} INFO - Dependencies all met for dep_context=non-requeueable deps ti=<TaskInstance: 3_4_2_homework_assignment.upload_to_clickhouse_task scheduled__2024-01-08T00:00:00+00:00 [queued]>
[2025-02-27T09:51:06.226+0000] {taskinstance.py:1956} INFO - Dependencies all met for dep_context=requeueable deps ti=<TaskInstance: 3_4_2_homework_assignment.upload_to_clickhouse_task scheduled__2024-01-08T00:00:00+00:00 [queued]>
[2025-02-27T09:51:06.226+0000] {taskinstance.py:2170} INFO - Starting attempt 1 of 1
[2025-02-27T09:51:06.238+0000] {taskinstance.py:2191} INFO - Executing <Task(PythonOperator): upload_to_clickhouse_task> on 2024-01-08 00:00:00+00:00
[2025-02-27T09:51:06.243+0000] {standard_task_runner.py:60} INFO - Started process 2485 to run task
[2025-02-27T09:51:06.245+0000] {standard_task_runner.py:87} INFO - Running: ['airflow', 'tasks', 'run', '3_4_2_homework_assignment', 'upload_to_clickhouse_task', 'scheduled__2024-01-08T00:00:00+00:00', '--job-id', '25', '--raw', '--subdir', 'DAGS_FOLDER/3_4_2_homework_assignment.py', '--cfg-path', '/tmp/tmp1sq2f7iu']
[2025-02-27T09:51:06.247+0000] {standard_task_runner.py:88} INFO - Job 25: Subtask upload_to_clickhouse_task
[2025-02-27T09:51:06.273+0000] {task_command.py:423} INFO - Running <TaskInstance: 3_4_2_homework_assignment.upload_to_clickhouse_task scheduled__2024-01-08T00:00:00+00:00 [running]> on host ea5964584459
[2025-02-27T09:51:06.324+0000] {taskinstance.py:2480} INFO - Exporting env vars: AIRFLOW_CTX_DAG_OWNER='airflow' AIRFLOW_CTX_DAG_ID='3_4_2_homework_assignment' AIRFLOW_CTX_TASK_ID='upload_to_clickhouse_task' AIRFLOW_CTX_EXECUTION_DATE='2024-01-08T00:00:00+00:00' AIRFLOW_CTX_TRY_NUMBER='1' AIRFLOW_CTX_DAG_RUN_ID='scheduled__2024-01-08T00:00:00+00:00'
[2025-02-27T09:51:06.326+0000] {taskinstance.py:2698} ERROR - Task failed with exception
Traceback (most recent call last):
  File "/home/airflow/.local/lib/python3.9/site-packages/airflow/models/taskinstance.py", line 433, in _execute_task
    result = execute_callable(context=context, **execute_callable_kwargs)
  File "/home/airflow/.local/lib/python3.9/site-packages/airflow/operators/python.py", line 199, in execute
    return_value = self.execute_callable()
  File "/home/airflow/.local/lib/python3.9/site-packages/airflow/operators/python.py", line 216, in execute_callable
    return self.python_callable(*self.op_args, **self.op_kwargs)
  File "/opt/airflow/dags/3_4_2_homework_assignment.py", line 92, in upload_to_clickhouse
    data_frame = pd.read_csv(csv_file)
  File "/home/airflow/.local/lib/python3.9/site-packages/pandas/io/parsers/readers.py", line 948, in read_csv
    return _read(filepath_or_buffer, kwds)
  File "/home/airflow/.local/lib/python3.9/site-packages/pandas/io/parsers/readers.py", line 611, in _read
    parser = TextFileReader(filepath_or_buffer, **kwds)
  File "/home/airflow/.local/lib/python3.9/site-packages/pandas/io/parsers/readers.py", line 1448, in __init__
    self._engine = self._make_engine(f, self.engine)
  File "/home/airflow/.local/lib/python3.9/site-packages/pandas/io/parsers/readers.py", line 1705, in _make_engine
    self.handles = get_handle(
  File "/home/airflow/.local/lib/python3.9/site-packages/pandas/io/common.py", line 863, in get_handle
    handle = open(
FileNotFoundError: [Errno 2] No such file or directory: 'extracted_data_csv.csv'
[2025-02-27T09:51:06.330+0000] {taskinstance.py:1138} INFO - Marking task as FAILED. dag_id=3_4_2_homework_assignment, task_id=upload_to_clickhouse_task, execution_date=20240108T000000, start_date=20250227T095106, end_date=20250227T095106
[2025-02-27T09:51:06.338+0000] {standard_task_runner.py:107} ERROR - Failed to execute job 25 for task upload_to_clickhouse_task ([Errno 2] No such file or directory: 'extracted_data_csv.csv'; 2485)
[2025-02-27T09:51:06.379+0000] {local_task_job_runner.py:234} INFO - Task exited with return code 1
[2025-02-27T09:51:06.388+0000] {taskinstance.py:3280} INFO - 0 downstream tasks scheduled from follow-on schedule check
[2025-02-27T09:55:26.326+0000] {taskinstance.py:1956} INFO - Dependencies all met for dep_context=non-requeueable deps ti=<TaskInstance: 3_4_2_homework_assignment.upload_to_clickhouse_task scheduled__2024-01-08T00:00:00+00:00 [queued]>
[2025-02-27T09:55:26.332+0000] {taskinstance.py:1956} INFO - Dependencies all met for dep_context=requeueable deps ti=<TaskInstance: 3_4_2_homework_assignment.upload_to_clickhouse_task scheduled__2024-01-08T00:00:00+00:00 [queued]>
[2025-02-27T09:55:26.333+0000] {taskinstance.py:2170} INFO - Starting attempt 1 of 1
[2025-02-27T09:55:26.347+0000] {taskinstance.py:2191} INFO - Executing <Task(PythonOperator): upload_to_clickhouse_task> on 2024-01-08 00:00:00+00:00
[2025-02-27T09:55:26.353+0000] {standard_task_runner.py:60} INFO - Started process 3065 to run task
[2025-02-27T09:55:26.356+0000] {standard_task_runner.py:87} INFO - Running: ['airflow', 'tasks', 'run', '3_4_2_homework_assignment', 'upload_to_clickhouse_task', 'scheduled__2024-01-08T00:00:00+00:00', '--job-id', '25', '--raw', '--subdir', 'DAGS_FOLDER/3_4_2_homework_assignment.py', '--cfg-path', '/tmp/tmpvhow3mpb']
[2025-02-27T09:55:26.357+0000] {standard_task_runner.py:88} INFO - Job 25: Subtask upload_to_clickhouse_task
[2025-02-27T09:55:26.389+0000] {task_command.py:423} INFO - Running <TaskInstance: 3_4_2_homework_assignment.upload_to_clickhouse_task scheduled__2024-01-08T00:00:00+00:00 [running]> on host ea5964584459
[2025-02-27T09:55:26.446+0000] {taskinstance.py:2480} INFO - Exporting env vars: AIRFLOW_CTX_DAG_OWNER='airflow' AIRFLOW_CTX_DAG_ID='3_4_2_homework_assignment' AIRFLOW_CTX_TASK_ID='upload_to_clickhouse_task' AIRFLOW_CTX_EXECUTION_DATE='2024-01-08T00:00:00+00:00' AIRFLOW_CTX_TRY_NUMBER='1' AIRFLOW_CTX_DAG_RUN_ID='scheduled__2024-01-08T00:00:00+00:00'
[2025-02-27T09:55:26.450+0000] {taskinstance.py:2698} ERROR - Task failed with exception
Traceback (most recent call last):
  File "/home/airflow/.local/lib/python3.9/site-packages/airflow/models/taskinstance.py", line 433, in _execute_task
    result = execute_callable(context=context, **execute_callable_kwargs)
  File "/home/airflow/.local/lib/python3.9/site-packages/airflow/operators/python.py", line 199, in execute
    return_value = self.execute_callable()
  File "/home/airflow/.local/lib/python3.9/site-packages/airflow/operators/python.py", line 216, in execute_callable
    return self.python_callable(*self.op_args, **self.op_kwargs)
  File "/opt/airflow/dags/3_4_2_homework_assignment.py", line 93, in upload_to_clickhouse
    data_frame = pd.read_csv(csv_file)
  File "/home/airflow/.local/lib/python3.9/site-packages/pandas/io/parsers/readers.py", line 948, in read_csv
    return _read(filepath_or_buffer, kwds)
  File "/home/airflow/.local/lib/python3.9/site-packages/pandas/io/parsers/readers.py", line 611, in _read
    parser = TextFileReader(filepath_or_buffer, **kwds)
  File "/home/airflow/.local/lib/python3.9/site-packages/pandas/io/parsers/readers.py", line 1448, in __init__
    self._engine = self._make_engine(f, self.engine)
  File "/home/airflow/.local/lib/python3.9/site-packages/pandas/io/parsers/readers.py", line 1705, in _make_engine
    self.handles = get_handle(
  File "/home/airflow/.local/lib/python3.9/site-packages/pandas/io/common.py", line 863, in get_handle
    handle = open(
FileNotFoundError: [Errno 2] No such file or directory: 'extracted_data_csv.csv'
[2025-02-27T09:55:26.455+0000] {taskinstance.py:1138} INFO - Marking task as FAILED. dag_id=3_4_2_homework_assignment, task_id=upload_to_clickhouse_task, execution_date=20240108T000000, start_date=20250227T095526, end_date=20250227T095526
[2025-02-27T09:55:26.470+0000] {standard_task_runner.py:107} ERROR - Failed to execute job 25 for task upload_to_clickhouse_task ([Errno 2] No such file or directory: 'extracted_data_csv.csv'; 3065)
[2025-02-27T09:55:26.489+0000] {local_task_job_runner.py:234} INFO - Task exited with return code 1
[2025-02-27T09:55:26.499+0000] {taskinstance.py:3280} INFO - 0 downstream tasks scheduled from follow-on schedule check
[2025-02-27T10:07:18.123+0000] {taskinstance.py:1956} INFO - Dependencies all met for dep_context=non-requeueable deps ti=<TaskInstance: 3_4_2_homework_assignment.upload_to_clickhouse_task scheduled__2024-01-08T00:00:00+00:00 [queued]>
[2025-02-27T10:07:18.128+0000] {taskinstance.py:1956} INFO - Dependencies all met for dep_context=requeueable deps ti=<TaskInstance: 3_4_2_homework_assignment.upload_to_clickhouse_task scheduled__2024-01-08T00:00:00+00:00 [queued]>
[2025-02-27T10:07:18.129+0000] {taskinstance.py:2170} INFO - Starting attempt 1 of 1
[2025-02-27T10:07:18.140+0000] {taskinstance.py:2191} INFO - Executing <Task(PythonOperator): upload_to_clickhouse_task> on 2024-01-08 00:00:00+00:00
[2025-02-27T10:07:18.144+0000] {standard_task_runner.py:60} INFO - Started process 3707 to run task
[2025-02-27T10:07:18.147+0000] {standard_task_runner.py:87} INFO - Running: ['airflow', 'tasks', 'run', '3_4_2_homework_assignment', 'upload_to_clickhouse_task', 'scheduled__2024-01-08T00:00:00+00:00', '--job-id', '25', '--raw', '--subdir', 'DAGS_FOLDER/3_4_2_homework_assignment.py', '--cfg-path', '/tmp/tmpitwjxtjh']
[2025-02-27T10:07:18.148+0000] {standard_task_runner.py:88} INFO - Job 25: Subtask upload_to_clickhouse_task
[2025-02-27T10:07:18.173+0000] {task_command.py:423} INFO - Running <TaskInstance: 3_4_2_homework_assignment.upload_to_clickhouse_task scheduled__2024-01-08T00:00:00+00:00 [running]> on host ea5964584459
[2025-02-27T10:07:18.214+0000] {taskinstance.py:2480} INFO - Exporting env vars: AIRFLOW_CTX_DAG_OWNER='airflow' AIRFLOW_CTX_DAG_ID='3_4_2_homework_assignment' AIRFLOW_CTX_TASK_ID='upload_to_clickhouse_task' AIRFLOW_CTX_EXECUTION_DATE='2024-01-08T00:00:00+00:00' AIRFLOW_CTX_TRY_NUMBER='1' AIRFLOW_CTX_DAG_RUN_ID='scheduled__2024-01-08T00:00:00+00:00'
[2025-02-27T10:07:18.217+0000] {taskinstance.py:2698} ERROR - Task failed with exception
Traceback (most recent call last):
  File "/home/airflow/.local/lib/python3.9/site-packages/airflow/models/taskinstance.py", line 433, in _execute_task
    result = execute_callable(context=context, **execute_callable_kwargs)
  File "/home/airflow/.local/lib/python3.9/site-packages/airflow/operators/python.py", line 199, in execute
    return_value = self.execute_callable()
  File "/home/airflow/.local/lib/python3.9/site-packages/airflow/operators/python.py", line 216, in execute_callable
    return self.python_callable(*self.op_args, **self.op_kwargs)
  File "/opt/airflow/dags/3_4_2_homework_assignment.py", line 87, in upload_to_clickhouse
    data_frame = pd.read_csv(csv_file)
  File "/home/airflow/.local/lib/python3.9/site-packages/pandas/io/parsers/readers.py", line 948, in read_csv
    return _read(filepath_or_buffer, kwds)
  File "/home/airflow/.local/lib/python3.9/site-packages/pandas/io/parsers/readers.py", line 611, in _read
    parser = TextFileReader(filepath_or_buffer, **kwds)
  File "/home/airflow/.local/lib/python3.9/site-packages/pandas/io/parsers/readers.py", line 1448, in __init__
    self._engine = self._make_engine(f, self.engine)
  File "/home/airflow/.local/lib/python3.9/site-packages/pandas/io/parsers/readers.py", line 1705, in _make_engine
    self.handles = get_handle(
  File "/home/airflow/.local/lib/python3.9/site-packages/pandas/io/common.py", line 863, in get_handle
    handle = open(
FileNotFoundError: [Errno 2] No such file or directory: 'extracted_data_csv.csv'
[2025-02-27T10:07:18.222+0000] {taskinstance.py:1138} INFO - Marking task as FAILED. dag_id=3_4_2_homework_assignment, task_id=upload_to_clickhouse_task, execution_date=20240108T000000, start_date=20250227T100718, end_date=20250227T100718
[2025-02-27T10:07:18.230+0000] {standard_task_runner.py:107} ERROR - Failed to execute job 25 for task upload_to_clickhouse_task ([Errno 2] No such file or directory: 'extracted_data_csv.csv'; 3707)
[2025-02-27T10:07:18.240+0000] {local_task_job_runner.py:234} INFO - Task exited with return code 1
[2025-02-27T10:07:18.249+0000] {taskinstance.py:3280} INFO - 0 downstream tasks scheduled from follow-on schedule check
[2025-02-27T10:14:55.368+0000] {taskinstance.py:1956} INFO - Dependencies all met for dep_context=non-requeueable deps ti=<TaskInstance: 3_4_2_homework_assignment.upload_to_clickhouse_task scheduled__2024-01-08T00:00:00+00:00 [queued]>
[2025-02-27T10:14:55.373+0000] {taskinstance.py:1956} INFO - Dependencies all met for dep_context=requeueable deps ti=<TaskInstance: 3_4_2_homework_assignment.upload_to_clickhouse_task scheduled__2024-01-08T00:00:00+00:00 [queued]>
[2025-02-27T10:14:55.374+0000] {taskinstance.py:2170} INFO - Starting attempt 1 of 1
[2025-02-27T10:14:55.384+0000] {taskinstance.py:2191} INFO - Executing <Task(PythonOperator): upload_to_clickhouse_task> on 2024-01-08 00:00:00+00:00
[2025-02-27T10:14:55.388+0000] {standard_task_runner.py:60} INFO - Started process 4602 to run task
[2025-02-27T10:14:55.391+0000] {standard_task_runner.py:87} INFO - Running: ['airflow', 'tasks', 'run', '3_4_2_homework_assignment', 'upload_to_clickhouse_task', 'scheduled__2024-01-08T00:00:00+00:00', '--job-id', '25', '--raw', '--subdir', 'DAGS_FOLDER/3_4_2_homework_assignment.py', '--cfg-path', '/tmp/tmpll8fssz9']
[2025-02-27T10:14:55.392+0000] {standard_task_runner.py:88} INFO - Job 25: Subtask upload_to_clickhouse_task
[2025-02-27T10:14:55.417+0000] {task_command.py:423} INFO - Running <TaskInstance: 3_4_2_homework_assignment.upload_to_clickhouse_task scheduled__2024-01-08T00:00:00+00:00 [running]> on host ea5964584459
[2025-02-27T10:14:55.458+0000] {taskinstance.py:2480} INFO - Exporting env vars: AIRFLOW_CTX_DAG_OWNER='airflow' AIRFLOW_CTX_DAG_ID='3_4_2_homework_assignment' AIRFLOW_CTX_TASK_ID='upload_to_clickhouse_task' AIRFLOW_CTX_EXECUTION_DATE='2024-01-08T00:00:00+00:00' AIRFLOW_CTX_TRY_NUMBER='1' AIRFLOW_CTX_DAG_RUN_ID='scheduled__2024-01-08T00:00:00+00:00'
[2025-02-27T10:14:55.463+0000] {connection.py:411} WARNING - Failed to connect to None:9000
Traceback (most recent call last):
  File "/home/airflow/.local/lib/python3.9/site-packages/clickhouse_driver/connection.py", line 399, in connect
    return self._init_connection(host, port)
  File "/home/airflow/.local/lib/python3.9/site-packages/clickhouse_driver/connection.py", line 329, in _init_connection
    self.socket = self._create_socket(host, port)
  File "/home/airflow/.local/lib/python3.9/site-packages/clickhouse_driver/connection.py", line 301, in _create_socket
    raise err
  File "/home/airflow/.local/lib/python3.9/site-packages/clickhouse_driver/connection.py", line 292, in _create_socket
    sock.connect(sa)
ConnectionRefusedError: [Errno 111] Connection refused
[2025-02-27T10:14:55.464+0000] {taskinstance.py:2698} ERROR - Task failed with exception
Traceback (most recent call last):
  File "/home/airflow/.local/lib/python3.9/site-packages/airflow/models/taskinstance.py", line 433, in _execute_task
    result = execute_callable(context=context, **execute_callable_kwargs)
  File "/home/airflow/.local/lib/python3.9/site-packages/airflow/operators/python.py", line 199, in execute
    return_value = self.execute_callable()
  File "/home/airflow/.local/lib/python3.9/site-packages/airflow/operators/python.py", line 216, in execute_callable
    return self.python_callable(*self.op_args, **self.op_kwargs)
  File "/opt/airflow/dags/3_4_2_homework_assignment.py", line 90, in upload_to_clickhouse
    client.execute(f'CREATE TABLE IF NOT EXISTS {table_name} (source String, currency String, value Float, date String) ENGINE Log')
  File "/home/airflow/.local/lib/python3.9/site-packages/clickhouse_driver/client.py", line 370, in execute
    with self.disconnect_on_error(query, settings):
  File "/usr/local/lib/python3.9/contextlib.py", line 119, in __enter__
    return next(self.gen)
  File "/home/airflow/.local/lib/python3.9/site-packages/clickhouse_driver/client.py", line 313, in disconnect_on_error
    self.establish_connection(settings)
  File "/home/airflow/.local/lib/python3.9/site-packages/clickhouse_driver/client.py", line 300, in establish_connection
    self.connection.force_connect()
  File "/home/airflow/.local/lib/python3.9/site-packages/clickhouse_driver/connection.py", line 258, in force_connect
    self.connect()
  File "/home/airflow/.local/lib/python3.9/site-packages/clickhouse_driver/connection.py", line 420, in connect
    raise err
clickhouse_driver.errors.NetworkError: Code: 210. Connection refused (None:9000)
[2025-02-27T10:14:55.469+0000] {taskinstance.py:1138} INFO - Marking task as FAILED. dag_id=3_4_2_homework_assignment, task_id=upload_to_clickhouse_task, execution_date=20240108T000000, start_date=20250227T101455, end_date=20250227T101455
[2025-02-27T10:14:55.478+0000] {standard_task_runner.py:107} ERROR - Failed to execute job 25 for task upload_to_clickhouse_task (Code: 210. Connection refused (None:9000); 4602)
[2025-02-27T10:14:55.524+0000] {local_task_job_runner.py:234} INFO - Task exited with return code 1
[2025-02-27T10:14:55.533+0000] {taskinstance.py:3280} INFO - 0 downstream tasks scheduled from follow-on schedule check
[2025-02-27T10:27:35.945+0000] {taskinstance.py:1956} INFO - Dependencies all met for dep_context=non-requeueable deps ti=<TaskInstance: 3_4_2_homework_assignment.upload_to_clickhouse_task scheduled__2024-01-08T00:00:00+00:00 [queued]>
[2025-02-27T10:27:35.951+0000] {taskinstance.py:1956} INFO - Dependencies all met for dep_context=requeueable deps ti=<TaskInstance: 3_4_2_homework_assignment.upload_to_clickhouse_task scheduled__2024-01-08T00:00:00+00:00 [queued]>
[2025-02-27T10:27:35.952+0000] {taskinstance.py:2170} INFO - Starting attempt 1 of 1
[2025-02-27T10:27:35.964+0000] {taskinstance.py:2191} INFO - Executing <Task(PythonOperator): upload_to_clickhouse_task> on 2024-01-08 00:00:00+00:00
[2025-02-27T10:27:35.970+0000] {standard_task_runner.py:60} INFO - Started process 5937 to run task
[2025-02-27T10:27:35.972+0000] {standard_task_runner.py:87} INFO - Running: ['airflow', 'tasks', 'run', '3_4_2_homework_assignment', 'upload_to_clickhouse_task', 'scheduled__2024-01-08T00:00:00+00:00', '--job-id', '25', '--raw', '--subdir', 'DAGS_FOLDER/3_4_2_homework_assignment.py', '--cfg-path', '/tmp/tmpe8o6vh6_']
[2025-02-27T10:27:35.973+0000] {standard_task_runner.py:88} INFO - Job 25: Subtask upload_to_clickhouse_task
[2025-02-27T10:27:36.002+0000] {task_command.py:423} INFO - Running <TaskInstance: 3_4_2_homework_assignment.upload_to_clickhouse_task scheduled__2024-01-08T00:00:00+00:00 [running]> on host ea5964584459
[2025-02-27T10:27:36.045+0000] {taskinstance.py:2480} INFO - Exporting env vars: AIRFLOW_CTX_DAG_OWNER='airflow' AIRFLOW_CTX_DAG_ID='3_4_2_homework_assignment' AIRFLOW_CTX_TASK_ID='upload_to_clickhouse_task' AIRFLOW_CTX_EXECUTION_DATE='2024-01-08T00:00:00+00:00' AIRFLOW_CTX_TRY_NUMBER='1' AIRFLOW_CTX_DAG_RUN_ID='scheduled__2024-01-08T00:00:00+00:00'
[2025-02-27T10:27:36.057+0000] {taskinstance.py:2698} ERROR - Task failed with exception
Traceback (most recent call last):
  File "/home/airflow/.local/lib/python3.9/site-packages/airflow/models/taskinstance.py", line 433, in _execute_task
    result = execute_callable(context=context, **execute_callable_kwargs)
  File "/home/airflow/.local/lib/python3.9/site-packages/airflow/operators/python.py", line 199, in execute
    return_value = self.execute_callable()
  File "/home/airflow/.local/lib/python3.9/site-packages/airflow/operators/python.py", line 216, in execute_callable
    return self.python_callable(*self.op_args, **self.op_kwargs)
  File "/opt/airflow/dags/3_4_2_homework_assignment.py", line 92, in upload_to_clickhouse
    client.execute(f'INSERT INTO {table_name} VALUES', data_frame.to_dict('records'))
  File "/home/airflow/.local/lib/python3.9/site-packages/clickhouse_driver/client.py", line 376, in execute
    rv = self.process_insert_query(
  File "/home/airflow/.local/lib/python3.9/site-packages/clickhouse_driver/client.py", line 607, in process_insert_query
    rv = self.send_data(sample_block, data,
  File "/home/airflow/.local/lib/python3.9/site-packages/clickhouse_driver/client.py", line 658, in send_data
    block = block_cls(sample_block.columns_with_types, chunk,
  File "/home/airflow/.local/lib/python3.9/site-packages/clickhouse_driver/block.py", line 40, in __init__
    self.data = self.normalize(data or [])
  File "/home/airflow/.local/lib/python3.9/site-packages/clickhouse_driver/block.py", line 128, in normalize
    self._mutate_dicts_to_rows(data)
  File "/home/airflow/.local/lib/python3.9/site-packages/clickhouse_driver/block.py", line 159, in _mutate_dicts_to_rows
    return self._pure_mutate_dicts_to_rows(
  File "/home/airflow/.local/lib/python3.9/site-packages/clickhouse_driver/block.py", line 186, in _pure_mutate_dicts_to_rows
    new_data.append(row[name])
KeyError: 'source'
[2025-02-27T10:27:36.064+0000] {taskinstance.py:1138} INFO - Marking task as FAILED. dag_id=3_4_2_homework_assignment, task_id=upload_to_clickhouse_task, execution_date=20240108T000000, start_date=20250227T102735, end_date=20250227T102736
[2025-02-27T10:27:36.073+0000] {standard_task_runner.py:107} ERROR - Failed to execute job 25 for task upload_to_clickhouse_task ('source'; 5937)
[2025-02-27T10:27:36.106+0000] {local_task_job_runner.py:234} INFO - Task exited with return code 1
[2025-02-27T10:27:36.115+0000] {taskinstance.py:3280} INFO - 0 downstream tasks scheduled from follow-on schedule check
[2025-02-27T10:35:57.224+0000] {taskinstance.py:1956} INFO - Dependencies all met for dep_context=non-requeueable deps ti=<TaskInstance: 3_4_2_homework_assignment.upload_to_clickhouse_task scheduled__2024-01-08T00:00:00+00:00 [queued]>
[2025-02-27T10:35:57.230+0000] {taskinstance.py:1956} INFO - Dependencies all met for dep_context=requeueable deps ti=<TaskInstance: 3_4_2_homework_assignment.upload_to_clickhouse_task scheduled__2024-01-08T00:00:00+00:00 [queued]>
[2025-02-27T10:35:57.230+0000] {taskinstance.py:2170} INFO - Starting attempt 1 of 1
[2025-02-27T10:35:57.242+0000] {taskinstance.py:2191} INFO - Executing <Task(PythonOperator): upload_to_clickhouse_task> on 2024-01-08 00:00:00+00:00
[2025-02-27T10:35:57.248+0000] {standard_task_runner.py:60} INFO - Started process 6597 to run task
[2025-02-27T10:35:57.250+0000] {standard_task_runner.py:87} INFO - Running: ['airflow', 'tasks', 'run', '3_4_2_homework_assignment', 'upload_to_clickhouse_task', 'scheduled__2024-01-08T00:00:00+00:00', '--job-id', '25', '--raw', '--subdir', 'DAGS_FOLDER/3_4_2_homework_assignment.py', '--cfg-path', '/tmp/tmpucollw4z']
[2025-02-27T10:35:57.251+0000] {standard_task_runner.py:88} INFO - Job 25: Subtask upload_to_clickhouse_task
[2025-02-27T10:35:57.279+0000] {task_command.py:423} INFO - Running <TaskInstance: 3_4_2_homework_assignment.upload_to_clickhouse_task scheduled__2024-01-08T00:00:00+00:00 [running]> on host ea5964584459
[2025-02-27T10:35:57.321+0000] {taskinstance.py:2480} INFO - Exporting env vars: AIRFLOW_CTX_DAG_OWNER='airflow' AIRFLOW_CTX_DAG_ID='3_4_2_homework_assignment' AIRFLOW_CTX_TASK_ID='upload_to_clickhouse_task' AIRFLOW_CTX_EXECUTION_DATE='2024-01-08T00:00:00+00:00' AIRFLOW_CTX_TRY_NUMBER='1' AIRFLOW_CTX_DAG_RUN_ID='scheduled__2024-01-08T00:00:00+00:00'
[2025-02-27T10:35:57.335+0000] {taskinstance.py:2698} ERROR - Task failed with exception
Traceback (most recent call last):
  File "/home/airflow/.local/lib/python3.9/site-packages/airflow/models/taskinstance.py", line 433, in _execute_task
    result = execute_callable(context=context, **execute_callable_kwargs)
  File "/home/airflow/.local/lib/python3.9/site-packages/airflow/operators/python.py", line 199, in execute
    return_value = self.execute_callable()
  File "/home/airflow/.local/lib/python3.9/site-packages/airflow/operators/python.py", line 216, in execute_callable
    return self.python_callable(*self.op_args, **self.op_kwargs)
  File "/opt/airflow/dags/3_4_2_homework_assignment.py", line 93, in upload_to_clickhouse
    client.execute(f'INSERT INTO {table_name} VALUES', data_frame.to_dict('records'))
  File "/home/airflow/.local/lib/python3.9/site-packages/clickhouse_driver/client.py", line 376, in execute
    rv = self.process_insert_query(
  File "/home/airflow/.local/lib/python3.9/site-packages/clickhouse_driver/client.py", line 607, in process_insert_query
    rv = self.send_data(sample_block, data,
  File "/home/airflow/.local/lib/python3.9/site-packages/clickhouse_driver/client.py", line 658, in send_data
    block = block_cls(sample_block.columns_with_types, chunk,
  File "/home/airflow/.local/lib/python3.9/site-packages/clickhouse_driver/block.py", line 40, in __init__
    self.data = self.normalize(data or [])
  File "/home/airflow/.local/lib/python3.9/site-packages/clickhouse_driver/block.py", line 128, in normalize
    self._mutate_dicts_to_rows(data)
  File "/home/airflow/.local/lib/python3.9/site-packages/clickhouse_driver/block.py", line 159, in _mutate_dicts_to_rows
    return self._pure_mutate_dicts_to_rows(
  File "/home/airflow/.local/lib/python3.9/site-packages/clickhouse_driver/block.py", line 186, in _pure_mutate_dicts_to_rows
    new_data.append(row[name])
KeyError: 'source'
[2025-02-27T10:35:57.341+0000] {taskinstance.py:1138} INFO - Marking task as FAILED. dag_id=3_4_2_homework_assignment, task_id=upload_to_clickhouse_task, execution_date=20240108T000000, start_date=20250227T103557, end_date=20250227T103557
[2025-02-27T10:35:57.350+0000] {standard_task_runner.py:107} ERROR - Failed to execute job 25 for task upload_to_clickhouse_task ('source'; 6597)
[2025-02-27T10:35:57.384+0000] {local_task_job_runner.py:234} INFO - Task exited with return code 1
[2025-02-27T10:35:57.394+0000] {taskinstance.py:3280} INFO - 0 downstream tasks scheduled from follow-on schedule check
[2025-02-27T10:45:49.406+0000] {taskinstance.py:1956} INFO - Dependencies all met for dep_context=non-requeueable deps ti=<TaskInstance: 3_4_2_homework_assignment.upload_to_clickhouse_task scheduled__2024-01-08T00:00:00+00:00 [queued]>
[2025-02-27T10:45:49.412+0000] {taskinstance.py:1956} INFO - Dependencies all met for dep_context=requeueable deps ti=<TaskInstance: 3_4_2_homework_assignment.upload_to_clickhouse_task scheduled__2024-01-08T00:00:00+00:00 [queued]>
[2025-02-27T10:45:49.412+0000] {taskinstance.py:2170} INFO - Starting attempt 1 of 1
[2025-02-27T10:45:49.422+0000] {taskinstance.py:2191} INFO - Executing <Task(PythonOperator): upload_to_clickhouse_task> on 2024-01-08 00:00:00+00:00
[2025-02-27T10:45:49.427+0000] {standard_task_runner.py:60} INFO - Started process 7282 to run task
[2025-02-27T10:45:49.429+0000] {standard_task_runner.py:87} INFO - Running: ['airflow', 'tasks', 'run', '3_4_2_homework_assignment', 'upload_to_clickhouse_task', 'scheduled__2024-01-08T00:00:00+00:00', '--job-id', '25', '--raw', '--subdir', 'DAGS_FOLDER/3_4_2_homework_assignment.py', '--cfg-path', '/tmp/tmpj97rbnqt']
[2025-02-27T10:45:49.430+0000] {standard_task_runner.py:88} INFO - Job 25: Subtask upload_to_clickhouse_task
[2025-02-27T10:45:49.456+0000] {task_command.py:423} INFO - Running <TaskInstance: 3_4_2_homework_assignment.upload_to_clickhouse_task scheduled__2024-01-08T00:00:00+00:00 [running]> on host ea5964584459
[2025-02-27T10:45:49.506+0000] {taskinstance.py:2480} INFO - Exporting env vars: AIRFLOW_CTX_DAG_OWNER='airflow' AIRFLOW_CTX_DAG_ID='3_4_2_homework_assignment' AIRFLOW_CTX_TASK_ID='upload_to_clickhouse_task' AIRFLOW_CTX_EXECUTION_DATE='2024-01-08T00:00:00+00:00' AIRFLOW_CTX_TRY_NUMBER='1' AIRFLOW_CTX_DAG_RUN_ID='scheduled__2024-01-08T00:00:00+00:00'
[2025-02-27T10:45:49.521+0000] {unix.py:142} WARNING - /etc/timezone is deprecated on Debian, and no longer reliable. Ignoring.
[2025-02-27T10:45:49.524+0000] {python.py:201} INFO - Done. Returned value was: None
[2025-02-27T10:45:49.528+0000] {taskinstance.py:1138} INFO - Marking task as SUCCESS. dag_id=3_4_2_homework_assignment, task_id=upload_to_clickhouse_task, execution_date=20240108T000000, start_date=20250227T104549, end_date=20250227T104549
[2025-02-27T10:45:49.564+0000] {local_task_job_runner.py:234} INFO - Task exited with return code 0
[2025-02-27T10:45:49.573+0000] {taskinstance.py:3280} INFO - 0 downstream tasks scheduled from follow-on schedule check
