[2025-02-27T09:48:08.498+0000] {taskinstance.py:1956} INFO - Dependencies all met for dep_context=non-requeueable deps ti=<TaskInstance: 3_4_2_homework_assignment.upload_to_clickhouse_task scheduled__2024-01-02T00:00:00+00:00 [queued]>
[2025-02-27T09:48:08.503+0000] {taskinstance.py:1956} INFO - Dependencies all met for dep_context=requeueable deps ti=<TaskInstance: 3_4_2_homework_assignment.upload_to_clickhouse_task scheduled__2024-01-02T00:00:00+00:00 [queued]>
[2025-02-27T09:48:08.503+0000] {taskinstance.py:2170} INFO - Starting attempt 1 of 1
[2025-02-27T09:48:08.516+0000] {taskinstance.py:2191} INFO - Executing <Task(PythonOperator): upload_to_clickhouse_task> on 2024-01-02 00:00:00+00:00
[2025-02-27T09:48:08.522+0000] {standard_task_runner.py:60} INFO - Started process 1919 to run task
[2025-02-27T09:48:08.525+0000] {standard_task_runner.py:87} INFO - Running: ['airflow', 'tasks', 'run', '3_4_2_homework_assignment', 'upload_to_clickhouse_task', 'scheduled__2024-01-02T00:00:00+00:00', '--job-id', '5', '--raw', '--subdir', 'DAGS_FOLDER/3_4_2_homework_assignment.py', '--cfg-path', '/tmp/tmpu3cglm33']
[2025-02-27T09:48:08.526+0000] {standard_task_runner.py:88} INFO - Job 5: Subtask upload_to_clickhouse_task
[2025-02-27T09:48:08.551+0000] {task_command.py:423} INFO - Running <TaskInstance: 3_4_2_homework_assignment.upload_to_clickhouse_task scheduled__2024-01-02T00:00:00+00:00 [running]> on host ea5964584459
[2025-02-27T09:48:08.591+0000] {taskinstance.py:2480} INFO - Exporting env vars: AIRFLOW_CTX_DAG_OWNER='airflow' AIRFLOW_CTX_DAG_ID='3_4_2_homework_assignment' AIRFLOW_CTX_TASK_ID='upload_to_clickhouse_task' AIRFLOW_CTX_EXECUTION_DATE='2024-01-02T00:00:00+00:00' AIRFLOW_CTX_TRY_NUMBER='1' AIRFLOW_CTX_DAG_RUN_ID='scheduled__2024-01-02T00:00:00+00:00'
[2025-02-27T09:48:08.593+0000] {taskinstance.py:2698} ERROR - Task failed with exception
Traceback (most recent call last):
  File "/home/airflow/.local/lib/python3.9/site-packages/airflow/models/taskinstance.py", line 433, in _execute_task
    result = execute_callable(context=context, **execute_callable_kwargs)
  File "/home/airflow/.local/lib/python3.9/site-packages/airflow/operators/python.py", line 199, in execute
    return_value = self.execute_callable()
  File "/home/airflow/.local/lib/python3.9/site-packages/airflow/operators/python.py", line 216, in execute_callable
    return self.python_callable(*self.op_args, **self.op_kwargs)
  File "/opt/airflow/dags/3_4_2_homework_assignment.py", line 86, in upload_to_clickhouse
    data_frame = pd.read_csv(csv_file)
  File "/home/airflow/.local/lib/python3.9/site-packages/pandas/io/parsers/readers.py", line 948, in read_csv
    return _read(filepath_or_buffer, kwds)
  File "/home/airflow/.local/lib/python3.9/site-packages/pandas/io/parsers/readers.py", line 611, in _read
    parser = TextFileReader(filepath_or_buffer, **kwds)
  File "/home/airflow/.local/lib/python3.9/site-packages/pandas/io/parsers/readers.py", line 1448, in __init__
    self._engine = self._make_engine(f, self.engine)
  File "/home/airflow/.local/lib/python3.9/site-packages/pandas/io/parsers/readers.py", line 1705, in _make_engine
    self.handles = get_handle(
  File "/home/airflow/.local/lib/python3.9/site-packages/pandas/io/common.py", line 863, in get_handle
    handle = open(
FileNotFoundError: [Errno 2] No such file or directory: 'extracted_data_csv.csv'
[2025-02-27T09:48:08.598+0000] {taskinstance.py:1138} INFO - Marking task as FAILED. dag_id=3_4_2_homework_assignment, task_id=upload_to_clickhouse_task, execution_date=20240102T000000, start_date=20250227T094808, end_date=20250227T094808
[2025-02-27T09:48:08.606+0000] {standard_task_runner.py:107} ERROR - Failed to execute job 5 for task upload_to_clickhouse_task ([Errno 2] No such file or directory: 'extracted_data_csv.csv'; 1919)
[2025-02-27T09:48:08.618+0000] {local_task_job_runner.py:234} INFO - Task exited with return code 1
[2025-02-27T09:48:08.627+0000] {taskinstance.py:3280} INFO - 0 downstream tasks scheduled from follow-on schedule check
[2025-02-27T09:50:02.512+0000] {taskinstance.py:1956} INFO - Dependencies all met for dep_context=non-requeueable deps ti=<TaskInstance: 3_4_2_homework_assignment.upload_to_clickhouse_task scheduled__2024-01-02T00:00:00+00:00 [queued]>
[2025-02-27T09:50:02.518+0000] {taskinstance.py:1956} INFO - Dependencies all met for dep_context=requeueable deps ti=<TaskInstance: 3_4_2_homework_assignment.upload_to_clickhouse_task scheduled__2024-01-02T00:00:00+00:00 [queued]>
[2025-02-27T09:50:02.518+0000] {taskinstance.py:2170} INFO - Starting attempt 1 of 1
[2025-02-27T09:50:02.529+0000] {taskinstance.py:2191} INFO - Executing <Task(PythonOperator): upload_to_clickhouse_task> on 2024-01-02 00:00:00+00:00
[2025-02-27T09:50:02.535+0000] {standard_task_runner.py:60} INFO - Started process 2153 to run task
[2025-02-27T09:50:02.537+0000] {standard_task_runner.py:87} INFO - Running: ['airflow', 'tasks', 'run', '3_4_2_homework_assignment', 'upload_to_clickhouse_task', 'scheduled__2024-01-02T00:00:00+00:00', '--job-id', '7', '--raw', '--subdir', 'DAGS_FOLDER/3_4_2_homework_assignment.py', '--cfg-path', '/tmp/tmpmkqozspm']
[2025-02-27T09:50:02.538+0000] {standard_task_runner.py:88} INFO - Job 7: Subtask upload_to_clickhouse_task
[2025-02-27T09:50:02.567+0000] {task_command.py:423} INFO - Running <TaskInstance: 3_4_2_homework_assignment.upload_to_clickhouse_task scheduled__2024-01-02T00:00:00+00:00 [running]> on host ea5964584459
[2025-02-27T09:50:02.610+0000] {taskinstance.py:2480} INFO - Exporting env vars: AIRFLOW_CTX_DAG_OWNER='airflow' AIRFLOW_CTX_DAG_ID='3_4_2_homework_assignment' AIRFLOW_CTX_TASK_ID='upload_to_clickhouse_task' AIRFLOW_CTX_EXECUTION_DATE='2024-01-02T00:00:00+00:00' AIRFLOW_CTX_TRY_NUMBER='1' AIRFLOW_CTX_DAG_RUN_ID='scheduled__2024-01-02T00:00:00+00:00'
[2025-02-27T09:50:02.612+0000] {taskinstance.py:2698} ERROR - Task failed with exception
Traceback (most recent call last):
  File "/home/airflow/.local/lib/python3.9/site-packages/airflow/models/taskinstance.py", line 433, in _execute_task
    result = execute_callable(context=context, **execute_callable_kwargs)
  File "/home/airflow/.local/lib/python3.9/site-packages/airflow/operators/python.py", line 199, in execute
    return_value = self.execute_callable()
  File "/home/airflow/.local/lib/python3.9/site-packages/airflow/operators/python.py", line 216, in execute_callable
    return self.python_callable(*self.op_args, **self.op_kwargs)
  File "/opt/airflow/dags/3_4_2_homework_assignment.py", line 92, in upload_to_clickhouse
    data_frame = pd.read_csv(csv_file)
  File "/home/airflow/.local/lib/python3.9/site-packages/pandas/io/parsers/readers.py", line 948, in read_csv
    return _read(filepath_or_buffer, kwds)
  File "/home/airflow/.local/lib/python3.9/site-packages/pandas/io/parsers/readers.py", line 611, in _read
    parser = TextFileReader(filepath_or_buffer, **kwds)
  File "/home/airflow/.local/lib/python3.9/site-packages/pandas/io/parsers/readers.py", line 1448, in __init__
    self._engine = self._make_engine(f, self.engine)
  File "/home/airflow/.local/lib/python3.9/site-packages/pandas/io/parsers/readers.py", line 1705, in _make_engine
    self.handles = get_handle(
  File "/home/airflow/.local/lib/python3.9/site-packages/pandas/io/common.py", line 863, in get_handle
    handle = open(
FileNotFoundError: [Errno 2] No such file or directory: 'extracted_data_csv.csv'
[2025-02-27T09:50:02.617+0000] {taskinstance.py:1138} INFO - Marking task as FAILED. dag_id=3_4_2_homework_assignment, task_id=upload_to_clickhouse_task, execution_date=20240102T000000, start_date=20250227T095002, end_date=20250227T095002
[2025-02-27T09:50:02.626+0000] {standard_task_runner.py:107} ERROR - Failed to execute job 7 for task upload_to_clickhouse_task ([Errno 2] No such file or directory: 'extracted_data_csv.csv'; 2153)
[2025-02-27T09:50:02.670+0000] {local_task_job_runner.py:234} INFO - Task exited with return code 1
[2025-02-27T09:50:02.680+0000] {taskinstance.py:3280} INFO - 0 downstream tasks scheduled from follow-on schedule check
[2025-02-27T09:54:17.642+0000] {taskinstance.py:1956} INFO - Dependencies all met for dep_context=non-requeueable deps ti=<TaskInstance: 3_4_2_homework_assignment.upload_to_clickhouse_task scheduled__2024-01-02T00:00:00+00:00 [queued]>
[2025-02-27T09:54:17.647+0000] {taskinstance.py:1956} INFO - Dependencies all met for dep_context=requeueable deps ti=<TaskInstance: 3_4_2_homework_assignment.upload_to_clickhouse_task scheduled__2024-01-02T00:00:00+00:00 [queued]>
[2025-02-27T09:54:17.648+0000] {taskinstance.py:2170} INFO - Starting attempt 1 of 1
[2025-02-27T09:54:17.658+0000] {taskinstance.py:2191} INFO - Executing <Task(PythonOperator): upload_to_clickhouse_task> on 2024-01-02 00:00:00+00:00
[2025-02-27T09:54:17.663+0000] {standard_task_runner.py:60} INFO - Started process 2733 to run task
[2025-02-27T09:54:17.665+0000] {standard_task_runner.py:87} INFO - Running: ['airflow', 'tasks', 'run', '3_4_2_homework_assignment', 'upload_to_clickhouse_task', 'scheduled__2024-01-02T00:00:00+00:00', '--job-id', '7', '--raw', '--subdir', 'DAGS_FOLDER/3_4_2_homework_assignment.py', '--cfg-path', '/tmp/tmpek_vf1r5']
[2025-02-27T09:54:17.666+0000] {standard_task_runner.py:88} INFO - Job 7: Subtask upload_to_clickhouse_task
[2025-02-27T09:54:17.694+0000] {task_command.py:423} INFO - Running <TaskInstance: 3_4_2_homework_assignment.upload_to_clickhouse_task scheduled__2024-01-02T00:00:00+00:00 [running]> on host ea5964584459
[2025-02-27T09:54:17.733+0000] {taskinstance.py:2480} INFO - Exporting env vars: AIRFLOW_CTX_DAG_OWNER='airflow' AIRFLOW_CTX_DAG_ID='3_4_2_homework_assignment' AIRFLOW_CTX_TASK_ID='upload_to_clickhouse_task' AIRFLOW_CTX_EXECUTION_DATE='2024-01-02T00:00:00+00:00' AIRFLOW_CTX_TRY_NUMBER='1' AIRFLOW_CTX_DAG_RUN_ID='scheduled__2024-01-02T00:00:00+00:00'
[2025-02-27T09:54:17.735+0000] {taskinstance.py:2698} ERROR - Task failed with exception
Traceback (most recent call last):
  File "/home/airflow/.local/lib/python3.9/site-packages/airflow/models/taskinstance.py", line 433, in _execute_task
    result = execute_callable(context=context, **execute_callable_kwargs)
  File "/home/airflow/.local/lib/python3.9/site-packages/airflow/operators/python.py", line 199, in execute
    return_value = self.execute_callable()
  File "/home/airflow/.local/lib/python3.9/site-packages/airflow/operators/python.py", line 216, in execute_callable
    return self.python_callable(*self.op_args, **self.op_kwargs)
  File "/opt/airflow/dags/3_4_2_homework_assignment.py", line 93, in upload_to_clickhouse
    data_frame = pd.read_csv(csv_file)
  File "/home/airflow/.local/lib/python3.9/site-packages/pandas/io/parsers/readers.py", line 948, in read_csv
    return _read(filepath_or_buffer, kwds)
  File "/home/airflow/.local/lib/python3.9/site-packages/pandas/io/parsers/readers.py", line 611, in _read
    parser = TextFileReader(filepath_or_buffer, **kwds)
  File "/home/airflow/.local/lib/python3.9/site-packages/pandas/io/parsers/readers.py", line 1448, in __init__
    self._engine = self._make_engine(f, self.engine)
  File "/home/airflow/.local/lib/python3.9/site-packages/pandas/io/parsers/readers.py", line 1705, in _make_engine
    self.handles = get_handle(
  File "/home/airflow/.local/lib/python3.9/site-packages/pandas/io/common.py", line 863, in get_handle
    handle = open(
FileNotFoundError: [Errno 2] No such file or directory: 'extracted_data_csv.csv'
[2025-02-27T09:54:17.741+0000] {taskinstance.py:1138} INFO - Marking task as FAILED. dag_id=3_4_2_homework_assignment, task_id=upload_to_clickhouse_task, execution_date=20240102T000000, start_date=20250227T095417, end_date=20250227T095417
[2025-02-27T09:54:17.750+0000] {standard_task_runner.py:107} ERROR - Failed to execute job 7 for task upload_to_clickhouse_task ([Errno 2] No such file or directory: 'extracted_data_csv.csv'; 2733)
[2025-02-27T09:54:17.759+0000] {local_task_job_runner.py:234} INFO - Task exited with return code 1
[2025-02-27T09:54:17.767+0000] {taskinstance.py:3280} INFO - 0 downstream tasks scheduled from follow-on schedule check
[2025-02-27T10:06:08.527+0000] {taskinstance.py:1956} INFO - Dependencies all met for dep_context=non-requeueable deps ti=<TaskInstance: 3_4_2_homework_assignment.upload_to_clickhouse_task scheduled__2024-01-02T00:00:00+00:00 [queued]>
[2025-02-27T10:06:08.532+0000] {taskinstance.py:1956} INFO - Dependencies all met for dep_context=requeueable deps ti=<TaskInstance: 3_4_2_homework_assignment.upload_to_clickhouse_task scheduled__2024-01-02T00:00:00+00:00 [queued]>
[2025-02-27T10:06:08.533+0000] {taskinstance.py:2170} INFO - Starting attempt 1 of 1
[2025-02-27T10:06:08.543+0000] {taskinstance.py:2191} INFO - Executing <Task(PythonOperator): upload_to_clickhouse_task> on 2024-01-02 00:00:00+00:00
[2025-02-27T10:06:08.547+0000] {standard_task_runner.py:60} INFO - Started process 3375 to run task
[2025-02-27T10:06:08.550+0000] {standard_task_runner.py:87} INFO - Running: ['airflow', 'tasks', 'run', '3_4_2_homework_assignment', 'upload_to_clickhouse_task', 'scheduled__2024-01-02T00:00:00+00:00', '--job-id', '7', '--raw', '--subdir', 'DAGS_FOLDER/3_4_2_homework_assignment.py', '--cfg-path', '/tmp/tmpuya_t_dm']
[2025-02-27T10:06:08.551+0000] {standard_task_runner.py:88} INFO - Job 7: Subtask upload_to_clickhouse_task
[2025-02-27T10:06:08.578+0000] {task_command.py:423} INFO - Running <TaskInstance: 3_4_2_homework_assignment.upload_to_clickhouse_task scheduled__2024-01-02T00:00:00+00:00 [running]> on host ea5964584459
[2025-02-27T10:06:08.618+0000] {taskinstance.py:2480} INFO - Exporting env vars: AIRFLOW_CTX_DAG_OWNER='airflow' AIRFLOW_CTX_DAG_ID='3_4_2_homework_assignment' AIRFLOW_CTX_TASK_ID='upload_to_clickhouse_task' AIRFLOW_CTX_EXECUTION_DATE='2024-01-02T00:00:00+00:00' AIRFLOW_CTX_TRY_NUMBER='1' AIRFLOW_CTX_DAG_RUN_ID='scheduled__2024-01-02T00:00:00+00:00'
[2025-02-27T10:06:08.620+0000] {taskinstance.py:2698} ERROR - Task failed with exception
Traceback (most recent call last):
  File "/home/airflow/.local/lib/python3.9/site-packages/airflow/models/taskinstance.py", line 433, in _execute_task
    result = execute_callable(context=context, **execute_callable_kwargs)
  File "/home/airflow/.local/lib/python3.9/site-packages/airflow/operators/python.py", line 199, in execute
    return_value = self.execute_callable()
  File "/home/airflow/.local/lib/python3.9/site-packages/airflow/operators/python.py", line 216, in execute_callable
    return self.python_callable(*self.op_args, **self.op_kwargs)
  File "/opt/airflow/dags/3_4_2_homework_assignment.py", line 87, in upload_to_clickhouse
    data_frame = pd.read_csv(csv_file)
  File "/home/airflow/.local/lib/python3.9/site-packages/pandas/io/parsers/readers.py", line 948, in read_csv
    return _read(filepath_or_buffer, kwds)
  File "/home/airflow/.local/lib/python3.9/site-packages/pandas/io/parsers/readers.py", line 611, in _read
    parser = TextFileReader(filepath_or_buffer, **kwds)
  File "/home/airflow/.local/lib/python3.9/site-packages/pandas/io/parsers/readers.py", line 1448, in __init__
    self._engine = self._make_engine(f, self.engine)
  File "/home/airflow/.local/lib/python3.9/site-packages/pandas/io/parsers/readers.py", line 1705, in _make_engine
    self.handles = get_handle(
  File "/home/airflow/.local/lib/python3.9/site-packages/pandas/io/common.py", line 863, in get_handle
    handle = open(
FileNotFoundError: [Errno 2] No such file or directory: 'extracted_data_csv.csv'
[2025-02-27T10:06:08.625+0000] {taskinstance.py:1138} INFO - Marking task as FAILED. dag_id=3_4_2_homework_assignment, task_id=upload_to_clickhouse_task, execution_date=20240102T000000, start_date=20250227T100608, end_date=20250227T100608
[2025-02-27T10:06:08.641+0000] {standard_task_runner.py:107} ERROR - Failed to execute job 7 for task upload_to_clickhouse_task ([Errno 2] No such file or directory: 'extracted_data_csv.csv'; 3375)
[2025-02-27T10:06:08.683+0000] {local_task_job_runner.py:234} INFO - Task exited with return code 1
[2025-02-27T10:06:08.692+0000] {taskinstance.py:3280} INFO - 0 downstream tasks scheduled from follow-on schedule check
[2025-02-27T10:13:51.695+0000] {taskinstance.py:1956} INFO - Dependencies all met for dep_context=non-requeueable deps ti=<TaskInstance: 3_4_2_homework_assignment.upload_to_clickhouse_task scheduled__2024-01-02T00:00:00+00:00 [queued]>
[2025-02-27T10:13:51.699+0000] {taskinstance.py:1956} INFO - Dependencies all met for dep_context=requeueable deps ti=<TaskInstance: 3_4_2_homework_assignment.upload_to_clickhouse_task scheduled__2024-01-02T00:00:00+00:00 [queued]>
[2025-02-27T10:13:51.700+0000] {taskinstance.py:2170} INFO - Starting attempt 1 of 1
[2025-02-27T10:13:51.709+0000] {taskinstance.py:2191} INFO - Executing <Task(PythonOperator): upload_to_clickhouse_task> on 2024-01-02 00:00:00+00:00
[2025-02-27T10:13:51.714+0000] {standard_task_runner.py:60} INFO - Started process 4270 to run task
[2025-02-27T10:13:51.716+0000] {standard_task_runner.py:87} INFO - Running: ['airflow', 'tasks', 'run', '3_4_2_homework_assignment', 'upload_to_clickhouse_task', 'scheduled__2024-01-02T00:00:00+00:00', '--job-id', '7', '--raw', '--subdir', 'DAGS_FOLDER/3_4_2_homework_assignment.py', '--cfg-path', '/tmp/tmp5szkn2sn']
[2025-02-27T10:13:51.718+0000] {standard_task_runner.py:88} INFO - Job 7: Subtask upload_to_clickhouse_task
[2025-02-27T10:13:51.743+0000] {task_command.py:423} INFO - Running <TaskInstance: 3_4_2_homework_assignment.upload_to_clickhouse_task scheduled__2024-01-02T00:00:00+00:00 [running]> on host ea5964584459
[2025-02-27T10:13:51.782+0000] {taskinstance.py:2480} INFO - Exporting env vars: AIRFLOW_CTX_DAG_OWNER='airflow' AIRFLOW_CTX_DAG_ID='3_4_2_homework_assignment' AIRFLOW_CTX_TASK_ID='upload_to_clickhouse_task' AIRFLOW_CTX_EXECUTION_DATE='2024-01-02T00:00:00+00:00' AIRFLOW_CTX_TRY_NUMBER='1' AIRFLOW_CTX_DAG_RUN_ID='scheduled__2024-01-02T00:00:00+00:00'
[2025-02-27T10:13:51.790+0000] {connection.py:411} WARNING - Failed to connect to None:9000
Traceback (most recent call last):
  File "/home/airflow/.local/lib/python3.9/site-packages/clickhouse_driver/connection.py", line 399, in connect
    return self._init_connection(host, port)
  File "/home/airflow/.local/lib/python3.9/site-packages/clickhouse_driver/connection.py", line 329, in _init_connection
    self.socket = self._create_socket(host, port)
  File "/home/airflow/.local/lib/python3.9/site-packages/clickhouse_driver/connection.py", line 301, in _create_socket
    raise err
  File "/home/airflow/.local/lib/python3.9/site-packages/clickhouse_driver/connection.py", line 292, in _create_socket
    sock.connect(sa)
ConnectionRefusedError: [Errno 111] Connection refused
[2025-02-27T10:13:51.792+0000] {taskinstance.py:2698} ERROR - Task failed with exception
Traceback (most recent call last):
  File "/home/airflow/.local/lib/python3.9/site-packages/airflow/models/taskinstance.py", line 433, in _execute_task
    result = execute_callable(context=context, **execute_callable_kwargs)
  File "/home/airflow/.local/lib/python3.9/site-packages/airflow/operators/python.py", line 199, in execute
    return_value = self.execute_callable()
  File "/home/airflow/.local/lib/python3.9/site-packages/airflow/operators/python.py", line 216, in execute_callable
    return self.python_callable(*self.op_args, **self.op_kwargs)
  File "/opt/airflow/dags/3_4_2_homework_assignment.py", line 90, in upload_to_clickhouse
    client.execute(f'CREATE TABLE IF NOT EXISTS {table_name} (source String, currency String, value Float, date String) ENGINE Log')
  File "/home/airflow/.local/lib/python3.9/site-packages/clickhouse_driver/client.py", line 370, in execute
    with self.disconnect_on_error(query, settings):
  File "/usr/local/lib/python3.9/contextlib.py", line 119, in __enter__
    return next(self.gen)
  File "/home/airflow/.local/lib/python3.9/site-packages/clickhouse_driver/client.py", line 313, in disconnect_on_error
    self.establish_connection(settings)
  File "/home/airflow/.local/lib/python3.9/site-packages/clickhouse_driver/client.py", line 300, in establish_connection
    self.connection.force_connect()
  File "/home/airflow/.local/lib/python3.9/site-packages/clickhouse_driver/connection.py", line 258, in force_connect
    self.connect()
  File "/home/airflow/.local/lib/python3.9/site-packages/clickhouse_driver/connection.py", line 420, in connect
    raise err
clickhouse_driver.errors.NetworkError: Code: 210. Connection refused (None:9000)
[2025-02-27T10:13:51.798+0000] {taskinstance.py:1138} INFO - Marking task as FAILED. dag_id=3_4_2_homework_assignment, task_id=upload_to_clickhouse_task, execution_date=20240102T000000, start_date=20250227T101351, end_date=20250227T101351
[2025-02-27T10:13:51.806+0000] {standard_task_runner.py:107} ERROR - Failed to execute job 7 for task upload_to_clickhouse_task (Code: 210. Connection refused (None:9000); 4270)
[2025-02-27T10:13:51.851+0000] {local_task_job_runner.py:234} INFO - Task exited with return code 1
[2025-02-27T10:13:51.860+0000] {taskinstance.py:3280} INFO - 0 downstream tasks scheduled from follow-on schedule check
[2025-02-27T10:19:04.484+0000] {taskinstance.py:1956} INFO - Dependencies all met for dep_context=non-requeueable deps ti=<TaskInstance: 3_4_2_homework_assignment.upload_to_clickhouse_task scheduled__2024-01-02T00:00:00+00:00 [queued]>
[2025-02-27T10:19:04.489+0000] {taskinstance.py:1956} INFO - Dependencies all met for dep_context=requeueable deps ti=<TaskInstance: 3_4_2_homework_assignment.upload_to_clickhouse_task scheduled__2024-01-02T00:00:00+00:00 [queued]>
[2025-02-27T10:19:04.490+0000] {taskinstance.py:2170} INFO - Starting attempt 1 of 1
[2025-02-27T10:19:04.502+0000] {taskinstance.py:2191} INFO - Executing <Task(PythonOperator): upload_to_clickhouse_task> on 2024-01-02 00:00:00+00:00
[2025-02-27T10:19:04.507+0000] {standard_task_runner.py:60} INFO - Started process 4863 to run task
[2025-02-27T10:19:04.509+0000] {standard_task_runner.py:87} INFO - Running: ['airflow', 'tasks', 'run', '3_4_2_homework_assignment', 'upload_to_clickhouse_task', 'scheduled__2024-01-02T00:00:00+00:00', '--job-id', '7', '--raw', '--subdir', 'DAGS_FOLDER/3_4_2_homework_assignment.py', '--cfg-path', '/tmp/tmpb5iiqrj3']
[2025-02-27T10:19:04.510+0000] {standard_task_runner.py:88} INFO - Job 7: Subtask upload_to_clickhouse_task
[2025-02-27T10:19:04.539+0000] {task_command.py:423} INFO - Running <TaskInstance: 3_4_2_homework_assignment.upload_to_clickhouse_task scheduled__2024-01-02T00:00:00+00:00 [running]> on host ea5964584459
[2025-02-27T10:19:04.584+0000] {taskinstance.py:2480} INFO - Exporting env vars: AIRFLOW_CTX_DAG_OWNER='airflow' AIRFLOW_CTX_DAG_ID='3_4_2_homework_assignment' AIRFLOW_CTX_TASK_ID='upload_to_clickhouse_task' AIRFLOW_CTX_EXECUTION_DATE='2024-01-02T00:00:00+00:00' AIRFLOW_CTX_TRY_NUMBER='1' AIRFLOW_CTX_DAG_RUN_ID='scheduled__2024-01-02T00:00:00+00:00'
[2025-02-27T10:19:04.594+0000] {connection.py:411} WARNING - Failed to connect to None:9000
Traceback (most recent call last):
  File "/home/airflow/.local/lib/python3.9/site-packages/clickhouse_driver/connection.py", line 399, in connect
    return self._init_connection(host, port)
  File "/home/airflow/.local/lib/python3.9/site-packages/clickhouse_driver/connection.py", line 329, in _init_connection
    self.socket = self._create_socket(host, port)
  File "/home/airflow/.local/lib/python3.9/site-packages/clickhouse_driver/connection.py", line 301, in _create_socket
    raise err
  File "/home/airflow/.local/lib/python3.9/site-packages/clickhouse_driver/connection.py", line 292, in _create_socket
    sock.connect(sa)
ConnectionRefusedError: [Errno 111] Connection refused
[2025-02-27T10:19:04.595+0000] {taskinstance.py:2698} ERROR - Task failed with exception
Traceback (most recent call last):
  File "/home/airflow/.local/lib/python3.9/site-packages/airflow/models/taskinstance.py", line 433, in _execute_task
    result = execute_callable(context=context, **execute_callable_kwargs)
  File "/home/airflow/.local/lib/python3.9/site-packages/airflow/operators/python.py", line 199, in execute
    return_value = self.execute_callable()
  File "/home/airflow/.local/lib/python3.9/site-packages/airflow/operators/python.py", line 216, in execute_callable
    return self.python_callable(*self.op_args, **self.op_kwargs)
  File "/opt/airflow/dags/3_4_2_homework_assignment.py", line 90, in upload_to_clickhouse
    client.execute(f'CREATE TABLE IF NOT EXISTS {table_name} (source String, currency String, value Float, date String) ENGINE Log')
  File "/home/airflow/.local/lib/python3.9/site-packages/clickhouse_driver/client.py", line 370, in execute
    with self.disconnect_on_error(query, settings):
  File "/usr/local/lib/python3.9/contextlib.py", line 119, in __enter__
    return next(self.gen)
  File "/home/airflow/.local/lib/python3.9/site-packages/clickhouse_driver/client.py", line 313, in disconnect_on_error
    self.establish_connection(settings)
  File "/home/airflow/.local/lib/python3.9/site-packages/clickhouse_driver/client.py", line 300, in establish_connection
    self.connection.force_connect()
  File "/home/airflow/.local/lib/python3.9/site-packages/clickhouse_driver/connection.py", line 258, in force_connect
    self.connect()
  File "/home/airflow/.local/lib/python3.9/site-packages/clickhouse_driver/connection.py", line 420, in connect
    raise err
clickhouse_driver.errors.NetworkError: Code: 210. Connection refused (None:9000)
[2025-02-27T10:19:04.602+0000] {taskinstance.py:1138} INFO - Marking task as FAILED. dag_id=3_4_2_homework_assignment, task_id=upload_to_clickhouse_task, execution_date=20240102T000000, start_date=20250227T101904, end_date=20250227T101904
[2025-02-27T10:19:04.612+0000] {standard_task_runner.py:107} ERROR - Failed to execute job 7 for task upload_to_clickhouse_task (Code: 210. Connection refused (None:9000); 4863)
[2025-02-27T10:19:04.643+0000] {local_task_job_runner.py:234} INFO - Task exited with return code 1
[2025-02-27T10:19:04.651+0000] {taskinstance.py:3280} INFO - 0 downstream tasks scheduled from follow-on schedule check
[2025-02-27T10:23:42.391+0000] {taskinstance.py:1956} INFO - Dependencies all met for dep_context=non-requeueable deps ti=<TaskInstance: 3_4_2_homework_assignment.upload_to_clickhouse_task scheduled__2024-01-02T00:00:00+00:00 [queued]>
[2025-02-27T10:23:42.396+0000] {taskinstance.py:1956} INFO - Dependencies all met for dep_context=requeueable deps ti=<TaskInstance: 3_4_2_homework_assignment.upload_to_clickhouse_task scheduled__2024-01-02T00:00:00+00:00 [queued]>
[2025-02-27T10:23:42.396+0000] {taskinstance.py:2170} INFO - Starting attempt 1 of 1
[2025-02-27T10:23:42.407+0000] {taskinstance.py:2191} INFO - Executing <Task(PythonOperator): upload_to_clickhouse_task> on 2024-01-02 00:00:00+00:00
[2025-02-27T10:23:42.412+0000] {standard_task_runner.py:60} INFO - Started process 5314 to run task
[2025-02-27T10:23:42.414+0000] {standard_task_runner.py:87} INFO - Running: ['airflow', 'tasks', 'run', '3_4_2_homework_assignment', 'upload_to_clickhouse_task', 'scheduled__2024-01-02T00:00:00+00:00', '--job-id', '7', '--raw', '--subdir', 'DAGS_FOLDER/3_4_2_homework_assignment.py', '--cfg-path', '/tmp/tmpx69k9264']
[2025-02-27T10:23:42.415+0000] {standard_task_runner.py:88} INFO - Job 7: Subtask upload_to_clickhouse_task
[2025-02-27T10:23:42.442+0000] {task_command.py:423} INFO - Running <TaskInstance: 3_4_2_homework_assignment.upload_to_clickhouse_task scheduled__2024-01-02T00:00:00+00:00 [running]> on host ea5964584459
[2025-02-27T10:23:42.484+0000] {taskinstance.py:2480} INFO - Exporting env vars: AIRFLOW_CTX_DAG_OWNER='airflow' AIRFLOW_CTX_DAG_ID='3_4_2_homework_assignment' AIRFLOW_CTX_TASK_ID='upload_to_clickhouse_task' AIRFLOW_CTX_EXECUTION_DATE='2024-01-02T00:00:00+00:00' AIRFLOW_CTX_TRY_NUMBER='1' AIRFLOW_CTX_DAG_RUN_ID='scheduled__2024-01-02T00:00:00+00:00'
[2025-02-27T10:23:42.489+0000] {connection.py:411} WARNING - Failed to connect to None:9000
Traceback (most recent call last):
  File "/home/airflow/.local/lib/python3.9/site-packages/clickhouse_driver/connection.py", line 399, in connect
    return self._init_connection(host, port)
  File "/home/airflow/.local/lib/python3.9/site-packages/clickhouse_driver/connection.py", line 329, in _init_connection
    self.socket = self._create_socket(host, port)
  File "/home/airflow/.local/lib/python3.9/site-packages/clickhouse_driver/connection.py", line 301, in _create_socket
    raise err
  File "/home/airflow/.local/lib/python3.9/site-packages/clickhouse_driver/connection.py", line 292, in _create_socket
    sock.connect(sa)
ConnectionRefusedError: [Errno 111] Connection refused
[2025-02-27T10:23:42.490+0000] {taskinstance.py:2698} ERROR - Task failed with exception
Traceback (most recent call last):
  File "/home/airflow/.local/lib/python3.9/site-packages/airflow/models/taskinstance.py", line 433, in _execute_task
    result = execute_callable(context=context, **execute_callable_kwargs)
  File "/home/airflow/.local/lib/python3.9/site-packages/airflow/operators/python.py", line 199, in execute
    return_value = self.execute_callable()
  File "/home/airflow/.local/lib/python3.9/site-packages/airflow/operators/python.py", line 216, in execute_callable
    return self.python_callable(*self.op_args, **self.op_kwargs)
  File "/opt/airflow/dags/3_4_2_homework_assignment.py", line 90, in upload_to_clickhouse
    client.execute(f'CREATE TABLE IF NOT EXISTS {table_name} (source String, currency String, value Float, date String) ENGINE Log')
  File "/home/airflow/.local/lib/python3.9/site-packages/clickhouse_driver/client.py", line 370, in execute
    with self.disconnect_on_error(query, settings):
  File "/usr/local/lib/python3.9/contextlib.py", line 119, in __enter__
    return next(self.gen)
  File "/home/airflow/.local/lib/python3.9/site-packages/clickhouse_driver/client.py", line 313, in disconnect_on_error
    self.establish_connection(settings)
  File "/home/airflow/.local/lib/python3.9/site-packages/clickhouse_driver/client.py", line 300, in establish_connection
    self.connection.force_connect()
  File "/home/airflow/.local/lib/python3.9/site-packages/clickhouse_driver/connection.py", line 258, in force_connect
    self.connect()
  File "/home/airflow/.local/lib/python3.9/site-packages/clickhouse_driver/connection.py", line 420, in connect
    raise err
clickhouse_driver.errors.NetworkError: Code: 210. Connection refused (None:9000)
[2025-02-27T10:23:42.496+0000] {taskinstance.py:1138} INFO - Marking task as FAILED. dag_id=3_4_2_homework_assignment, task_id=upload_to_clickhouse_task, execution_date=20240102T000000, start_date=20250227T102342, end_date=20250227T102342
[2025-02-27T10:23:42.506+0000] {standard_task_runner.py:107} ERROR - Failed to execute job 7 for task upload_to_clickhouse_task (Code: 210. Connection refused (None:9000); 5314)
[2025-02-27T10:23:42.548+0000] {local_task_job_runner.py:234} INFO - Task exited with return code 1
[2025-02-27T10:23:42.558+0000] {taskinstance.py:3280} INFO - 0 downstream tasks scheduled from follow-on schedule check
[2025-02-27T10:26:30.435+0000] {taskinstance.py:1956} INFO - Dependencies all met for dep_context=non-requeueable deps ti=<TaskInstance: 3_4_2_homework_assignment.upload_to_clickhouse_task scheduled__2024-01-02T00:00:00+00:00 [queued]>
[2025-02-27T10:26:30.440+0000] {taskinstance.py:1956} INFO - Dependencies all met for dep_context=requeueable deps ti=<TaskInstance: 3_4_2_homework_assignment.upload_to_clickhouse_task scheduled__2024-01-02T00:00:00+00:00 [queued]>
[2025-02-27T10:26:30.440+0000] {taskinstance.py:2170} INFO - Starting attempt 1 of 1
[2025-02-27T10:26:30.451+0000] {taskinstance.py:2191} INFO - Executing <Task(PythonOperator): upload_to_clickhouse_task> on 2024-01-02 00:00:00+00:00
[2025-02-27T10:26:30.456+0000] {standard_task_runner.py:60} INFO - Started process 5605 to run task
[2025-02-27T10:26:30.458+0000] {standard_task_runner.py:87} INFO - Running: ['airflow', 'tasks', 'run', '3_4_2_homework_assignment', 'upload_to_clickhouse_task', 'scheduled__2024-01-02T00:00:00+00:00', '--job-id', '7', '--raw', '--subdir', 'DAGS_FOLDER/3_4_2_homework_assignment.py', '--cfg-path', '/tmp/tmpx_d00e00']
[2025-02-27T10:26:30.459+0000] {standard_task_runner.py:88} INFO - Job 7: Subtask upload_to_clickhouse_task
[2025-02-27T10:26:30.484+0000] {task_command.py:423} INFO - Running <TaskInstance: 3_4_2_homework_assignment.upload_to_clickhouse_task scheduled__2024-01-02T00:00:00+00:00 [running]> on host ea5964584459
[2025-02-27T10:26:30.521+0000] {taskinstance.py:2480} INFO - Exporting env vars: AIRFLOW_CTX_DAG_OWNER='airflow' AIRFLOW_CTX_DAG_ID='3_4_2_homework_assignment' AIRFLOW_CTX_TASK_ID='upload_to_clickhouse_task' AIRFLOW_CTX_EXECUTION_DATE='2024-01-02T00:00:00+00:00' AIRFLOW_CTX_TRY_NUMBER='1' AIRFLOW_CTX_DAG_RUN_ID='scheduled__2024-01-02T00:00:00+00:00'
[2025-02-27T10:26:30.535+0000] {taskinstance.py:2698} ERROR - Task failed with exception
Traceback (most recent call last):
  File "/home/airflow/.local/lib/python3.9/site-packages/airflow/models/taskinstance.py", line 433, in _execute_task
    result = execute_callable(context=context, **execute_callable_kwargs)
  File "/home/airflow/.local/lib/python3.9/site-packages/airflow/operators/python.py", line 199, in execute
    return_value = self.execute_callable()
  File "/home/airflow/.local/lib/python3.9/site-packages/airflow/operators/python.py", line 216, in execute_callable
    return self.python_callable(*self.op_args, **self.op_kwargs)
  File "/opt/airflow/dags/3_4_2_homework_assignment.py", line 92, in upload_to_clickhouse
    client.execute(f'INSERT INTO {table_name} VALUES', data_frame.to_dict('records'))
  File "/home/airflow/.local/lib/python3.9/site-packages/clickhouse_driver/client.py", line 376, in execute
    rv = self.process_insert_query(
  File "/home/airflow/.local/lib/python3.9/site-packages/clickhouse_driver/client.py", line 607, in process_insert_query
    rv = self.send_data(sample_block, data,
  File "/home/airflow/.local/lib/python3.9/site-packages/clickhouse_driver/client.py", line 658, in send_data
    block = block_cls(sample_block.columns_with_types, chunk,
  File "/home/airflow/.local/lib/python3.9/site-packages/clickhouse_driver/block.py", line 40, in __init__
    self.data = self.normalize(data or [])
  File "/home/airflow/.local/lib/python3.9/site-packages/clickhouse_driver/block.py", line 128, in normalize
    self._mutate_dicts_to_rows(data)
  File "/home/airflow/.local/lib/python3.9/site-packages/clickhouse_driver/block.py", line 159, in _mutate_dicts_to_rows
    return self._pure_mutate_dicts_to_rows(
  File "/home/airflow/.local/lib/python3.9/site-packages/clickhouse_driver/block.py", line 186, in _pure_mutate_dicts_to_rows
    new_data.append(row[name])
KeyError: 'source'
[2025-02-27T10:26:30.542+0000] {taskinstance.py:1138} INFO - Marking task as FAILED. dag_id=3_4_2_homework_assignment, task_id=upload_to_clickhouse_task, execution_date=20240102T000000, start_date=20250227T102630, end_date=20250227T102630
[2025-02-27T10:26:30.550+0000] {standard_task_runner.py:107} ERROR - Failed to execute job 7 for task upload_to_clickhouse_task ('source'; 5605)
[2025-02-27T10:26:30.593+0000] {local_task_job_runner.py:234} INFO - Task exited with return code 1
[2025-02-27T10:26:30.601+0000] {taskinstance.py:3280} INFO - 0 downstream tasks scheduled from follow-on schedule check
[2025-02-27T10:34:54.037+0000] {taskinstance.py:1956} INFO - Dependencies all met for dep_context=non-requeueable deps ti=<TaskInstance: 3_4_2_homework_assignment.upload_to_clickhouse_task scheduled__2024-01-02T00:00:00+00:00 [queued]>
[2025-02-27T10:34:54.042+0000] {taskinstance.py:1956} INFO - Dependencies all met for dep_context=requeueable deps ti=<TaskInstance: 3_4_2_homework_assignment.upload_to_clickhouse_task scheduled__2024-01-02T00:00:00+00:00 [queued]>
[2025-02-27T10:34:54.042+0000] {taskinstance.py:2170} INFO - Starting attempt 1 of 1
[2025-02-27T10:34:54.056+0000] {taskinstance.py:2191} INFO - Executing <Task(PythonOperator): upload_to_clickhouse_task> on 2024-01-02 00:00:00+00:00
[2025-02-27T10:34:54.061+0000] {standard_task_runner.py:60} INFO - Started process 6265 to run task
[2025-02-27T10:34:54.063+0000] {standard_task_runner.py:87} INFO - Running: ['airflow', 'tasks', 'run', '3_4_2_homework_assignment', 'upload_to_clickhouse_task', 'scheduled__2024-01-02T00:00:00+00:00', '--job-id', '7', '--raw', '--subdir', 'DAGS_FOLDER/3_4_2_homework_assignment.py', '--cfg-path', '/tmp/tmpralt2dt7']
[2025-02-27T10:34:54.065+0000] {standard_task_runner.py:88} INFO - Job 7: Subtask upload_to_clickhouse_task
[2025-02-27T10:34:54.096+0000] {task_command.py:423} INFO - Running <TaskInstance: 3_4_2_homework_assignment.upload_to_clickhouse_task scheduled__2024-01-02T00:00:00+00:00 [running]> on host ea5964584459
[2025-02-27T10:34:54.142+0000] {taskinstance.py:2480} INFO - Exporting env vars: AIRFLOW_CTX_DAG_OWNER='airflow' AIRFLOW_CTX_DAG_ID='3_4_2_homework_assignment' AIRFLOW_CTX_TASK_ID='upload_to_clickhouse_task' AIRFLOW_CTX_EXECUTION_DATE='2024-01-02T00:00:00+00:00' AIRFLOW_CTX_TRY_NUMBER='1' AIRFLOW_CTX_DAG_RUN_ID='scheduled__2024-01-02T00:00:00+00:00'
[2025-02-27T10:34:54.161+0000] {taskinstance.py:2698} ERROR - Task failed with exception
Traceback (most recent call last):
  File "/home/airflow/.local/lib/python3.9/site-packages/airflow/models/taskinstance.py", line 433, in _execute_task
    result = execute_callable(context=context, **execute_callable_kwargs)
  File "/home/airflow/.local/lib/python3.9/site-packages/airflow/operators/python.py", line 199, in execute
    return_value = self.execute_callable()
  File "/home/airflow/.local/lib/python3.9/site-packages/airflow/operators/python.py", line 216, in execute_callable
    return self.python_callable(*self.op_args, **self.op_kwargs)
  File "/opt/airflow/dags/3_4_2_homework_assignment.py", line 93, in upload_to_clickhouse
    client.execute(f'INSERT INTO {table_name} VALUES', data_frame.to_dict('records'))
  File "/home/airflow/.local/lib/python3.9/site-packages/clickhouse_driver/client.py", line 376, in execute
    rv = self.process_insert_query(
  File "/home/airflow/.local/lib/python3.9/site-packages/clickhouse_driver/client.py", line 607, in process_insert_query
    rv = self.send_data(sample_block, data,
  File "/home/airflow/.local/lib/python3.9/site-packages/clickhouse_driver/client.py", line 658, in send_data
    block = block_cls(sample_block.columns_with_types, chunk,
  File "/home/airflow/.local/lib/python3.9/site-packages/clickhouse_driver/block.py", line 40, in __init__
    self.data = self.normalize(data or [])
  File "/home/airflow/.local/lib/python3.9/site-packages/clickhouse_driver/block.py", line 128, in normalize
    self._mutate_dicts_to_rows(data)
  File "/home/airflow/.local/lib/python3.9/site-packages/clickhouse_driver/block.py", line 159, in _mutate_dicts_to_rows
    return self._pure_mutate_dicts_to_rows(
  File "/home/airflow/.local/lib/python3.9/site-packages/clickhouse_driver/block.py", line 186, in _pure_mutate_dicts_to_rows
    new_data.append(row[name])
KeyError: 'source'
[2025-02-27T10:34:54.169+0000] {taskinstance.py:1138} INFO - Marking task as FAILED. dag_id=3_4_2_homework_assignment, task_id=upload_to_clickhouse_task, execution_date=20240102T000000, start_date=20250227T103454, end_date=20250227T103454
[2025-02-27T10:34:54.182+0000] {standard_task_runner.py:107} ERROR - Failed to execute job 7 for task upload_to_clickhouse_task ('source'; 6265)
[2025-02-27T10:34:54.196+0000] {local_task_job_runner.py:234} INFO - Task exited with return code 1
[2025-02-27T10:34:54.206+0000] {taskinstance.py:3280} INFO - 0 downstream tasks scheduled from follow-on schedule check
[2025-02-27T10:44:45.370+0000] {taskinstance.py:1956} INFO - Dependencies all met for dep_context=non-requeueable deps ti=<TaskInstance: 3_4_2_homework_assignment.upload_to_clickhouse_task scheduled__2024-01-02T00:00:00+00:00 [queued]>
[2025-02-27T10:44:45.377+0000] {taskinstance.py:1956} INFO - Dependencies all met for dep_context=requeueable deps ti=<TaskInstance: 3_4_2_homework_assignment.upload_to_clickhouse_task scheduled__2024-01-02T00:00:00+00:00 [queued]>
[2025-02-27T10:44:45.378+0000] {taskinstance.py:2170} INFO - Starting attempt 1 of 1
[2025-02-27T10:44:45.389+0000] {taskinstance.py:2191} INFO - Executing <Task(PythonOperator): upload_to_clickhouse_task> on 2024-01-02 00:00:00+00:00
[2025-02-27T10:44:45.394+0000] {standard_task_runner.py:60} INFO - Started process 6950 to run task
[2025-02-27T10:44:45.397+0000] {standard_task_runner.py:87} INFO - Running: ['airflow', 'tasks', 'run', '3_4_2_homework_assignment', 'upload_to_clickhouse_task', 'scheduled__2024-01-02T00:00:00+00:00', '--job-id', '7', '--raw', '--subdir', 'DAGS_FOLDER/3_4_2_homework_assignment.py', '--cfg-path', '/tmp/tmp7vvyv6f1']
[2025-02-27T10:44:45.398+0000] {standard_task_runner.py:88} INFO - Job 7: Subtask upload_to_clickhouse_task
[2025-02-27T10:44:45.424+0000] {task_command.py:423} INFO - Running <TaskInstance: 3_4_2_homework_assignment.upload_to_clickhouse_task scheduled__2024-01-02T00:00:00+00:00 [running]> on host ea5964584459
[2025-02-27T10:44:45.475+0000] {taskinstance.py:2480} INFO - Exporting env vars: AIRFLOW_CTX_DAG_OWNER='airflow' AIRFLOW_CTX_DAG_ID='3_4_2_homework_assignment' AIRFLOW_CTX_TASK_ID='upload_to_clickhouse_task' AIRFLOW_CTX_EXECUTION_DATE='2024-01-02T00:00:00+00:00' AIRFLOW_CTX_TRY_NUMBER='1' AIRFLOW_CTX_DAG_RUN_ID='scheduled__2024-01-02T00:00:00+00:00'
[2025-02-27T10:44:45.492+0000] {unix.py:142} WARNING - /etc/timezone is deprecated on Debian, and no longer reliable. Ignoring.
[2025-02-27T10:44:45.495+0000] {python.py:201} INFO - Done. Returned value was: None
[2025-02-27T10:44:45.499+0000] {taskinstance.py:1138} INFO - Marking task as SUCCESS. dag_id=3_4_2_homework_assignment, task_id=upload_to_clickhouse_task, execution_date=20240102T000000, start_date=20250227T104445, end_date=20250227T104445
[2025-02-27T10:44:45.530+0000] {local_task_job_runner.py:234} INFO - Task exited with return code 0
[2025-02-27T10:44:45.541+0000] {taskinstance.py:3280} INFO - 0 downstream tasks scheduled from follow-on schedule check
