[2025-03-03T14:24:24.954+0000] {taskinstance.py:1956} INFO - Dependencies all met for dep_context=non-requeueable deps ti=<TaskInstance: 4_4_house_assignment.upload_to_clickhouse scheduled__2024-01-01T00:00:00+00:00 [queued]>
[2025-03-03T14:24:24.960+0000] {taskinstance.py:1956} INFO - Dependencies all met for dep_context=requeueable deps ti=<TaskInstance: 4_4_house_assignment.upload_to_clickhouse scheduled__2024-01-01T00:00:00+00:00 [queued]>
[2025-03-03T14:24:24.961+0000] {taskinstance.py:2170} INFO - Starting attempt 1 of 1
[2025-03-03T14:24:24.971+0000] {taskinstance.py:2191} INFO - Executing <Task(PythonOperator): upload_to_clickhouse> on 2024-01-01 00:00:00+00:00
[2025-03-03T14:24:24.976+0000] {standard_task_runner.py:60} INFO - Started process 2115 to run task
[2025-03-03T14:24:24.978+0000] {standard_task_runner.py:87} INFO - Running: ['airflow', 'tasks', 'run', '4_4_house_assignment', 'upload_to_clickhouse', 'scheduled__2024-01-01T00:00:00+00:00', '--job-id', '6', '--raw', '--subdir', 'DAGS_FOLDER/4_4_house_assignment.py', '--cfg-path', '/tmp/tmpqnt0uh_s']
[2025-03-03T14:24:24.980+0000] {standard_task_runner.py:88} INFO - Job 6: Subtask upload_to_clickhouse
[2025-03-03T14:24:25.012+0000] {task_command.py:423} INFO - Running <TaskInstance: 4_4_house_assignment.upload_to_clickhouse scheduled__2024-01-01T00:00:00+00:00 [running]> on host 9a2e4036dec3
[2025-03-03T14:24:25.058+0000] {taskinstance.py:2480} INFO - Exporting env vars: AIRFLOW_CTX_DAG_OWNER='airflow' AIRFLOW_CTX_DAG_ID='4_4_house_assignment' AIRFLOW_CTX_TASK_ID='upload_to_clickhouse' AIRFLOW_CTX_EXECUTION_DATE='2024-01-01T00:00:00+00:00' AIRFLOW_CTX_TRY_NUMBER='1' AIRFLOW_CTX_DAG_RUN_ID='scheduled__2024-01-01T00:00:00+00:00'
[2025-03-03T14:24:25.067+0000] {connection.py:411} WARNING - Failed to connect to localhost:9000
Traceback (most recent call last):
  File "/home/airflow/.local/lib/python3.9/site-packages/clickhouse_driver/connection.py", line 399, in connect
    return self._init_connection(host, port)
  File "/home/airflow/.local/lib/python3.9/site-packages/clickhouse_driver/connection.py", line 329, in _init_connection
    self.socket = self._create_socket(host, port)
  File "/home/airflow/.local/lib/python3.9/site-packages/clickhouse_driver/connection.py", line 301, in _create_socket
    raise err
  File "/home/airflow/.local/lib/python3.9/site-packages/clickhouse_driver/connection.py", line 292, in _create_socket
    sock.connect(sa)
ConnectionRefusedError: [Errno 111] Connection refused
[2025-03-03T14:24:25.068+0000] {taskinstance.py:2698} ERROR - Task failed with exception
Traceback (most recent call last):
  File "/home/airflow/.local/lib/python3.9/site-packages/airflow/models/taskinstance.py", line 433, in _execute_task
    result = execute_callable(context=context, **execute_callable_kwargs)
  File "/home/airflow/.local/lib/python3.9/site-packages/airflow/operators/python.py", line 199, in execute
    return_value = self.execute_callable()
  File "/home/airflow/.local/lib/python3.9/site-packages/airflow/operators/python.py", line 216, in execute_callable
    return self.python_callable(*self.op_args, **self.op_kwargs)
  File "/opt/airflow/dags/4_4_house_assignment.py", line 74, in upload_to_clickhouse
    client.execute(f'CREATE TABLE IF NOT EXISTS {table_name} (num_code Int64, char_code String, nominal Int64, name String, value String, date String) ENGINE Log')
  File "/home/airflow/.local/lib/python3.9/site-packages/clickhouse_driver/client.py", line 370, in execute
    with self.disconnect_on_error(query, settings):
  File "/usr/local/lib/python3.9/contextlib.py", line 119, in __enter__
    return next(self.gen)
  File "/home/airflow/.local/lib/python3.9/site-packages/clickhouse_driver/client.py", line 313, in disconnect_on_error
    self.establish_connection(settings)
  File "/home/airflow/.local/lib/python3.9/site-packages/clickhouse_driver/client.py", line 300, in establish_connection
    self.connection.force_connect()
  File "/home/airflow/.local/lib/python3.9/site-packages/clickhouse_driver/connection.py", line 258, in force_connect
    self.connect()
  File "/home/airflow/.local/lib/python3.9/site-packages/clickhouse_driver/connection.py", line 420, in connect
    raise err
clickhouse_driver.errors.NetworkError: Code: 210. Connection refused (localhost:9000)
[2025-03-03T14:24:25.076+0000] {taskinstance.py:1138} INFO - Marking task as FAILED. dag_id=4_4_house_assignment, task_id=upload_to_clickhouse, execution_date=20240101T000000, start_date=20250303T142424, end_date=20250303T142425
[2025-03-03T14:24:25.088+0000] {standard_task_runner.py:107} ERROR - Failed to execute job 6 for task upload_to_clickhouse (Code: 210. Connection refused (localhost:9000); 2115)
[2025-03-03T14:24:25.111+0000] {local_task_job_runner.py:234} INFO - Task exited with return code 1
[2025-03-03T14:24:25.120+0000] {taskinstance.py:3280} INFO - 0 downstream tasks scheduled from follow-on schedule check
[2025-03-03T14:26:47.474+0000] {taskinstance.py:1956} INFO - Dependencies all met for dep_context=non-requeueable deps ti=<TaskInstance: 4_4_house_assignment.upload_to_clickhouse scheduled__2024-01-01T00:00:00+00:00 [queued]>
[2025-03-03T14:26:47.481+0000] {taskinstance.py:1956} INFO - Dependencies all met for dep_context=requeueable deps ti=<TaskInstance: 4_4_house_assignment.upload_to_clickhouse scheduled__2024-01-01T00:00:00+00:00 [queued]>
[2025-03-03T14:26:47.481+0000] {taskinstance.py:2170} INFO - Starting attempt 1 of 1
[2025-03-03T14:26:47.492+0000] {taskinstance.py:2191} INFO - Executing <Task(PythonOperator): upload_to_clickhouse> on 2024-01-01 00:00:00+00:00
[2025-03-03T14:26:47.497+0000] {standard_task_runner.py:60} INFO - Started process 2417 to run task
[2025-03-03T14:26:47.500+0000] {standard_task_runner.py:87} INFO - Running: ['airflow', 'tasks', 'run', '4_4_house_assignment', 'upload_to_clickhouse', 'scheduled__2024-01-01T00:00:00+00:00', '--job-id', '6', '--raw', '--subdir', 'DAGS_FOLDER/4_4_house_assignment.py', '--cfg-path', '/tmp/tmpodc8i6j8']
[2025-03-03T14:26:47.502+0000] {standard_task_runner.py:88} INFO - Job 6: Subtask upload_to_clickhouse
[2025-03-03T14:26:47.540+0000] {task_command.py:423} INFO - Running <TaskInstance: 4_4_house_assignment.upload_to_clickhouse scheduled__2024-01-01T00:00:00+00:00 [running]> on host 9a2e4036dec3
[2025-03-03T14:26:47.591+0000] {taskinstance.py:2480} INFO - Exporting env vars: AIRFLOW_CTX_DAG_OWNER='airflow' AIRFLOW_CTX_DAG_ID='4_4_house_assignment' AIRFLOW_CTX_TASK_ID='upload_to_clickhouse' AIRFLOW_CTX_EXECUTION_DATE='2024-01-01T00:00:00+00:00' AIRFLOW_CTX_TRY_NUMBER='1' AIRFLOW_CTX_DAG_RUN_ID='scheduled__2024-01-01T00:00:00+00:00'
[2025-03-03T14:26:47.744+0000] {unix.py:142} WARNING - /etc/timezone is deprecated on Debian, and no longer reliable. Ignoring.
[2025-03-03T14:26:47.754+0000] {python.py:201} INFO - Done. Returned value was: None
[2025-03-03T14:26:47.759+0000] {taskinstance.py:1138} INFO - Marking task as SUCCESS. dag_id=4_4_house_assignment, task_id=upload_to_clickhouse, execution_date=20240101T000000, start_date=20250303T142647, end_date=20250303T142647
[2025-03-03T14:26:47.793+0000] {local_task_job_runner.py:234} INFO - Task exited with return code 0
[2025-03-03T14:26:47.803+0000] {taskinstance.py:3280} INFO - 0 downstream tasks scheduled from follow-on schedule check
[2025-03-10T09:47:51.240+0000] {taskinstance.py:1956} INFO - Dependencies all met for dep_context=non-requeueable deps ti=<TaskInstance: 4_4_house_assignment.upload_to_clickhouse scheduled__2024-01-01T00:00:00+00:00 [queued]>
[2025-03-10T09:47:51.247+0000] {taskinstance.py:1956} INFO - Dependencies all met for dep_context=requeueable deps ti=<TaskInstance: 4_4_house_assignment.upload_to_clickhouse scheduled__2024-01-01T00:00:00+00:00 [queued]>
[2025-03-10T09:47:51.247+0000] {taskinstance.py:2170} INFO - Starting attempt 1 of 1
[2025-03-10T09:47:51.258+0000] {taskinstance.py:2191} INFO - Executing <Task(PythonOperator): upload_to_clickhouse> on 2024-01-01 00:00:00+00:00
[2025-03-10T09:47:51.264+0000] {standard_task_runner.py:60} INFO - Started process 217 to run task
[2025-03-10T09:47:51.266+0000] {standard_task_runner.py:87} INFO - Running: ['airflow', 'tasks', 'run', '4_4_house_assignment', 'upload_to_clickhouse', 'scheduled__2024-01-01T00:00:00+00:00', '--job-id', '22', '--raw', '--subdir', 'DAGS_FOLDER/4_4_house_assignment.py', '--cfg-path', '/tmp/tmp7e8yy4z8']
[2025-03-10T09:47:51.268+0000] {standard_task_runner.py:88} INFO - Job 22: Subtask upload_to_clickhouse
[2025-03-10T09:47:51.299+0000] {task_command.py:423} INFO - Running <TaskInstance: 4_4_house_assignment.upload_to_clickhouse scheduled__2024-01-01T00:00:00+00:00 [running]> on host 9a2e4036dec3
[2025-03-10T09:47:51.343+0000] {taskinstance.py:2480} INFO - Exporting env vars: AIRFLOW_CTX_DAG_OWNER='airflow' AIRFLOW_CTX_DAG_ID='4_4_house_assignment' AIRFLOW_CTX_TASK_ID='upload_to_clickhouse' AIRFLOW_CTX_EXECUTION_DATE='2024-01-01T00:00:00+00:00' AIRFLOW_CTX_TRY_NUMBER='1' AIRFLOW_CTX_DAG_RUN_ID='scheduled__2024-01-01T00:00:00+00:00'
[2025-03-10T09:47:51.424+0000] {unix.py:142} WARNING - /etc/timezone is deprecated on Debian, and no longer reliable. Ignoring.
[2025-03-10T09:47:51.429+0000] {python.py:201} INFO - Done. Returned value was: None
[2025-03-10T09:47:51.434+0000] {taskinstance.py:1138} INFO - Marking task as SUCCESS. dag_id=4_4_house_assignment, task_id=upload_to_clickhouse, execution_date=20240101T000000, start_date=20250310T094751, end_date=20250310T094751
[2025-03-10T09:47:51.479+0000] {local_task_job_runner.py:234} INFO - Task exited with return code 0
[2025-03-10T09:47:51.492+0000] {taskinstance.py:3280} INFO - 0 downstream tasks scheduled from follow-on schedule check
[2025-03-12T14:50:04.396+0000] {taskinstance.py:1956} INFO - Dependencies all met for dep_context=non-requeueable deps ti=<TaskInstance: 4_4_house_assignment.upload_to_clickhouse scheduled__2024-01-01T00:00:00+00:00 [queued]>
[2025-03-12T14:50:04.402+0000] {taskinstance.py:1956} INFO - Dependencies all met for dep_context=requeueable deps ti=<TaskInstance: 4_4_house_assignment.upload_to_clickhouse scheduled__2024-01-01T00:00:00+00:00 [queued]>
[2025-03-12T14:50:04.402+0000] {taskinstance.py:2170} INFO - Starting attempt 1 of 1
[2025-03-12T14:50:04.413+0000] {taskinstance.py:2191} INFO - Executing <Task(PythonOperator): upload_to_clickhouse> on 2024-01-01 00:00:00+00:00
[2025-03-12T14:50:04.418+0000] {standard_task_runner.py:60} INFO - Started process 2384 to run task
[2025-03-12T14:50:04.420+0000] {standard_task_runner.py:87} INFO - Running: ['airflow', 'tasks', 'run', '4_4_house_assignment', 'upload_to_clickhouse', 'scheduled__2024-01-01T00:00:00+00:00', '--job-id', '17', '--raw', '--subdir', 'DAGS_FOLDER/4_4_house_assignment.py', '--cfg-path', '/tmp/tmpfqnadggu']
[2025-03-12T14:50:04.421+0000] {standard_task_runner.py:88} INFO - Job 17: Subtask upload_to_clickhouse
[2025-03-12T14:50:04.449+0000] {task_command.py:423} INFO - Running <TaskInstance: 4_4_house_assignment.upload_to_clickhouse scheduled__2024-01-01T00:00:00+00:00 [running]> on host 13d00b3af9e0
[2025-03-12T14:50:04.490+0000] {taskinstance.py:2480} INFO - Exporting env vars: AIRFLOW_CTX_DAG_OWNER='airflow' AIRFLOW_CTX_DAG_ID='4_4_house_assignment' AIRFLOW_CTX_TASK_ID='upload_to_clickhouse' AIRFLOW_CTX_EXECUTION_DATE='2024-01-01T00:00:00+00:00' AIRFLOW_CTX_TRY_NUMBER='1' AIRFLOW_CTX_DAG_RUN_ID='scheduled__2024-01-01T00:00:00+00:00'
[2025-03-12T14:50:04.499+0000] {connection.py:411} WARNING - Failed to connect to localhost:9000
Traceback (most recent call last):
  File "/home/airflow/.local/lib/python3.9/site-packages/clickhouse_driver/connection.py", line 399, in connect
    return self._init_connection(host, port)
  File "/home/airflow/.local/lib/python3.9/site-packages/clickhouse_driver/connection.py", line 329, in _init_connection
    self.socket = self._create_socket(host, port)
  File "/home/airflow/.local/lib/python3.9/site-packages/clickhouse_driver/connection.py", line 301, in _create_socket
    raise err
  File "/home/airflow/.local/lib/python3.9/site-packages/clickhouse_driver/connection.py", line 292, in _create_socket
    sock.connect(sa)
ConnectionRefusedError: [Errno 111] Connection refused
[2025-03-12T14:50:04.501+0000] {taskinstance.py:2698} ERROR - Task failed with exception
Traceback (most recent call last):
  File "/home/airflow/.local/lib/python3.9/site-packages/airflow/models/taskinstance.py", line 433, in _execute_task
    result = execute_callable(context=context, **execute_callable_kwargs)
  File "/home/airflow/.local/lib/python3.9/site-packages/airflow/operators/python.py", line 199, in execute
    return_value = self.execute_callable()
  File "/home/airflow/.local/lib/python3.9/site-packages/airflow/operators/python.py", line 216, in execute_callable
    return self.python_callable(*self.op_args, **self.op_kwargs)
  File "/opt/airflow/dags/4_4_house_assignment.py", line 74, in upload_to_clickhouse
    client.execute(f'CREATE TABLE IF NOT EXISTS {table_name} (num_code Int64, char_code String, nominal Int64, name String, value String, date String) ENGINE Log')
  File "/home/airflow/.local/lib/python3.9/site-packages/clickhouse_driver/client.py", line 370, in execute
    with self.disconnect_on_error(query, settings):
  File "/usr/local/lib/python3.9/contextlib.py", line 119, in __enter__
    return next(self.gen)
  File "/home/airflow/.local/lib/python3.9/site-packages/clickhouse_driver/client.py", line 313, in disconnect_on_error
    self.establish_connection(settings)
  File "/home/airflow/.local/lib/python3.9/site-packages/clickhouse_driver/client.py", line 300, in establish_connection
    self.connection.force_connect()
  File "/home/airflow/.local/lib/python3.9/site-packages/clickhouse_driver/connection.py", line 258, in force_connect
    self.connect()
  File "/home/airflow/.local/lib/python3.9/site-packages/clickhouse_driver/connection.py", line 420, in connect
    raise err
clickhouse_driver.errors.NetworkError: Code: 210. Connection refused (localhost:9000)
[2025-03-12T14:50:04.509+0000] {taskinstance.py:1138} INFO - Marking task as FAILED. dag_id=4_4_house_assignment, task_id=upload_to_clickhouse, execution_date=20240101T000000, start_date=20250312T145004, end_date=20250312T145004
[2025-03-12T14:50:04.517+0000] {standard_task_runner.py:107} ERROR - Failed to execute job 17 for task upload_to_clickhouse (Code: 210. Connection refused (localhost:9000); 2384)
[2025-03-12T14:50:04.553+0000] {local_task_job_runner.py:234} INFO - Task exited with return code 1
[2025-03-12T14:50:04.561+0000] {taskinstance.py:3280} INFO - 0 downstream tasks scheduled from follow-on schedule check
