[2025-02-26T09:54:22.551+0000] {taskinstance.py:1956} INFO - Dependencies all met for dep_context=non-requeueable deps ti=<TaskInstance: 0_Examples_3_4_1_ETL_2.upload_to_clickhouse scheduled__2024-01-01T00:00:00+00:00 [queued]>
[2025-02-26T09:54:22.572+0000] {taskinstance.py:1956} INFO - Dependencies all met for dep_context=requeueable deps ti=<TaskInstance: 0_Examples_3_4_1_ETL_2.upload_to_clickhouse scheduled__2024-01-01T00:00:00+00:00 [queued]>
[2025-02-26T09:54:22.574+0000] {taskinstance.py:2170} INFO - Starting attempt 1 of 1
[2025-02-26T09:54:22.597+0000] {taskinstance.py:2191} INFO - Executing <Task(PythonOperator): upload_to_clickhouse> on 2024-01-01 00:00:00+00:00
[2025-02-26T09:54:22.603+0000] {standard_task_runner.py:60} INFO - Started process 146 to run task
[2025-02-26T09:54:22.607+0000] {standard_task_runner.py:87} INFO - Running: ['airflow', 'tasks', 'run', '0_Examples_3_4_1_ETL_2', 'upload_to_clickhouse', 'scheduled__2024-01-01T00:00:00+00:00', '--job-id', '4', '--raw', '--subdir', 'DAGS_FOLDER/exchangerate_api_work.py', '--cfg-path', '/tmp/tmpqo20miq7']
[2025-02-26T09:54:22.608+0000] {standard_task_runner.py:88} INFO - Job 4: Subtask upload_to_clickhouse
[2025-02-26T09:54:22.640+0000] {task_command.py:423} INFO - Running <TaskInstance: 0_Examples_3_4_1_ETL_2.upload_to_clickhouse scheduled__2024-01-01T00:00:00+00:00 [running]> on host 8b59c4dac072
[2025-02-26T09:54:22.702+0000] {taskinstance.py:2480} INFO - Exporting env vars: AIRFLOW_CTX_DAG_OWNER='airflow' AIRFLOW_CTX_DAG_ID='0_Examples_3_4_1_ETL_2' AIRFLOW_CTX_TASK_ID='upload_to_clickhouse' AIRFLOW_CTX_EXECUTION_DATE='2024-01-01T00:00:00+00:00' AIRFLOW_CTX_TRY_NUMBER='1' AIRFLOW_CTX_DAG_RUN_ID='scheduled__2024-01-01T00:00:00+00:00'
[2025-02-26T09:54:22.713+0000] {connection.py:411} WARNING - Failed to connect to localhost:9000
Traceback (most recent call last):
  File "/home/airflow/.local/lib/python3.9/site-packages/clickhouse_driver/connection.py", line 399, in connect
    return self._init_connection(host, port)
  File "/home/airflow/.local/lib/python3.9/site-packages/clickhouse_driver/connection.py", line 329, in _init_connection
    self.socket = self._create_socket(host, port)
  File "/home/airflow/.local/lib/python3.9/site-packages/clickhouse_driver/connection.py", line 301, in _create_socket
    raise err
  File "/home/airflow/.local/lib/python3.9/site-packages/clickhouse_driver/connection.py", line 292, in _create_socket
    sock.connect(sa)
ConnectionRefusedError: [Errno 111] Connection refused
[2025-02-26T09:54:22.714+0000] {taskinstance.py:2698} ERROR - Task failed with exception
Traceback (most recent call last):
  File "/home/airflow/.local/lib/python3.9/site-packages/airflow/models/taskinstance.py", line 433, in _execute_task
    result = execute_callable(context=context, **execute_callable_kwargs)
  File "/home/airflow/.local/lib/python3.9/site-packages/airflow/operators/python.py", line 199, in execute
    return_value = self.execute_callable()
  File "/home/airflow/.local/lib/python3.9/site-packages/airflow/operators/python.py", line 216, in execute_callable
    return self.python_callable(*self.op_args, **self.op_kwargs)
  File "/opt/airflow/dags/exchangerate_api_work.py", line 61, in upload_to_clickhouse
    client.execute(f'CREATE TABLE IF NOT EXISTS {table_name} (num_code Int64, char_code String, nominal Int64, name String, value String, date String) ENGINE Log')
  File "/home/airflow/.local/lib/python3.9/site-packages/clickhouse_driver/client.py", line 370, in execute
    with self.disconnect_on_error(query, settings):
  File "/usr/local/lib/python3.9/contextlib.py", line 119, in __enter__
    return next(self.gen)
  File "/home/airflow/.local/lib/python3.9/site-packages/clickhouse_driver/client.py", line 313, in disconnect_on_error
    self.establish_connection(settings)
  File "/home/airflow/.local/lib/python3.9/site-packages/clickhouse_driver/client.py", line 300, in establish_connection
    self.connection.force_connect()
  File "/home/airflow/.local/lib/python3.9/site-packages/clickhouse_driver/connection.py", line 258, in force_connect
    self.connect()
  File "/home/airflow/.local/lib/python3.9/site-packages/clickhouse_driver/connection.py", line 420, in connect
    raise err
clickhouse_driver.errors.NetworkError: Code: 210. Connection refused (localhost:9000)
[2025-02-26T09:54:22.721+0000] {taskinstance.py:1138} INFO - Marking task as FAILED. dag_id=0_Examples_3_4_1_ETL_2, task_id=upload_to_clickhouse, execution_date=20240101T000000, start_date=20250226T095422, end_date=20250226T095422
[2025-02-26T09:54:22.730+0000] {standard_task_runner.py:107} ERROR - Failed to execute job 4 for task upload_to_clickhouse (Code: 210. Connection refused (localhost:9000); 146)
[2025-02-26T09:54:22.740+0000] {local_task_job_runner.py:234} INFO - Task exited with return code 1
[2025-02-26T09:54:22.751+0000] {taskinstance.py:3280} INFO - 0 downstream tasks scheduled from follow-on schedule check
[2025-02-26T09:57:00.316+0000] {taskinstance.py:1956} INFO - Dependencies all met for dep_context=non-requeueable deps ti=<TaskInstance: 0_Examples_3_4_1_ETL_2.upload_to_clickhouse scheduled__2024-01-01T00:00:00+00:00 [queued]>
[2025-02-26T09:57:00.321+0000] {taskinstance.py:1956} INFO - Dependencies all met for dep_context=requeueable deps ti=<TaskInstance: 0_Examples_3_4_1_ETL_2.upload_to_clickhouse scheduled__2024-01-01T00:00:00+00:00 [queued]>
[2025-02-26T09:57:00.322+0000] {taskinstance.py:2170} INFO - Starting attempt 1 of 1
[2025-02-26T09:57:00.334+0000] {taskinstance.py:2191} INFO - Executing <Task(PythonOperator): upload_to_clickhouse> on 2024-01-01 00:00:00+00:00
[2025-02-26T09:57:00.340+0000] {standard_task_runner.py:60} INFO - Started process 389 to run task
[2025-02-26T09:57:00.343+0000] {standard_task_runner.py:87} INFO - Running: ['airflow', 'tasks', 'run', '0_Examples_3_4_1_ETL_2', 'upload_to_clickhouse', 'scheduled__2024-01-01T00:00:00+00:00', '--job-id', '16', '--raw', '--subdir', 'DAGS_FOLDER/exchangerate_api_work.py', '--cfg-path', '/tmp/tmppeee2aew']
[2025-02-26T09:57:00.345+0000] {standard_task_runner.py:88} INFO - Job 16: Subtask upload_to_clickhouse
[2025-02-26T09:57:00.378+0000] {task_command.py:423} INFO - Running <TaskInstance: 0_Examples_3_4_1_ETL_2.upload_to_clickhouse scheduled__2024-01-01T00:00:00+00:00 [running]> on host 8b59c4dac072
[2025-02-26T09:57:00.425+0000] {taskinstance.py:2480} INFO - Exporting env vars: AIRFLOW_CTX_DAG_OWNER='airflow' AIRFLOW_CTX_DAG_ID='0_Examples_3_4_1_ETL_2' AIRFLOW_CTX_TASK_ID='upload_to_clickhouse' AIRFLOW_CTX_EXECUTION_DATE='2024-01-01T00:00:00+00:00' AIRFLOW_CTX_TRY_NUMBER='1' AIRFLOW_CTX_DAG_RUN_ID='scheduled__2024-01-01T00:00:00+00:00'
[2025-02-26T09:57:00.431+0000] {connection.py:411} WARNING - Failed to connect to localhost:8123
Traceback (most recent call last):
  File "/home/airflow/.local/lib/python3.9/site-packages/clickhouse_driver/connection.py", line 399, in connect
    return self._init_connection(host, port)
  File "/home/airflow/.local/lib/python3.9/site-packages/clickhouse_driver/connection.py", line 329, in _init_connection
    self.socket = self._create_socket(host, port)
  File "/home/airflow/.local/lib/python3.9/site-packages/clickhouse_driver/connection.py", line 301, in _create_socket
    raise err
  File "/home/airflow/.local/lib/python3.9/site-packages/clickhouse_driver/connection.py", line 292, in _create_socket
    sock.connect(sa)
ConnectionRefusedError: [Errno 111] Connection refused
[2025-02-26T09:57:00.432+0000] {taskinstance.py:2698} ERROR - Task failed with exception
Traceback (most recent call last):
  File "/home/airflow/.local/lib/python3.9/site-packages/airflow/models/taskinstance.py", line 433, in _execute_task
    result = execute_callable(context=context, **execute_callable_kwargs)
  File "/home/airflow/.local/lib/python3.9/site-packages/airflow/operators/python.py", line 199, in execute
    return_value = self.execute_callable()
  File "/home/airflow/.local/lib/python3.9/site-packages/airflow/operators/python.py", line 216, in execute_callable
    return self.python_callable(*self.op_args, **self.op_kwargs)
  File "/opt/airflow/dags/exchangerate_api_work.py", line 62, in upload_to_clickhouse
    client.execute(f'CREATE TABLE IF NOT EXISTS {table_name} (num_code Int64, char_code String, nominal Int64, name String, value String, date String) ENGINE Log')
  File "/home/airflow/.local/lib/python3.9/site-packages/clickhouse_driver/client.py", line 370, in execute
    with self.disconnect_on_error(query, settings):
  File "/usr/local/lib/python3.9/contextlib.py", line 119, in __enter__
    return next(self.gen)
  File "/home/airflow/.local/lib/python3.9/site-packages/clickhouse_driver/client.py", line 313, in disconnect_on_error
    self.establish_connection(settings)
  File "/home/airflow/.local/lib/python3.9/site-packages/clickhouse_driver/client.py", line 300, in establish_connection
    self.connection.force_connect()
  File "/home/airflow/.local/lib/python3.9/site-packages/clickhouse_driver/connection.py", line 258, in force_connect
    self.connect()
  File "/home/airflow/.local/lib/python3.9/site-packages/clickhouse_driver/connection.py", line 420, in connect
    raise err
clickhouse_driver.errors.NetworkError: Code: 210. Connection refused (localhost:8123)
[2025-02-26T09:57:00.438+0000] {taskinstance.py:1138} INFO - Marking task as FAILED. dag_id=0_Examples_3_4_1_ETL_2, task_id=upload_to_clickhouse, execution_date=20240101T000000, start_date=20250226T095700, end_date=20250226T095700
[2025-02-26T09:57:00.446+0000] {standard_task_runner.py:107} ERROR - Failed to execute job 16 for task upload_to_clickhouse (Code: 210. Connection refused (localhost:8123); 389)
[2025-02-26T09:57:00.475+0000] {local_task_job_runner.py:234} INFO - Task exited with return code 1
[2025-02-26T09:57:00.484+0000] {taskinstance.py:3280} INFO - 0 downstream tasks scheduled from follow-on schedule check
[2025-02-26T10:03:06.575+0000] {taskinstance.py:1956} INFO - Dependencies all met for dep_context=non-requeueable deps ti=<TaskInstance: 0_Examples_3_4_1_ETL_2.upload_to_clickhouse scheduled__2024-01-01T00:00:00+00:00 [queued]>
[2025-02-26T10:03:06.582+0000] {taskinstance.py:1956} INFO - Dependencies all met for dep_context=requeueable deps ti=<TaskInstance: 0_Examples_3_4_1_ETL_2.upload_to_clickhouse scheduled__2024-01-01T00:00:00+00:00 [queued]>
[2025-02-26T10:03:06.582+0000] {taskinstance.py:2170} INFO - Starting attempt 1 of 1
[2025-02-26T10:03:06.599+0000] {taskinstance.py:2191} INFO - Executing <Task(PythonOperator): upload_to_clickhouse> on 2024-01-01 00:00:00+00:00
[2025-02-26T10:03:06.604+0000] {standard_task_runner.py:60} INFO - Started process 164 to run task
[2025-02-26T10:03:06.607+0000] {standard_task_runner.py:87} INFO - Running: ['airflow', 'tasks', 'run', '0_Examples_3_4_1_ETL_2', 'upload_to_clickhouse', 'scheduled__2024-01-01T00:00:00+00:00', '--job-id', '4', '--raw', '--subdir', 'DAGS_FOLDER/exchangerate_api_work.py', '--cfg-path', '/tmp/tmp_oua5gvy']
[2025-02-26T10:03:06.609+0000] {standard_task_runner.py:88} INFO - Job 4: Subtask upload_to_clickhouse
[2025-02-26T10:03:06.640+0000] {task_command.py:423} INFO - Running <TaskInstance: 0_Examples_3_4_1_ETL_2.upload_to_clickhouse scheduled__2024-01-01T00:00:00+00:00 [running]> on host a57e69d73574
[2025-02-26T10:03:06.690+0000] {taskinstance.py:2480} INFO - Exporting env vars: AIRFLOW_CTX_DAG_OWNER='airflow' AIRFLOW_CTX_DAG_ID='0_Examples_3_4_1_ETL_2' AIRFLOW_CTX_TASK_ID='upload_to_clickhouse' AIRFLOW_CTX_EXECUTION_DATE='2024-01-01T00:00:00+00:00' AIRFLOW_CTX_TRY_NUMBER='1' AIRFLOW_CTX_DAG_RUN_ID='scheduled__2024-01-01T00:00:00+00:00'
[2025-02-26T10:03:06.697+0000] {connection.py:411} WARNING - Failed to connect to localhost:8123
Traceback (most recent call last):
  File "/home/airflow/.local/lib/python3.9/site-packages/clickhouse_driver/connection.py", line 399, in connect
    return self._init_connection(host, port)
  File "/home/airflow/.local/lib/python3.9/site-packages/clickhouse_driver/connection.py", line 329, in _init_connection
    self.socket = self._create_socket(host, port)
  File "/home/airflow/.local/lib/python3.9/site-packages/clickhouse_driver/connection.py", line 301, in _create_socket
    raise err
  File "/home/airflow/.local/lib/python3.9/site-packages/clickhouse_driver/connection.py", line 292, in _create_socket
    sock.connect(sa)
ConnectionRefusedError: [Errno 111] Connection refused
[2025-02-26T10:03:06.699+0000] {taskinstance.py:2698} ERROR - Task failed with exception
Traceback (most recent call last):
  File "/home/airflow/.local/lib/python3.9/site-packages/airflow/models/taskinstance.py", line 433, in _execute_task
    result = execute_callable(context=context, **execute_callable_kwargs)
  File "/home/airflow/.local/lib/python3.9/site-packages/airflow/operators/python.py", line 199, in execute
    return_value = self.execute_callable()
  File "/home/airflow/.local/lib/python3.9/site-packages/airflow/operators/python.py", line 216, in execute_callable
    return self.python_callable(*self.op_args, **self.op_kwargs)
  File "/opt/airflow/dags/exchangerate_api_work.py", line 62, in upload_to_clickhouse
    client.execute(f'CREATE TABLE IF NOT EXISTS {table_name} (num_code Int64, char_code String, nominal Int64, name String, value String, date String) ENGINE Log')
  File "/home/airflow/.local/lib/python3.9/site-packages/clickhouse_driver/client.py", line 370, in execute
    with self.disconnect_on_error(query, settings):
  File "/usr/local/lib/python3.9/contextlib.py", line 119, in __enter__
    return next(self.gen)
  File "/home/airflow/.local/lib/python3.9/site-packages/clickhouse_driver/client.py", line 313, in disconnect_on_error
    self.establish_connection(settings)
  File "/home/airflow/.local/lib/python3.9/site-packages/clickhouse_driver/client.py", line 300, in establish_connection
    self.connection.force_connect()
  File "/home/airflow/.local/lib/python3.9/site-packages/clickhouse_driver/connection.py", line 258, in force_connect
    self.connect()
  File "/home/airflow/.local/lib/python3.9/site-packages/clickhouse_driver/connection.py", line 420, in connect
    raise err
clickhouse_driver.errors.NetworkError: Code: 210. Connection refused (localhost:8123)
[2025-02-26T10:03:06.706+0000] {taskinstance.py:1138} INFO - Marking task as FAILED. dag_id=0_Examples_3_4_1_ETL_2, task_id=upload_to_clickhouse, execution_date=20240101T000000, start_date=20250226T100306, end_date=20250226T100306
[2025-02-26T10:03:06.715+0000] {standard_task_runner.py:107} ERROR - Failed to execute job 4 for task upload_to_clickhouse (Code: 210. Connection refused (localhost:8123); 164)
[2025-02-26T10:03:06.740+0000] {local_task_job_runner.py:234} INFO - Task exited with return code 1
[2025-02-26T10:03:06.750+0000] {taskinstance.py:3280} INFO - 0 downstream tasks scheduled from follow-on schedule check
[2025-02-26T10:04:21.446+0000] {taskinstance.py:1956} INFO - Dependencies all met for dep_context=non-requeueable deps ti=<TaskInstance: 0_Examples_3_4_1_ETL_2.upload_to_clickhouse scheduled__2024-01-01T00:00:00+00:00 [queued]>
[2025-02-26T10:04:21.452+0000] {taskinstance.py:1956} INFO - Dependencies all met for dep_context=requeueable deps ti=<TaskInstance: 0_Examples_3_4_1_ETL_2.upload_to_clickhouse scheduled__2024-01-01T00:00:00+00:00 [queued]>
[2025-02-26T10:04:21.453+0000] {taskinstance.py:2170} INFO - Starting attempt 1 of 1
[2025-02-26T10:04:21.466+0000] {taskinstance.py:2191} INFO - Executing <Task(PythonOperator): upload_to_clickhouse> on 2024-01-01 00:00:00+00:00
[2025-02-26T10:04:21.471+0000] {standard_task_runner.py:60} INFO - Started process 257 to run task
[2025-02-26T10:04:21.473+0000] {standard_task_runner.py:87} INFO - Running: ['airflow', 'tasks', 'run', '0_Examples_3_4_1_ETL_2', 'upload_to_clickhouse', 'scheduled__2024-01-01T00:00:00+00:00', '--job-id', '4', '--raw', '--subdir', 'DAGS_FOLDER/exchangerate_api_work.py', '--cfg-path', '/tmp/tmp2hi23_4b']
[2025-02-26T10:04:21.475+0000] {standard_task_runner.py:88} INFO - Job 4: Subtask upload_to_clickhouse
[2025-02-26T10:04:21.504+0000] {task_command.py:423} INFO - Running <TaskInstance: 0_Examples_3_4_1_ETL_2.upload_to_clickhouse scheduled__2024-01-01T00:00:00+00:00 [running]> on host a57e69d73574
[2025-02-26T10:04:21.549+0000] {taskinstance.py:2480} INFO - Exporting env vars: AIRFLOW_CTX_DAG_OWNER='airflow' AIRFLOW_CTX_DAG_ID='0_Examples_3_4_1_ETL_2' AIRFLOW_CTX_TASK_ID='upload_to_clickhouse' AIRFLOW_CTX_EXECUTION_DATE='2024-01-01T00:00:00+00:00' AIRFLOW_CTX_TRY_NUMBER='1' AIRFLOW_CTX_DAG_RUN_ID='scheduled__2024-01-01T00:00:00+00:00'
[2025-02-26T10:04:21.556+0000] {connection.py:411} WARNING - Failed to connect to localhost:9000
Traceback (most recent call last):
  File "/home/airflow/.local/lib/python3.9/site-packages/clickhouse_driver/connection.py", line 399, in connect
    return self._init_connection(host, port)
  File "/home/airflow/.local/lib/python3.9/site-packages/clickhouse_driver/connection.py", line 329, in _init_connection
    self.socket = self._create_socket(host, port)
  File "/home/airflow/.local/lib/python3.9/site-packages/clickhouse_driver/connection.py", line 301, in _create_socket
    raise err
  File "/home/airflow/.local/lib/python3.9/site-packages/clickhouse_driver/connection.py", line 292, in _create_socket
    sock.connect(sa)
ConnectionRefusedError: [Errno 111] Connection refused
[2025-02-26T10:04:21.557+0000] {taskinstance.py:2698} ERROR - Task failed with exception
Traceback (most recent call last):
  File "/home/airflow/.local/lib/python3.9/site-packages/airflow/models/taskinstance.py", line 433, in _execute_task
    result = execute_callable(context=context, **execute_callable_kwargs)
  File "/home/airflow/.local/lib/python3.9/site-packages/airflow/operators/python.py", line 199, in execute
    return_value = self.execute_callable()
  File "/home/airflow/.local/lib/python3.9/site-packages/airflow/operators/python.py", line 216, in execute_callable
    return self.python_callable(*self.op_args, **self.op_kwargs)
  File "/opt/airflow/dags/exchangerate_api_work.py", line 62, in upload_to_clickhouse
    client.execute(f'CREATE TABLE IF NOT EXISTS {table_name} (num_code Int64, char_code String, nominal Int64, name String, value String, date String) ENGINE Log')
  File "/home/airflow/.local/lib/python3.9/site-packages/clickhouse_driver/client.py", line 370, in execute
    with self.disconnect_on_error(query, settings):
  File "/usr/local/lib/python3.9/contextlib.py", line 119, in __enter__
    return next(self.gen)
  File "/home/airflow/.local/lib/python3.9/site-packages/clickhouse_driver/client.py", line 313, in disconnect_on_error
    self.establish_connection(settings)
  File "/home/airflow/.local/lib/python3.9/site-packages/clickhouse_driver/client.py", line 300, in establish_connection
    self.connection.force_connect()
  File "/home/airflow/.local/lib/python3.9/site-packages/clickhouse_driver/connection.py", line 258, in force_connect
    self.connect()
  File "/home/airflow/.local/lib/python3.9/site-packages/clickhouse_driver/connection.py", line 420, in connect
    raise err
clickhouse_driver.errors.NetworkError: Code: 210. Connection refused (localhost:9000)
[2025-02-26T10:04:21.563+0000] {taskinstance.py:1138} INFO - Marking task as FAILED. dag_id=0_Examples_3_4_1_ETL_2, task_id=upload_to_clickhouse, execution_date=20240101T000000, start_date=20250226T100421, end_date=20250226T100421
[2025-02-26T10:04:21.572+0000] {standard_task_runner.py:107} ERROR - Failed to execute job 4 for task upload_to_clickhouse (Code: 210. Connection refused (localhost:9000); 257)
[2025-02-26T10:04:21.606+0000] {local_task_job_runner.py:234} INFO - Task exited with return code 1
[2025-02-26T10:04:21.616+0000] {taskinstance.py:3280} INFO - 0 downstream tasks scheduled from follow-on schedule check
[2025-02-26T10:08:11.054+0000] {taskinstance.py:1956} INFO - Dependencies all met for dep_context=non-requeueable deps ti=<TaskInstance: 0_Examples_3_4_1_ETL_2.upload_to_clickhouse scheduled__2024-01-01T00:00:00+00:00 [queued]>
[2025-02-26T10:08:11.059+0000] {taskinstance.py:1956} INFO - Dependencies all met for dep_context=requeueable deps ti=<TaskInstance: 0_Examples_3_4_1_ETL_2.upload_to_clickhouse scheduled__2024-01-01T00:00:00+00:00 [queued]>
[2025-02-26T10:08:11.059+0000] {taskinstance.py:2170} INFO - Starting attempt 1 of 1
[2025-02-26T10:08:11.071+0000] {taskinstance.py:2191} INFO - Executing <Task(PythonOperator): upload_to_clickhouse> on 2024-01-01 00:00:00+00:00
[2025-02-26T10:08:11.076+0000] {standard_task_runner.py:60} INFO - Started process 547 to run task
[2025-02-26T10:08:11.079+0000] {standard_task_runner.py:87} INFO - Running: ['airflow', 'tasks', 'run', '0_Examples_3_4_1_ETL_2', 'upload_to_clickhouse', 'scheduled__2024-01-01T00:00:00+00:00', '--job-id', '4', '--raw', '--subdir', 'DAGS_FOLDER/exchangerate_api_work.py', '--cfg-path', '/tmp/tmpc7lpy7ol']
[2025-02-26T10:08:11.080+0000] {standard_task_runner.py:88} INFO - Job 4: Subtask upload_to_clickhouse
[2025-02-26T10:08:11.106+0000] {task_command.py:423} INFO - Running <TaskInstance: 0_Examples_3_4_1_ETL_2.upload_to_clickhouse scheduled__2024-01-01T00:00:00+00:00 [running]> on host a57e69d73574
[2025-02-26T10:08:11.145+0000] {taskinstance.py:2480} INFO - Exporting env vars: AIRFLOW_CTX_DAG_OWNER='airflow' AIRFLOW_CTX_DAG_ID='0_Examples_3_4_1_ETL_2' AIRFLOW_CTX_TASK_ID='upload_to_clickhouse' AIRFLOW_CTX_EXECUTION_DATE='2024-01-01T00:00:00+00:00' AIRFLOW_CTX_TRY_NUMBER='1' AIRFLOW_CTX_DAG_RUN_ID='scheduled__2024-01-01T00:00:00+00:00'
[2025-02-26T10:08:11.218+0000] {unix.py:142} WARNING - /etc/timezone is deprecated on Debian, and no longer reliable. Ignoring.
[2025-02-26T10:08:11.223+0000] {python.py:201} INFO - Done. Returned value was: None
[2025-02-26T10:08:11.229+0000] {taskinstance.py:1138} INFO - Marking task as SUCCESS. dag_id=0_Examples_3_4_1_ETL_2, task_id=upload_to_clickhouse, execution_date=20240101T000000, start_date=20250226T100811, end_date=20250226T100811
[2025-02-26T10:08:11.253+0000] {local_task_job_runner.py:234} INFO - Task exited with return code 0
[2025-02-26T10:08:11.262+0000] {taskinstance.py:3280} INFO - 0 downstream tasks scheduled from follow-on schedule check
[2025-03-12T11:45:23.894+0000] {taskinstance.py:1956} INFO - Dependencies all met for dep_context=non-requeueable deps ti=<TaskInstance: 0_Examples_3_4_1_ETL_2.upload_to_clickhouse scheduled__2024-01-01T00:00:00+00:00 [queued]>
[2025-03-12T11:45:23.902+0000] {taskinstance.py:1956} INFO - Dependencies all met for dep_context=requeueable deps ti=<TaskInstance: 0_Examples_3_4_1_ETL_2.upload_to_clickhouse scheduled__2024-01-01T00:00:00+00:00 [queued]>
[2025-03-12T11:45:23.903+0000] {taskinstance.py:2170} INFO - Starting attempt 1 of 1
[2025-03-12T11:45:23.923+0000] {taskinstance.py:2191} INFO - Executing <Task(PythonOperator): upload_to_clickhouse> on 2024-01-01 00:00:00+00:00
[2025-03-12T11:45:23.931+0000] {standard_task_runner.py:60} INFO - Started process 2704 to run task
[2025-03-12T11:45:23.934+0000] {standard_task_runner.py:87} INFO - Running: ['airflow', 'tasks', 'run', '0_Examples_3_4_1_ETL_2', 'upload_to_clickhouse', 'scheduled__2024-01-01T00:00:00+00:00', '--job-id', '4', '--raw', '--subdir', 'DAGS_FOLDER/exchangerate_api_work.py', '--cfg-path', '/tmp/tmpmxaileva']
[2025-03-12T11:45:23.935+0000] {standard_task_runner.py:88} INFO - Job 4: Subtask upload_to_clickhouse
[2025-03-12T11:45:23.974+0000] {task_command.py:423} INFO - Running <TaskInstance: 0_Examples_3_4_1_ETL_2.upload_to_clickhouse scheduled__2024-01-01T00:00:00+00:00 [running]> on host 727edeb5f419
[2025-03-12T11:45:24.030+0000] {taskinstance.py:2480} INFO - Exporting env vars: AIRFLOW_CTX_DAG_OWNER='airflow' AIRFLOW_CTX_DAG_ID='0_Examples_3_4_1_ETL_2' AIRFLOW_CTX_TASK_ID='upload_to_clickhouse' AIRFLOW_CTX_EXECUTION_DATE='2024-01-01T00:00:00+00:00' AIRFLOW_CTX_TRY_NUMBER='1' AIRFLOW_CTX_DAG_RUN_ID='scheduled__2024-01-01T00:00:00+00:00'
[2025-03-12T11:45:24.151+0000] {python.py:201} INFO - Done. Returned value was: None
[2025-03-12T11:45:24.158+0000] {taskinstance.py:1138} INFO - Marking task as SUCCESS. dag_id=0_Examples_3_4_1_ETL_2, task_id=upload_to_clickhouse, execution_date=20240101T000000, start_date=20250312T114523, end_date=20250312T114524
[2025-03-12T11:45:24.191+0000] {local_task_job_runner.py:234} INFO - Task exited with return code 0
[2025-03-12T11:45:24.203+0000] {taskinstance.py:3280} INFO - 0 downstream tasks scheduled from follow-on schedule check
